Workbook
Name data_amt: Данные!$D$2:$D$341
Name data_cat: Данные!$C$2:$C$341
Name data_dir: Данные!$E$2:$E$341
Name data_item: Данные!$B$2:$B$341

Sheet Данные
A1: Дата | B1: Статья | C1: Категория | D1: Сумма | E1: Направление | F1: Проект | G1: Примечание | H1: Кол-во | I1: Цена | J1: Срок | K1: Флаг | L1: Доля | M1: Вес | N1: Код | O1: Остаток
A2: 45870 | B2: Сырьё 4 | C2: Кат-06 | D2: 390525.48 | E2: расход | F2: П11 | G2: 'с кавычкой | H2: 99 | I2: 4552.71 | J2: 45700 | K2: TRUE | L2: 0.154 | M2: 4.891439 | N2: K67369 | O2: -105380.68
A3: 45939 | B3: Доход 2 | C3: Кат-12 | D3: -78635.15 | E3: расход | F3: П05 | G3: 25% | H3: 65 | I3: 5460.82 | J3: 46102 | K3: TRUE | L3: 0.77 | M3: 9.94534 | N3: K239333 | O3: 257001.29
A4: 45698 | B4: Налог 1 | C4: Кат-15 | D4: 24606.32 | E4: расход | F4: П02 | G4: 25% | H4: 4 | I4: 6222.2 | J4: 46109 | K4: FALSE | L4: 0.402 | M4: 3.0237285 | N4: K677214 | O4: 452631.44
A5: 46011 | B5: Доход 4 | C5: Кат-03 | D5: 317210.93 | E5: приход | F5: П14 | G5: 25% | H5: 88 | I5: 5100.59 | J5: 46270 | K5: FALSE | L5: 0.949 | M5: 1.3192058 | N5: K977882 | O5: -336987.18
A6: 45781 | B6: Налог 3 | C6: Кат-11 | D6: 62162.46 | E6: расход | F6: П02 | H6: 85 | I6: 2727.87 | J6: 45773 | K6: TRUE | L6: 0.144 | M6: 6.5457657 | N6: K549060 | O6: -175382.91
A7: 45692 | B7: Доход 3 | C7: Кат-14 | D7: 50413.46 | E7: приход | F7: П08 | G7: он сказал "да" | H7: 21 | I7: 7921.98 | J7: 46018 | K7: FALSE | L7: 0.004 | M7: 1.8297106 | N7: K28350 | O7: 484251.44
A8: 45768 | B8: Чай 2 | C8: Кат-18 | D8: -53073.73 | E8: расход | F8: П12 | G8: 25% | H8: 9 | I8: 1491.37 | J8: 45847 | K8: FALSE | L8: 0.312 | M8: 9.0910573 | N8: K861756 | O8: 132972.16
A9: 45907 | B9: Сырьё 1 | C9: Кат-06 | D9: 53759.45 | E9: расход | F9: П15 | G9: TRUE | H9: 32 | I9: 766.57 | J9: 45941 | K9: TRUE | L9: 0.148 | M9: 8.2118014 | N9: K307948 | O9: 392440.7
A10: 45850 | B10: Сырье 1 | C10: Кат-11 | D10: 72419.45 | E10: расход | F10: П12 | G10: =1+1 | H10: 20 | I10: 6317.22 | J10: 46032 | K10: TRUE | L10: 0.872 | M10: 6.4881417 | N10: K358758 | O10: -145403.93
A11: 45870 | B11: Ёлка 3 | C11: Кат-13 | D11: 170040.1 | E11: приход | F11: П02 | H11: 14 | I11: 7105.7 | J11: 45878 | K11: FALSE | L11: 0.926 | M11: 0.72140963 | N11: K110150 | O11: -326665.79
A12: 45902 | B12: Чаи 4 | C12: Кат-06 | D12: 89894.04 | E12: приход | F12: П15 | G12: пробелы | H12: 1 | I12: 8608.17 | J12: 45795 | K12: FALSE | L12: 0.385 | M12: 7.1257513 | N12: K134502 | O12: -215782.98
A13: 46009 | B13: Налог 1 | C13: Кат-13 | D13: -78781.56 | E13: приход | F13: П03 | G13: путь\к\файлу | H13: 61 | I13: 192.13 | J13: 45669 | K13: FALSE | L13: 0.653 | M13: 7.9840452 | N13: K644748 | O13: 174135.62
A14: 45992 | B14: Чаи 1 | C14: Кат-17 | D14: 359716.92 | E14: расход | F14: П09 | G14: 2025-01-01 | H14: 10 | I14: 836.13 | J14: 46143 | K14: FALSE | L14: 0.551 | M14: 6.861817 | N14: K861061 | O14: -3102.43
A15: 45932 | B15: Сырьё 1 | C15: Кат-18 | D15: 267685.09 | E15: расход | F15: П02 | G15: TRUE | H15: 70 | I15: 337.33 | J15: 46366 | K15: FALSE | L15: 0.85 | M15: 6.2798565 | N15: K468277 | O15: 98538.37
A16: 45814 | B16: Связь 3 | C16: Кат-01 | D16: 369197.94 | E16: расход | F16: П09 | G16: TRUE | H16: 15 | I16: 9543.86 | J16: 45671 | K16: TRUE | L16: 0.976 | M16: 6.3044936 | N16: K479752 | O16: -497254.49
A17: 45870 | B17: Доход 1 | C17: Кат-13 | D17: 386326.05 | E17: расход | F17: П09 | G17: он сказал "да" | H17: 40 | I17: 6149.58 | J17: 46320 | K17: TRUE | L17: 0.759 | M17: 7.1544776 | N17: K241962 | O17: -340589.31
A18: 45972 | B18: Связь 3 | C18: Кат-09 | D18: 153637.47 | E18: приход | F18: П12 | G18: путь\к\файлу | H18: 77 | I18: 1237.9 | J18: 45952 | K18: TRUE | L18: 0.319 | M18: 7.4562634 | N18: K34119 | O18: -265488.29
A19: 45666 | B19: Налог 2 | C19: Кат-14 | D19: 58052.64 | E19: приход | F19: П10 | G19: обычный текст | H19: 66 | I19: 4704.15 | J19: 45803 | K19: TRUE | L19: 0.91 | M19: 9.9669643 | N19: K607536 | O19: -302362.17
A20: 45887 | B20: Аренда 2 | C20: Кат-19 | D20: 353981.07 | E20: приход | F20: П07 | G20: 25% | H20: 1 | I20: 5034.99 | J20: 45939 | K20: FALSE | L20: 0.906 | M20: 4.2413345 | N20: K187445 | O20: 54272.46
A21: 45849 | B21: Чай 3 | C21: Кат-10 | D21: 225608.62 | E21: приход | F21: П07 | G21: TRUE | H21: 55 | I21: 374.9 | J21: 46158 | K21: TRUE | L21: 0.139 | M21: 2.7454624 | N21: K306175 | O21: -209049.39
A22: 45886 | B22: Налог 1 | C22: Кат-16 | D22: 94760.89 | E22: расход | F22: П04 | G22: 'с кавычкой | H22: 0 | I22: 1456.39 | J22: 45897 | K22: TRUE | L22: 0.608 | M22: 5.1767241 | N22: K403984 | O22: -108032.77
A23: 45674 | B23: Чаи 1 | C23: Кат-07 | D23: 150225.98 | E23: приход | F23: П10 | G23: пробелы | H23: 91 | I23: 4846.2 | J23: 46174 | K23: TRUE | L23: 0.928 | M23: 0.49381798 | N23: K346466 | O23: 338797.34
... A29: 45891 | B29: Елка 3 | C29: Кат-01 | D29: 1.2814733e+09 | E29: приход | F29: П01 | G29: обычный текст | H29: 7 | I29: 8906.24 | J29: 45779 | K29: FALSE | L29: 0.684 | M29: 8.6563913 | N29: K922157 | O29: -427031.58
A30: 45980 | B30: Ёлка 1 | C30: Кат-17 | D30: 57068.59 | E30: приход | F30: П11 | H30: 29 | I30: 4044.33 | J30: 46330 | K30: FALSE | L30: 0.09 | M30: 5.5685139 | N30: K359871 | O30: -335017.2
A31: 45694 | B31: Связь 1 | C31: Кат-19 | D31: 178192.36 | E31: приход | F31: П01 | G31: 'с кавычкой | H31: 20 | I31: 3442.57 | J31: 45896 | K31: FALSE | L31: 0.231 | M31: 7.8811559 | N31: K554589 | O31: -252598.89
A32: 45963 | B32: Связь 2 | C32: Кат-17 | D32: -68844.6 | E32: расход | F32: П05 | G32: 2025-01-01 | H32: 44 | I32: 3839.67 | J32: 46194 | K32: FALSE | L32: 0.712 | M32: 0.58203895 | N32: K444788 | O32: -79740.38
A33: 45832 | B33: Сырьё 4 | C33: Кат-15 | D33: 6434.18 | E33: расход | F33: П03 | G33: пробелы | H33: 2 | I33: 4684.49 | J33: 45871 | K33: FALSE | L33: 0.125 | M33: 1.2359374 | N33: K340369 | O33: -54374.87
A34: 45765 | B34: Чай 2 | C34: Кат-14 | D34: -29513.86 | E34: расход | F34: П08 | G34: 'с кавычкой | H34: 99 | I34: 7570.22 | J34: 45995 | K34: TRUE | L34: 0.537 | M34: 5.6520037 | N34: K593825 | O34: -399106.66
A35: 45796 | B35: Чай 3 | C35: Кат-15 | D35: 72144.07 | E35: расход | F35: П10 | G35: пробелы | H35: 75 | I35: 7469.7 | J35: 45984 | K35: TRUE | L35: 0.333 | M35: 8.0419463 | N35: K938352 | O35: 412030.36
A36: 45681 | B36: Связь 1 | C36: Кат-09 | D36: 97614.39 | E36: приход | F36: П04 | G36: он сказал "да" | H36: 97 | I36: 5474.36 | J36: 46006 | K36: FALSE | L36: 0.016 | M36: 7.8039018 | N36: K811663 | O36: 280714.95
A37: 46017 | B37: Доход 3 | C37: Кат-10 | D37: -83837.23 | E37: расход | F37: П09 | G37: путь\к\файлу | H37: 17 | I37: 7465.77 | J37: 45846 | K37: TRUE | L37: 0.384 | M37: 1.0216789 | N37: K35817 | O37: -94126.92
A38: 45675 | B38: Сырьё 2 | C38: Кат-18 | D38: 48723.82 | E38: расход | F38: П15 | G38: 2025-01-01 | H38: 37 | I38: 5043.61 | J38: 45794 | K38: TRUE | L38: 0.496 | M38: 1.1926085 | N38: K275953 | O38: 65603.62
A39: 45662 | B39: Аренда 2 | C39: Кат-01 | D39: 204895.21 | E39: расход | F39: П01 | G39: =1+1 | H39: 85 | I39: 1817.91 | J39: 45917 | K39: FALSE | L39: 0.223 | M39: 6.8138124 | N39: K347378 | O39: 456608.53
A40: 45937 | B40: Чай 2 | C40: Кат-14 | D40: 66279.71 | E40: приход | F40: П04 | G40: пробелы | H40: 43 | I40: 3039.5 | J40: 46274 | K40: FALSE | L40: 0.99 | M40: 6.9203224 | N40: K78757 | O40: 158731.17
A41: 45761 | B41: Чай 3 | C41: Кат-09 | D41: 392435.78 | E41: расход | F41: П02 | G41: 'с кавычкой | H41: 80 | I41: 9538.15 | J41: 45877 | K41: FALSE | L41: 0.128 | M41: 0.77584809 | N41: K584645 | O41: -380913.54
A42: 45878 | B42: Аренда 2 | C42: Кат-15 | D42: 74328.45 | E42: расход | F42: П09 | G42: обычный текст | H42: 99 | I42: 2614.22 | J42: 46161 | K42: TRUE | L42: 0.802 | M42: 4.6396291 | N42: K744947 | O42: 109001.35
A43: 45923 | B43: Ёлка 2 | C43: Кат-15 | D43: 70013.85 | E43: расход | F43: П06 | H43: 68 | I43: 157.13 | J43: 46377 | K43: TRUE | L43: 0.165 | M43: 7.7028911 | N43: K342103 | O43: 329128.67
A44: 45738 | B44: Чай 1 | C44: Кат-08 | D44: 239810.47 | E44: приход | F44: П07 | G44: обычный текст | H44: 8 | I44: 4447.87 | J44: 45736 | K44: TRUE | L44: 0.976 | M44: 1.7178456 | N44: K903894 | O44: 146611.26
A45: 45939 | B45: Связь 2 | C45: Кат-17 | D45: -32180.28 | E45: расход | F45: П04 | G45: путь\к\файлу | H45: 60 | I45: 3714.7 | J45: 46196 | K45: FALSE | L45: 0.589 | M45: 6.9196208 | N45: K651840 | O45: 348187.59
...

Sheet Статьи
A1: Статья | B1: Группа | C1: Название группы | E1: Группа | F1: Название
A2: Чай 1 | B2: 1 | C2: {=_xlfn.XLOOKUP(B2,$E$2:$E$9,$F$2:$F$9,"нет")} -> Группа «1» | E2: 1 | F2: Группа «1»
A3: Чаи 1 | B3: 1 | C3: {=_xlfn.XLOOKUP(B3,$E$2:$E$9,$F$2:$F$9,"нет")} -> Группа «1» | E3: 2 | F3: Группа «2»
A4: Ёлка 1 | B4: 1 | C4: {=_xlfn.XLOOKUP(B4,$E$2:$E$9,$F$2:$F$9,"нет")} -> Группа «1» | E4: 3 | F4: Группа «3»
A5: Елка 1 | B5: 1 | C5: {=_xlfn.XLOOKUP(B5,$E$2:$E$9,$F$2:$F$9,"нет")} -> Группа «1» | E5: 4 | F5: Группа «4»
A6: Аренда 1 | B6: 1 | C6: {=_xlfn.XLOOKUP(B6,$E$2:$E$9,$F$2:$F$9,"нет")} -> Группа «1» | E6: 5 | F6: Группа «5»
A7: Связь 1 | B7: 2 | C7: {=_xlfn.XLOOKUP(B7,$E$2:$E$9,$F$2:$F$9,"нет")} -> Группа «2» | E7: 6 | F7: Группа «6»
A8: Налог 1 | B8: 2 | C8: {=_xlfn.XLOOKUP(B8,$E$2:$E$9,$F$2:$F$9,"нет")} -> Группа «2» | E8: 7 | F8: Группа «7»
A9: Доход 1 | B9: 2 | C9: {=_xlfn.XLOOKUP(B9,$E$2:$E$9,$F$2:$F$9,"нет")} -> Группа «2» | E9: 8 | F9: Группа «8»
A10: Сырьё 1 | B10: 2 | C10: {=_xlfn.XLOOKUP(B10,$E$2:$E$9,$F$2:$F$9,"нет")} -> Группа «2»
A11: Сырье 1 | B11: 2 | C11: {=_xlfn.XLOOKUP(B11,$E$2:$E$9,$F$2:$F$9,"нет")} -> Группа «2»
A12: Чай 2 | B12: 3 | C12: {=_xlfn.XLOOKUP(B12,$E$2:$E$9,$F$2:$F$9,"нет")} -> Группа «3»
A13: Чаи 2 | B13: 3 | C13: {=_xlfn.XLOOKUP(B13,$E$2:$E$9,$F$2:$F$9,"нет")} -> Группа «3»
A14: Ёлка 2 | B14: 3 | C14: {=_xlfn.XLOOKUP(B14,$E$2:$E$9,$F$2:$F$9,"нет")} -> Группа «3»
A15: Елка 2 | B15: 3 | C15: {=_xlfn.XLOOKUP(B15,$E$2:$E$9,$F$2:$F$9,"нет")} -> Группа «3»
A16: Аренда 2 | B16: 3 | C16: {=_xlfn.XLOOKUP(B16,$E$2:$E$9,$F$2:$F$9,"нет")} -> Группа «3»
A17: Связь 2 | B17: 4 | C17: {=_xlfn.XLOOKUP(B17,$E$2:$E$9,$F$2:$F$9,"нет")} -> Группа «4»
A18: Налог 2 | B18: 4 | C18: {=_xlfn.XLOOKUP(B18,$E$2:$E$9,$F$2:$F$9,"нет")} -> Группа «4»
A19: Доход 2 | B19: 4 | C19: {=_xlfn.XLOOKUP(B19,$E$2:$E$9,$F$2:$F$9,"нет")} -> Группа «4»
A20: Сырьё 2 | B20: 4 | C20: {=_xlfn.XLOOKUP(B20,$E$2:$E$9,$F$2:$F$9,"нет")} -> Группа «4»
A21: Сырье 2 | B21: 4 | C21: {=_xlfn.XLOOKUP(B21,$E$2:$E$9,$F$2:$F$9,"нет")} -> Группа «4»
... A41: Сырье 4 | B41: 8 | C41: {=_xlfn.XLOOKUP(B41,$E$2:$E$9,$F$2:$F$9,"нет")} -> Группа «8»

Sheet Параметры
A1: Начало | B1: 45658
A2: Конец | B2: {=EOMONTH(B1,11)} -> 46022
A3: Приход | B3: приход
A4: Расход | B4: расход
A5: Начало DATE | B5: {=DATE(2025,1,1)} -> 45658
A10: Чай* | B10: {=COUNTIFS(Данные!$B:$B,"Чай*")} -> 41
B11: {=COUNTIFS(Данные!$B:$B,A10,Данные!$E:$E,B3)} -> 17
B12: {=IFERROR(ПоМесяцам!N3/ПоМесяцам!N4,0)} -> 1.0546062
B13: {=ROUND(B12,2)} -> 1.05
B14: {=IF(B12>1,"больше","не больше")} -> больше
B15: {=TEXT(B1,"YYYY-MM-DD")} -> 2025-01-01
B16: {=TEXT(B13,"0.00")} -> 1.05
B17: {=IFERROR(1/(B3="нет"),-1)} -> -1
B18: {=SUMIFS(Данные!$D:$D,Данные!$B:$B,"Чаи*")} -> 3633640.1

Sheet ПоМесяцам
A1: ПоМесяцам | B1: {=Параметры!B1} -> 45658 | C1: {=EOMONTH(B1,0)+1} -> 45689 | D1: {=EOMONTH(C1,0)+1} -> 45717 | E1: {=EOMONTH(D1,0)+1} -> 45748 | F1: {=EOMONTH(E1,0)+1} -> 45778 | G1: {=EOMONTH(F1,0)+1} -> 45809 | H1: {=EOMONTH(G1,0)+1} -> 45839 | I1: {=EOMONTH(H1,0)+1} -> 45870 | J1: {=EOMONTH(I1,0)+1} -> 45901 | ... M1: {=EOMONTH(L1,0)+1} -> 45992
B2: {=EOMONTH(B1,0)} -> 45688 | C2: {=EOMONTH(C1,0)} -> 45716 | D2: {=EOMONTH(D1,0)} -> 45747 | E2: {=EOMONTH(E1,0)} -> 45777 | F2: {=EOMONTH(F1,0)} -> 45808 | G2: {=EOMONTH(G1,0)} -> 45838 | H2: {=EOMONTH(H1,0)} -> 45869 | I2: {=EOMONTH(I1,0)} -> 45900 | ... M2: {=EOMONTH(M1,0)} -> 46022
A3: {=Статьи!A2} -> Чай 1 | B3: {=SUMIFS(Данные!$D:$D,Данные!$B:$B,$A3,Данные!$A:$A,">="&B$1,Данные!$A:$A,"<="&B$2)} -> 201440.5 | C3: {=SUMIFS(Данные!$D:$D,Данные!$B:$B,$A3,Данные!$A:$A,">="&C$1,Данные!$A:$A,"<="&C$2)} -> 0 | D3: {=SUMIFS(Данные!$D:$D,Данные!$B:$B,$A3,Данные!$A:$A,">="&D$1,Данные!$A:$A,"<="&D$2)} -> 674698.26 | E3: {=SUMIFS(Данные!$D:$D,Данные!$B:$B,$A3,Данные!$A:$A,">="&E$1,Данные!$A:$A,"<="&E$2)} -> -77680.2 | F3: {=SUMIFS(Данные!$D:$D,Данные!$B:$B,$A3,Данные!$A:$A,">="&F$1,Данные!$A:$A,"<="&F$2)} -> 0 | G3: {=SUMIFS(Данные!$D:$D,Данные!$B:$B,$A3,Данные!$A:$A,">="&G$1,Данные!$A:$A,"<="&G$2)} -> 0 | H3: {=SUMIFS(Данные!$D:$D,Данные!$B:$B,$A3,Данные!$A:$A,">="&H$1,Данные!$A:$A,"<="&H$2)} -> 494752.81 | I3: {=SUMIFS(Данные!$D:$D,Данные!$B:$B,$A3,Данные!$A:$A,">="&I$1,Данные!$A:$A,"<="&I$2)} -> 0 | ... M3: {=SUMIFS(Данные!$D:$D,Данные!$B:$B,$A3,Данные!$A:$A,">="&M$1,Данные!$A:$A,"<="&M$2)} -> 206959.82 | N3: {=SUM(B3:M3)} -> 1884168.1
A4: {=Статьи!A3} -> Чаи 1 | B4: {=SUMIFS(Данные!$D:$D,Данные!$B:$B,$A4,Данные!$A:$A,">="&B$1,Данные!$A:$A,"<="&B$2)} -> 150225.98 | C4: {=SUMIFS(Данные!$D:$D,Данные!$B:$B,$A4,Данные!$A:$A,">="&C$1,Данные!$A:$A,"<="&C$2)} -> 0 | D4: {=SUMIFS(Данные!$D:$D,Данные!$B:$B,$A4,Данные!$A:$A,">="&D$1,Данные!$A:$A,"<="&D$2)} -> 0 | E4: {=SUMIFS(Данные!$D:$D,Данные!$B:$B,$A4,Данные!$A:$A,">="&E$1,Данные!$A:$A,"<="&E$2)} -> 0 | F4: {=SUMIFS(Данные!$D:$D,Данные!$B:$B,$A4,Данные!$A:$A,">="&F$1,Данные!$A:$A,"<="&F$2)} -> 482987.52 | G4: {=SUMIFS(Данные!$D:$D,Данные!$B:$B,$A4,Данные!$A:$A,">="&G$1,Данные!$A:$A,"<="&G$2)} -> -6678.65 | H4: {=SUMIFS(Данные!$D:$D,Данные!$B:$B,$A4,Данные!$A:$A,">="&H$1,Данные!$A:$A,"<="&H$2)} -> 0 | I4: {=SUMIFS(Данные!$D:$D,Данные!$B:$B,$A4,Данные!$A:$A,">="&I$1,Данные!$A:$A,"<="&I$2)} -> 200235.22 | ... M4: {=SUMIFS(Данные!$D:$D,Данные!$B:$B,$A4,Данные!$A:$A,">="&M$1,Данные!$A:$A,"<="&M$2)} -> 668551.03 | N4: {=SUM(B4:M4)} -> 1786608.3
A5: {=Статьи!A4} -> Ёлка 1 | B5: {=SUMIFS(Данные!$D:$D,Данные!$B:$B,$A5,Данные!$A:$A,">="&B$1,Данные!$A:$A,"<="&B$2)} -> 284772.29 | C5: {=SUMIFS(Данные!$D:$D,Данные!$B:$B,$A5,Данные!$A:$A,">="&C$1,Данные!$A:$A,"<="&C$2)} -> 476555.97 | D5: {=SUMIFS(Данные!$D:$D,Данные!$B:$B,$A5,Данные!$A:$A,">="&D$1,Данные!$A:$A,"<="&D$2)} -> 0 | E5: {=SUMIFS(Данные!$D:$D,Данные!$B:$B,$A5,Данные!$A:$A,">="&E$1,Данные!$A:$A,"<="&E$2)} -> 239698.95 | F5: {=SUMIFS(Данные!$D:$D,Данные!$B:$B,$A5,Данные!$A:$A,">="&F$1,Данные!$A:$A,"<="&F$2)} -> 390910.21 | G5: {=SUMIFS(Данные!$D:$D,Данные!$B:$B,$A5,Данные!$A:$A,">="&G$1,Данные!$A:$A,"<="&G$2)} -> 112561.77 | H5: {=SUMIFS(Данные!$D:$D,Данные!$B:$B,$A5,Данные!$A:$A,">="&H$1,Данные!$A:$A,"<="&H$2)} -> 0 | I5: {=SUMIFS(Данные!$D:$D,Данные!$B:$B,$A5,Данные!$A:$A,">="&I$1,Данные!$A:$A,"<="&I$2)} -> 0 | ... M5: {=SUMIFS(Данные!$D:$D,Данные!$B:$B,$A5,Данные!$A:$A,">="&M$1,Данные!$A:$A,"<="&M$2)} -> 0 | N5: {=SUM(B5:M5)} -> 1939261.5
A6: {=Статьи!A5} -> Елка 1 | B6: {=SUMIFS(Данные!$D:$D,Данные!$B:$B,$A6,Данные!$A:$A,">="&B$1,Данные!$A:$A,"<="&B$2)} -> 0 | C6: {=SUMIFS(Данные!$D:$D,Данные!$B:$B,$A6,Данные!$A:$A,">="&C$1,Данные!$A:$A,"<="&C$2)} -> 111694.51 | D6: {=SUMIFS(Данные!$D:$D,Данные!$B:$B,$A6,Данные!$A:$A,">="&D$1,Данные!$A:$A,"<="&D$2)} -> 561396.13 | E6: {=SUMIFS(Данные!$D:$D,Данные!$B:$B,$A6,Данные!$A:$A,">="&E$1,Данные!$A:$A,"<="&E$2)} -> 0 | F6: {=SUMIFS(Данные!$D:$D,Данные!$B:$B,$A6,Данные!$A:$A,">="&F$1,Данные!$A:$A,"<="&F$2)} -> 147133.95 | G6: {=SUMIFS(Данные!$D:$D,Данные!$B:$B,$A6,Данные!$A:$A,">="&G$1,Данные!$A:$A,"<="&G$2)} -> 492890.75 | H6: {=SUMIFS(Данные!$D:$D,Данные!$B:$B,$A6,Данные!$A:$A,">="&H$1,Данные!$A:$A,"<="&H$2)} -> 0 | I6: {=SUMIFS(Данные!$D:$D,Данные!$B:$B,$A6,Данные!$A:$A,">="&I$1,Данные!$A:$A,"<="&I$2)} -> 0 | ... M6: {=SUMIFS(Данные!$D:$D,Данные!$B:$B,$A6,Данные!$A:$A,">="&M$1,Данные!$A:$A,"<="&M$2)} -> 0 | N6: {=SUM(B6:M6)} -> 1525962.7
A7: {=Статьи!A6} -> Аренда 1 | B7: {=SUMIFS(Данные!$D:$D,Данные!$B:$B,$A7,Данные!$A:$A,">="&B$1,Данные!$A:$A,"<="&B$2)} -> 0 | C7: {=SUMIFS(Данные!$D:$D,Данные!$B:$B,$A7,Данные!$A:$A,">="&C$1,Данные!$A:$A,"<="&C$2)} -> 117411.05 | D7: {=SUMIFS(Данные!$D:$D,Данные!$B:$B,$A7,Данные!$A:$A,">="&D$1,Данные!$A:$A,"<="&D$2)} -> 200873.7 | E7: {=SUMIFS(Данные!$D:$D,Данные!$B:$B,$A7,Данные!$A:$A,">="&E$1,Данные!$A:$A,"<="&E$2)} -> 90275.12 | F7: {=SUMIFS(Данные!$D:$D,Данные!$B:$B,$A7,Данные!$A:$A,">="&F$1,Данные!$A:$A,"<="&F$2)} -> 0 | G7: {=SUMIFS(Данные!$D:$D,Данные!$B:$B,$A7,Данные!$A:$A,">="&G$1,Данные!$A:$A,"<="&G$2)} -> 0 | H7: {=SUMIFS(Данные!$D:$D,Данные!$B:$B,$A7,Данные!$A:$A,">="&H$1,Данные!$A:$A,"<="&H$2)} -> 0 | I7: {=SUMIFS(Данные!$D:$D,Данные!$B:$B,$A7,Данные!$A:$A,">="&I$1,Данные!$A:$A,"<="&I$2)} -> 345306.23 | ... M7: {=SUMIFS(Данные!$D:$D,Данные!$B:$B,$A7,Данные!$A:$A,">="&M$1,Данные!$A:$A,"<="&M$2)} -> 354795.36 | N7: {=SUM(B7:M7)} -> 1496071.2
A8: Итого группа 1 | B8: {=SUM(B3:B7)} -> 636438.77 | C8: {=SUM(C3:C7)} -> 705661.53 | D8: {=SUM(D3:D7)} -> 1436968.1 | E8: {=SUM(E3:E7)} -> 252293.87 | F8: {=SUM(F3:F7)} -> 1021031.7 | G8: {=SUM(G3:G7)} -> 598773.87 | H8: {=SUM(H3:H7)} -> 494752.81 | I8: {=SUM(I3:I7)} -> 545541.45 | ... N8: {=SUM(N3:N7)} -> 8632071.8
A9: {=Статьи!A7} -> Связь 1 | B9: {=SUMIFS(Данные!$D:$D,Данные!$B:$B,$A9,Данные!$A:$A,">="&B$1,Данные!$A:$A,"<="&B$2)} -> 97614.39 | C9: {=SUMIFS(Данные!$D:$D,Данные!$B:$B,$A9,Данные!$A:$A,">="&C$1,Данные!$A:$A,"<="&C$2)} -> 178192.36 | D9: {=SUMIFS(Данные!$D:$D,Данные!$B:$B,$A9,Данные!$A:$A,">="&D$1,Данные!$A:$A,"<="&D$2)} -> 0 | E9: {=SUMIFS(Данные!$D:$D,Данные!$B:$B,$A9,Данные!$A:$A,">="&E$1,Данные!$A:$A,"<="&E$2)} -> 0 | F9: {=SUMIFS(Данные!$D:$D,Данные!$B:$B,$A9,Данные!$A:$A,">="&F$1,Данные!$A:$A,"<="&F$2)} -> 141542.73 | G9: {=SUMIFS(Данные!$D:$D,Данные!$B:$B,$A9,Данные!$A:$A,">="&G$1,Данные!$A:$A,"<="&G$2)} -> 615190.07 | H9: {=SUMIFS(Данные!$D:$D,Данные!$B:$B,$A9,Данные!$A:$A,">="&H$1,Данные!$A:$A,"<="&H$2)} -> 173233.8 | I9: {=SUMIFS(Данные!$D:$D,Данные!$B:$B,$A9,Данные!$A:$A,">="&I$1,Данные!$A:$A,"<="&I$2)} -> 0 | ... M9: {=SUMIFS(Данные!$D:$D,Данные!$B:$B,$A9,Данные!$A:$A,">="&M$1,Данные!$A:$A,"<="&M$2)} -> 78369.71 | N9: {=SUM(B9:M9)} -> 1284143.1
A10: {=Статьи!A8} -> Налог 1 | B10: {=SUMIFS(Данные!$D:$D,Данные!$B:$B,$A10,Данные!$A:$A,">="&B$1,Данные!$A:$A,"<="&B$2)} -> 0 | C10: {=SUMIFS(Данные!$D:$D,Данные!$B:$B,$A10,Данные!$A:$A,">="&C$1,Данные!$A:$A,"<="&C$2)} -> 24606.32 | D10: {=SUMIFS(Данные!$D:$D,Данные!$B:$B,$A10,Данные!$A:$A,">="&D$1,Данные!$A:$A,"<="&D$2)} -> -53530.76 | E10: {=SUMIFS(Данные!$D:$D,Данные!$B:$B,$A10,Данные!$A:$A,">="&E$1,Данные!$A:$A,"<="&E$2)} -> 0 | F10: {=SUMIFS(Данные!$D:$D,Данные!$B:$B,$A10,Данные!$A:$A,">="&F$1,Данные!$A:$A,"<="&F$2)} -> 46330.65 | G10: {=SUMIFS(Данные!$D:$D,Данные!$B:$B,$A10,Данные!$A:$A,">="&G$1,Данные!$A:$A,"<="&G$2)} -> 222390.05 | H10: {=SUMIFS(Данные!$D:$D,Данные!$B:$B,$A10,Данные!$A:$A,">="&H$1,Данные!$A:$A,"<="&H$2)} -> 0 | I10: {=SUMIFS(Данные!$D:$D,Данные!$B:$B,$A10,Данные!$A:$A,">="&I$1,Данные!$A:$A,"<="&I$2)} -> 387806.59 | ... M10: {=SUMIFS(Данные!$D:$D,Данные!$B:$B,$A10,Данные!$A:$A,">="&M$1,Данные!$A:$A,"<="&M$2)} -> -78781.56 | N10: {=SUM(B10:M10)} -> 630619.24
A11: {=Статьи!A9} -> Доход 1 | B11: {=SUMIFS(Данные!$D:$D,Данные!$B:$B,$A11,Данные!$A:$A,">="&B$1,Данные!$A:$A,"<="&B$2)} -> 10010.8 | C11: {=SUMIFS(Данные!$D:$D,Данные!$B:$B,$A11,Данные!$A:$A,">="&C$1,Данные!$A:$A,"<="&C$2)} -> 0 | D11: {=SUMIFS(Данные!$D:$D,Данные!$B:$B,$A11,Данные!$A:$A,">="&D$1,Данные!$A:$A,"<="&D$2)} -> 242812.16 | E11: {=SUMIFS(Данные!$D:$D,Данные!$B:$B,$A11,Данные!$A:$A,">="&E$1,Данные!$A:$A,"<="&E$2)} -> 0 | F11: {=SUMIFS(Данные!$D:$D,Данные!$B:$B,$A11,Данные!$A:$A,">="&F$1,Данные!$A:$A,"<="&F$2)} -> 280790.62 | G11: {=SUMIFS(Данные!$D:$D,Данные!$B:$B,$A11,Данные!$A:$A,">="&G$1,Данные!$A:$A,"<="&G$2)} -> 0 | H11: {=SUMIFS(Данные!$D:$D,Данные!$B:$B,$A11,Данные!$A:$A,">="&H$1,Данные!$A:$A,"<="&H$2)} -> 217989.18 | I11: {=SUMIFS(Данные!$D:$D,Данные!$B:$B,$A11,Данные!$A:$A,">="&I$1,Данные!$A:$A,"<="&I$2)} -> 386326.05 | ... M11: {=SUMIFS(Данные!$D:$D,Данные!$B:$B,$A11,Данные!$A:$A,">="&M$1,Данные!$A:$A,"<="&M$2)} -> 0 | N11: {=SUM(B11:M11)} -> 1746676.3
A12: {=Статьи!A10} -> Сырьё 1 | B12: {=SUMIFS(Данные!$D:$D,Данные!$B:$B,$A12,Данные!$A:$A,">="&B$1,Данные!$A:$A,"<="&B$2)} -> 356320.82 | C12: {=SUMIFS(Данные!$D:$D,Данные!$B:$B,$A12,Данные!$A:$A,">="&C$1,Данные!$A:$A,"<="&C$2)} -> 0 | D12: {=SUMIFS(Данные!$D:$D,Данные!$B:$B,$A12,Данные!$A:$A,">="&D$1,Данные!$A:$A,"<="&D$2)} -> 0 | E12: {=SUMIFS(Данные!$D:$D,Данные!$B:$B,$A12,Данные!$A:$A,">="&E$1,Данные!$A:$A,"<="&E$2)} -> 339107.89 | F12: {=SUMIFS(Данные!$D:$D,Данные!$B:$B,$A12,Данные!$A:$A,">="&F$1,Данные!$A:$A,"<="&F$2)} -> 0 | G12: {=SUMIFS(Данные!$D:$D,Данные!$B:$B,$A12,Данные!$A:$A,">="&G$1,Данные!$A:$A,"<="&G$2)} -> -182223.25 | H12: {=SUMIFS(Данные!$D:$D,Данные!$B:$B,$A12,Данные!$A:$A,">="&H$1,Данные!$A:$A,"<="&H$2)} -> 0 | I12: {=SUMIFS(Данные!$D:$D,Данные!$B:$B,$A12,Данные!$A:$A,">="&I$1,Данные!$A:$A,"<="&I$2)} -> -42568.94 | ... M12: {=SUMIFS(Данные!$D:$D,Данные!$B:$B,$A12,Данные!$A:$A,">="&M$1,Данные!$A:$A,"<="&M$2)} -> 326886.85 | N12: {=SUM(B12:M12)} -> 1461005.5
A13: {=Статьи!A11} -> Сырье 1 | B13: {=SUMIFS(Данные!$D:$D,Данные!$B:$B,$A13,Данные!$A:$A,">="&B$1,Данные!$A:$A,"<="&B$2)} -> 0 | C13: {=SUMIFS(Данные!$D:$D,Данные!$B:$B,$A13,Данные!$A:$A,">="&C$1,Данные!$A:$A,"<="&C$2)} -> 0 | D13: {=SUMIFS(Данные!$D:$D,Данные!$B:$B,$A13,Данные!$A:$A,">="&D$1,Данные!$A:$A,"<="&D$2)} -> -7891.15 | E13: {=SUMIFS(Данные!$D:$D,Данные!$B:$B,$A13,Данные!$A:$A,">="&E$1,Данные!$A:$A,"<="&E$2)} -> 0 | F13: {=SUMIFS(Данные!$D:$D,Данные!$B:$B,$A13,Данные!$A:$A,">="&F$1,Данные!$A:$A,"<="&F$2)} -> 0 | G13: {=SUMIFS(Данные!$D:$D,Данные!$B:$B,$A13,Данные!$A:$A,">="&G$1,Данные!$A:$A,"<="&G$2)} -> 0 | H13: {=SUMIFS(Данные!$D:$D,Данные!$B:$B,$A13,Данные!$A:$A,">="&H$1,Данные!$A:$A,"<="&H$2)} -> 44692.14 | I13: {=SUMIFS(Данные!$D:$D,Данные!$B:$B,$A13,Данные!$A:$A,">="&I$1,Данные!$A:$A,"<="&I$2)} -> 197703.92 | ... M13: {=SUMIFS(Данные!$D:$D,Данные!$B:$B,$A13,Данные!$A:$A,">="&M$1,Данные!$A:$A,"<="&M$2)} -> -31559.73 | N13: {=SUM(B13:M13)} -> 472649.75
A14: Итого группа 2 | B14: {=SUM(B9:B13)} -> 463946.01 | C14: {=SUM(C9:C13)} -> 202798.68 | D14: {=SUM(D9:D13)} -> 181390.25 | E14: {=SUM(E9:E13)} -> 339107.89 | F14: {=SUM(F9:F13)} -> 468664 | G14: {=SUM(G9:G13)} -> 655356.87 | H14: {=SUM(H9:H13)} -> 435915.12 | I14: {=SUM(I9:I13)} -> 929267.62 | ... N14: {=SUM(N9:N13)} -> 5595093.9
A15: {=Статьи!A12} -> Чай 2 | B15: {=SUMIFS(Данные!$D:$D,Данные!$B:$B,$A15,Данные!$A:$A,">="&B$1,Данные!$A:$A,"<="&B$2)} -> 0 | C15: {=SUMIFS(Данные!$D:$D,Данные!$B:$B,$A15,Данные!$A:$A,">="&C$1,Данные!$A:$A,"<="&C$2)} -> 0 | D15: {=SUMIFS(Данные!$D:$D,Данные!$B:$B,$A15,Данные!$A:$A,">="&D$1,Данные!$A:$A,"<="&D$2)} -> 261512.61 | E15: {=SUMIFS(Данные!$D:$D,Данные!$B:$B,$A15,Данные!$A:$A,">="&E$1,Данные!$A:$A,"<="&E$2)} -> -82587.59 | F15: {=SUMIFS(Данные!$D:$D,Данные!$B:$B,$A15,Данные!$A:$A,">="&F$1,Данные!$A:$A,"<="&F$2)} -> 0 | G15: {=SUMIFS(Данные!$D:$D,Данные!$B:$B,$A15,Данные!$A:$A,">="&G$1,Данные!$A:$A,"<="&G$2)} -> 0 | H15: {=SUMIFS(Данные!$D:$D,Данные!$B:$B,$A15,Данные!$A:$A,">="&H$1,Данные!$A:$A,"<="&H$2)} -> 222008.01 | I15: {=SUMIFS(Данные!$D:$D,Данные!$B:$B,$A15,Данные!$A:$A,">="&I$1,Данные!$A:$A,"<="&I$2)} -> 452052.26 | ... M15: {=SUMIFS(Данные!$D:$D,Данные!$B:$B,$A15,Данные!$A:$A,">="&M$1,Данные!$A:$A,"<="&M$2)} -> 635438.37 | N15: {=SUM(B15:M15)} -> 2050056.9
A16: {=Статьи!A13} -> Чаи 2 | B16: {=SUMIFS(Данные!$D:$D,Данные!$B:$B,$A16,Данные!$A:$A,">="&B$1,Данные!$A:$A,"<="&B$2)} -> 0 | C16: {=SUMIFS(Данные!$D:$D,Данные!$B:$B,$A16,Данные!$A:$A,">="&C$1,Данные!$A:$A,"<="&C$2)} -> 0 | D16: {=SUMIFS(Данные!$D:$D,Данные!$B:$B,$A16,Данные!$A:$A,">="&D$1,Данные!$A:$A,"<="&D$2)} -> 0 | E16: {=SUMIFS(Данные!$D:$D,Данные!$B:$B,$A16,Данные!$A:$A,">="&E$1,Данные!$A:$A,"<="&E$2)} -> 0 | F16: {=SUMIFS(Данные!$D:$D,Данные!$B:$B,$A16,Данные!$A:$A,">="&F$1,Данные!$A:$A,"<="&F$2)} -> 0 | G16: {=SUMIFS(Данные!$D:$D,Данные!$B:$B,$A16,Данные!$A:$A,">="&G$1,Данные!$A:$A,"<="&G$2)} -> 0 | H16: {=SUMIFS(Данные!$D:$D,Данные!$B:$B,$A16,Данные!$A:$A,">="&H$1,Данные!$A:$A,"<="&H$2)} -> 0 | I16: {=SUMIFS(Данные!$D:$D,Данные!$B:$B,$A16,Данные!$A:$A,">="&I$1,Данные!$A:$A,"<="&I$2)} -> 0 | ... M16: {=SUMIFS(Данные!$D:$D,Данные!$B:$B,$A16,Данные!$A:$A,">="&M$1,Данные!$A:$A,"<="&M$2)} -> 73165.31 | N16: {=SUM(B16:M16)} -> 334421.4
A17: {=Статьи!A14} -> Ёлка 2 | B17: {=SUMIFS(Данные!$D:$D,Данные!$B:$B,$A17,Данные!$A:$A,">="&B$1,Данные!$A:$A,"<="&B$2)} -> 225830.81 | C17: {=SUMIFS(Данные!$D:$D,Данные!$B:$B,$A17,Данные!$A:$A,">="&C$1,Данные!$A:$A,"<="&C$2)} -> -52645.57 | D17: {=SUMIFS(Данные!$D:$D,Данные!$B:$B,$A17,Данные!$A:$A,">="&D$1,Данные!$A:$A,"<="&D$2)} -> 273906.27 | E17: {=SUMIFS(Данные!$D:$D,Данные!$B:$B,$A17,Данные!$A:$A,">="&E$1,Данные!$A:$A,"<="&E$2)} -> 0 | F17: {=SUMIFS(Данные!$D:$D,Данные!$B:$B,$A17,Данные!$A:$A,">="&F$1,Данные!$A:$A,"<="&F$2)} -> 0 | G17: {=SUMIFS(Данные!$D:$D,Данные!$B:$B,$A17,Данные!$A:$A,">="&G$1,Данные!$A:$A,"<="&G$2)} -> 17122.95 | H17: {=SUMIFS(Данные!$D:$D,Данные!$B:$B,$A17,Данные!$A:$A,">="&H$1,Данные!$A:$A,"<="&H$2)} -> 0 | I17: {=SUMIFS(Данные!$D:$D,Данные!$B:$B,$A17,Данные!$A:$A,">="&I$1,Данные!$A:$A,"<="&I$2)} -> -28948.52 | ... M17: {=SUMIFS(Данные!$D:$D,Данные!$B:$B,$A17,Данные!$A:$A,">="&M$1,Данные!$A:$A,"<="&M$2)} -> 0 | N17: {=SUM(B17:M17)} -> 773174.4
A18: {=Статьи!A15} -> Елка 2 | B18: {=SUMIFS(Данные!$D:$D,Данные!$B:$B,$A18,Данные!$A:$A,">="&B$1,Данные!$A:$A,"<="&B$2)} -> 0 | C18: {=SUMIFS(Данные!$D:$D,Данные!$B:$B,$A18,Данные!$A:$A,">="&C$1,Данные!$A:$A,"<="&C$2)} -> 0 | D18: {=SUMIFS(Данные!$D:$D,Данные!$B:$B,$A18,Данные!$A:$A,">="&D$1,Данные!$A:$A,"<="&D$2)} -> -63824.16 | E18: {=SUMIFS(Данные!$D:$D,Данные!$B:$B,$A18,Данные!$A:$A,">="&E$1,Данные!$A:$A,"<="&E$2)} -> 0 | F18: {=SUMIFS(Данные!$D:$D,Данные!$B:$B,$A18,Данные!$A:$A,">="&F$1,Данные!$A:$A,"<="&F$2)} -> 0 | G18: {=SUMIFS(Данные!$D:$D,Данные!$B:$B,$A18,Данные!$A:$A,">="&G$1,Данные!$A:$A,"<="&G$2)} -> 358273.26 | H18: {=SUMIFS(Данные!$D:$D,Данные!$B:$B,$A18,Данные!$A:$A,">="&H$1,Данные!$A:$A,"<="&H$2)} -> -15627.84 | I18: {=SUMIFS(Данные!$D:$D,Данные!$B:$B,$A18,Данные!$A:$A,">="&I$1,Данные!$A:$A,"<="&I$2)} -> 365776.07 | ... M18: {=SUMIFS(Данные!$D:$D,Данные!$B:$B,$A18,Данные!$A:$A,">="&M$1,Данные!$A:$A,"<="&M$2)} -> 0 | N18: {=SUM(B18:M18)} -> 674538.7
A19: {=Статьи!A16} -> Аренда 2 | B19: {=SUMIFS(Данные!$D:$D,Данные!$B:$B,$A19,Данные!$A:$A,">="&B$1,Данные!$A:$A,"<="&B$2)} -> 193100.63 | C19: {=SUMIFS(Данные!$D:$D,Данные!$B:$B,$A19,Данные!$A:$A,">="&C$1,Данные!$A:$A,"<="&C$2)} -> 0 | D19: {=SUMIFS(Данные!$D:$D,Данные!$B:$B,$A19,Данные!$A:$A,">="&D$1,Данные!$A:$A,"<="&D$2)} -> 324159.6 | E19: {=SUMIFS(Данные!$D:$D,Данные!$B:$B,$A19,Данные!$A:$A,">="&E$1,Данные!$A:$A,"<="&E$2)} -> 0 | F19: {=SUMIFS(Данные!$D:$D,Данные!$B:$B,$A19,Данные!$A:$A,">="&F$1,Данные!$A:$A,"<="&F$2)} -> 672233.3 | G19: {=SUMIFS(Данные!$D:$D,Данные!$B:$B,$A19,Данные!$A:$A,">="&G$1,Данные!$A:$A,"<="&G$2)} -> 94850.14 | H19: {=SUMIFS(Данные!$D:$D,Данные!$B:$B,$A19,Данные!$A:$A,">="&H$1,Данные!$A:$A,"<="&H$2)} -> 0 | I19: {=SUMIFS(Данные!$D:$D,Данные!$B:$B,$A19,Данные!$A:$A,">="&I$1,Данные!$A:$A,"<="&I$2)} -> 428309.52 | ... M19: {=SUMIFS(Данные!$D:$D,Данные!$B:$B,$A19,Данные!$A:$A,">="&M$1,Данные!$A:$A,"<="&M$2)} -> 0 | N19: {=SUM(B19:M19)} -> 1712653.2
A20: Итого группа 3 | B20: {=SUM(B15:B19)} -> 418931.44 | C20: {=SUM(C15:C19)} -> -52645.57 | D20: {=SUM(D15:D19)} -> 795754.32 | E20: {=SUM(E15:E19)} -> -82587.59 | F20: {=SUM(F15:F19)} -> 672233.3 | G20: {=SUM(G15:G19)} -> 470246.35 | H20: {=SUM(H15:H19)} -> 206380.17 | I20: {=SUM(I15:I19)} -> 1217189.3 | ... N20: {=SUM(N15:N19)} -> 5544844.5
A21: {=Статьи!A17} -> Связь 2 | B21: {=SUMIFS(Данные!$D:$D,Данные!$B:$B,$A21,Данные!$A:$A,">="&B$1,Данные!$A:$A,"<="&B$2)} -> 0 | C21: {=SUMIFS(Данные!$D:$D,Данные!$B:$B,$A21,Данные!$A:$A,">="&C$1,Данные!$A:$A,"<="&C$2)} -> 0 | D21: {=SUMIFS(Данные!$D:$D,Данные!$B:$B,$A21,Данные!$A:$A,">="&D$1,Данные!$A:$A,"<="&D$2)} -> 302502.66 | E21: {=SUMIFS(Данные!$D:$D,Данные!$B:$B,$A21,Данные!$A:$A,">="&E$1,Данные!$A:$A,"<="&E$2)} -> 0 | F21: {=SUMIFS(Данные!$D:$D,Данные!$B:$B,$A21,Данные!$A:$A,">="&F$1,Данные!$A:$A,"<="&F$2)} -> 17079.28 | G21: {=SUMIFS(Данные!$D:$D,Данные!$B:$B,$A21,Данные!$A:$A,">="&G$1,Данные!$A:$A,"<="&G$2)} -> 3338.13 | H21: {=SUMIFS(Данные!$D:$D,Данные!$B:$B,$A21,Данные!$A:$A,">="&H$1,Данные!$A:$A,"<="&H$2)} -> 0 | I21: {=SUMIFS(Данные!$D:$D,Данные!$B:$B,$A21,Данные!$A:$A,">="&I$1,Данные!$A:$A,"<="&I$2)} -> 369105.58 | ... M21: {=SUMIFS(Данные!$D:$D,Данные!$B:$B,$A21,Данные!$A:$A,">="&M$1,Данные!$A:$A,"<="&M$2)} -> 0 | N21: {=SUM(B21:M21)} -> 540928.25
A22: {=Статьи!A18} -> Налог 2 | B22: {=SUMIFS(Данные!$D:$D,Данные!$B:$B,$A22,Данные!$A:$A,">="&B$1,Данные!$A:$A,"<="&B$2)} -> 359900.52 | C22: {=SUMIFS(Данные!$D:$D,Данные!$B:$B,$A22,Данные!$A:$A,">="&C$1,Данные!$A:$A,"<="&C$2)} -> 0 | D22: {=SUMIFS(Данные!$D:$D,Данные!$B:$B,$A22,Данные!$A:$A,">="&D$1,Данные!$A:$A,"<="&D$2)} -> 0 | E22: {=SUMIFS(Данные!$D:$D,Данные!$B:$B,$A22,Данные!$A:$A,">="&E$1,Данные!$A:$A,"<="&E$2)} -> 0 | F22: {=SUMIFS(Данные!$D:$D,Данные!$B:$B,$A22,Данные!$A:$A,">="&F$1,Данные!$A:$A,"<="&F$2)} -> 0 | G22: {=SUMIFS(Данные!$D:$D,Данные!$B:$B,$A22,Данные!$A:$A,">="&G$1,Данные!$A:$A,"<="&G$2)} -> 0 | H22: {=SUMIFS(Данные!$D:$D,Данные!$B:$B,$A22,Данные!$A:$A,">="&H$1,Данные!$A:$A,"<="&H$2)} -> 146159.26 | I22: {=SUMIFS(Данные!$D:$D,Данные!$B:$B,$A22,Данные!$A:$A,">="&I$1,Данные!$A:$A,"<="&I$2)} -> -76742.92 | ... M22: {=SUMIFS(Данные!$D:$D,Данные!$B:$B,$A22,Данные!$A:$A,">="&M$1,Данные!$A:$A,"<="&M$2)} -> 0 | N22: {=SUM(B22:M22)} -> 1132300.7
A23: {=Статьи!A19} -> Доход 2 | B23: {=SUMIFS(Данные!$D:$D,Данные!$B:$B,$A23,Данные!$A:$A,">="&B$1,Данные!$A:$A,"<="&B$2)} -> 283598.73 | C23: {=SUMIFS(Данные!$D:$D,Данные!$B:$B,$A23,Данные!$A:$A,">="&C$1,Данные!$A:$A,"<="&C$2)} -> 0 | D23: {=SUMIFS(Данные!$D:$D,Данные!$B:$B,$A23,Данные!$A:$A,">="&D$1,Данные!$A:$A,"<="&D$2)} -> 0 | E23: {=SUMIFS(Данные!$D:$D,Данные!$B:$B,$A23,Данные!$A:$A,">="&E$1,Данные!$A:$A,"<="&E$2)} -> 0 | F23: {=SUMIFS(Данные!$D:$D,Данные!$B:$B,$A23,Данные!$A:$A,">="&F$1,Данные!$A:$A,"<="&F$2)} -> 321244.59 | G23: {=SUMIFS(Данные!$D:$D,Данные!$B:$B,$A23,Данные!$A:$A,">="&G$1,Данные!$A:$A,"<="&G$2)} -> 0 | H23: {=SUMIFS(Данные!$D:$D,Данные!$B:$B,$A23,Данные!$A:$A,">="&H$1,Данные!$A:$A,"<="&H$2)} -> 0 | I23: {=SUMIFS(Данные!$D:$D,Данные!$B:$B,$A23,Данные!$A:$A,">="&I$1,Данные!$A:$A,"<="&I$2)} -> 0 | ... M23: {=SUMIFS(Данные!$D:$D,Данные!$B:$B,$A23,Данные!$A:$A,">="&M$1,Данные!$A:$A,"<="&M$2)} -> 0 | N23: {=SUM(B23:M23)} -> 702919.91
A24: {=Статьи!A20} -> Сырьё 2 | B24: {=SUMIFS(Данные!$D:$D,Данные!$B:$B,$A24,Данные!$A:$A,">="&B$1,Данные!$A:$A,"<="&B$2)} -> 48723.82 | C24: {=SUMIFS(Данные!$D:$D,Данные!$B:$B,$A24,Данные!$A:$A,">="&C$1,Данные!$A:$A,"<="&C$2)} -> 29317.87 | D24: {=SUMIFS(Данные!$D:$D,Данные!$B:$B,$A24,Данные!$A:$A,">="&D$1,Данные!$A:$A,"<="&D$2)} -> 152209.67 | E24: {=SUMIFS(Данные!$D:$D,Данные!$B:$B,$A24,Данные!$A:$A,">="&E$1,Данные!$A:$A,"<="&E$2)} -> 292678.6 | F24: {=SUMIFS(Данные!$D:$D,Данные!$B:$B,$A24,Данные!$A:$A,">="&F$1,Данные!$A:$A,"<="&F$2)} -> 0 | G24: {=SUMIFS(Данные!$D:$D,Данные!$B:$B,$A24,Данные!$A:$A,">="&G$1,Данные!$A:$A,"<="&G$2)} -> 3.8050072e+08 | H24: {=SUMIFS(Данные!$D:$D,Данные!$B:$B,$A24,Данные!$A:$A,">="&H$1,Данные!$A:$A,"<="&H$2)} -> 332928.47 | I24: {=SUMIFS(Данные!$D:$D,Данные!$B:$B,$A24,Данные!$A:$A,">="&I$1,Данные!$A:$A,"<="&I$2)} -> 0 | ... M24: {=SUMIFS(Данные!$D:$D,Данные!$B:$B,$A24,Данные!$A:$A,">="&M$1,Данные!$A:$A,"<="&M$2)} -> 103867.83 | N24: {=SUM(B24:M24)} -> 3.8138789e+08
A25: {=Статьи!A21} -> Сырье 2 | B25: {=SUMIFS(Данные!$D:$D,Данные!$B:$B,$A25,Данные!$A:$A,">="&B$1,Данные!$A:$A,"<="&B$2)} -> -68476 | C25: {=SUMIFS(Данные!$D:$D,Данные!$B:$B,$A25,Данные!$A:$A,">="&C$1,Данные!$A:$A,"<="&C$2)} -> 0 | D25: {=SUMIFS(Данные!$D:$D,Данные!$B:$B,$A25,Данные!$A:$A,">="&D$1,Данные!$A:$A,"<="&D$2)} -> 221595.45 | E25: {=SUMIFS(Данные!$D:$D,Данные!$B:$B,$A25,Данные!$A:$A,">="&E$1,Данные!$A:$A,"<="&E$2)} -> 150781.73 | F25: {=SUMIFS(Данные!$D:$D,Данные!$B:$B,$A25,Данные!$A:$A,">="&F$1,Данные!$A:$A,"<="&F$2)} -> -42207.32 | G25: {=SUMIFS(Данные!$D:$D,Данные!$B:$B,$A25,Данные!$A:$A,">="&G$1,Данные!$A:$A,"<="&G$2)} -> 102310.79 | H25: {=SUMIFS(Данные!$D:$D,Данные!$B:$B,$A25,Данные!$A:$A,">="&H$1,Данные!$A:$A,"<="&H$2)} -> -61034.63 | I25: {=SUMIFS(Данные!$D:$D,Данные!$B:$B,$A25,Данные!$A:$A,">="&I$1,Данные!$A:$A,"<="&I$2)} -> 0 | ... M25: {=SUMIFS(Данные!$D:$D,Данные!$B:$B,$A25,Данные!$A:$A,">="&M$1,Данные!$A:$A,"<="&M$2)} -> -34400.87 | N25: {=SUM(B25:M25)} -> 268569.15
A26: Итого группа 4 | B26: {=SUM(B21:B25)} -> 623747.07 | C26: {=SUM(C21:C25)} -> 29317.87 | D26: {=SUM(D21:D25)} -> 676307.78 | E26: {=SUM(E21:E25)} -> 443460.33 | F26: {=SUM(F21:F25)} -> 296116.55 | G26: {=SUM(G21:G25)} -> 3.8060637e+08 | H26: {=SUM(H21:H25)} -> 418053.1 | I26: {=SUM(I21:I25)} -> 292362.66 | ... N26: {=SUM(N21:N25)} -> 3.840326e+08
A27: {=Статьи!A22} -> Чай 3 | B27: {=SUMIFS(Данные!$D:$D,Данные!$B:$B,$A27,Данные!$A:$A,">="&B$1,Данные!$A:$A,"<="&B$2)} -> 56606.62 | C27: {=SUMIFS(Данные!$D:$D,Данные!$B:$B,$A27,Данные!$A:$A,">="&C$1,Данные!$A:$A,"<="&C$2)} -> 0 | D27: {=SUMIFS(Данные!$D:$D,Данные!$B:$B,$A27,Данные!$A:$A,">="&D$1,Данные!$A:$A,"<="&D$2)} -> 265561.61 | E27: {=SUMIFS(Данные!$D:$D,Данные!$B:$B,$A27,Данные!$A:$A,">="&E$1,Данные!$A:$A,"<="&E$2)} -> 435406.09 | F27: {=SUMIFS(Данные!$D:$D,Данные!$B:$B,$A27,Данные!$A:$A,">="&F$1,Данные!$A:$A,"<="&F$2)} -> 72144.07 | G27: {=SUMIFS(Данные!$D:$D,Данные!$B:$B,$A27,Данные!$A:$A,">="&G$1,Данные!$A:$A,"<="&G$2)} -> 0 | H27: {=SUMIFS(Данные!$D:$D,Данные!$B:$B,$A27,Данные!$A:$A,">="&H$1,Данные!$A:$A,"<="&H$2)} -> 225608.62 | I27: {=SUMIFS(Данные!$D:$D,Данные!$B:$B,$A27,Данные!$A:$A,">="&I$1,Данные!$A:$A,"<="&I$2)} -> 0 | ... M27: {=SUMIFS(Данные!$D:$D,Данные!$B:$B,$A27,Данные!$A:$A,">="&M$1,Данные!$A:$A,"<="&M$2)} -> 298260.07 | N27: {=SUM(B27:M27)} -> 1669478.9
A28: {=Статьи!A23} -> Чаи 3 | B28: {=SUMIFS(Данные!$D:$D,Данные!$B:$B,$A28,Данные!$A:$A,">="&B$1,Данные!$A:$A,"<="&B$2)} -> 0 | C28: {=SUMIFS(Данные!$D:$D,Данные!$B:$B,$A28,Данные!$A:$A,">="&C$1,Данные!$A:$A,"<="&C$2)} -> 0 | D28: {=SUMIFS(Данные!$D:$D,Данные!$B:$B,$A28,Данные!$A:$A,">="&D$1,Данные!$A:$A,"<="&D$2)} -> 0 | E28: {=SUMIFS(Данные!$D:$D,Данные!$B:$B,$A28,Данные!$A:$A,">="&E$1,Данные!$A:$A,"<="&E$2)} -> 0 | F28: {=SUMIFS(Данные!$D:$D,Данные!$B:$B,$A28,Данные!$A:$A,">="&F$1,Данные!$A:$A,"<="&F$2)} -> 283986.55 | G28: {=SUMIFS(Данные!$D:$D,Данные!$B:$B,$A28,Данные!$A:$A,">="&G$1,Данные!$A:$A,"<="&G$2)} -> 315607.12 | H28: {=SUMIFS(Данные!$D:$D,Данные!$B:$B,$A28,Данные!$A:$A,">="&H$1,Данные!$A:$A,"<="&H$2)} -> 255552.73 | I28: {=SUMIFS(Данные!$D:$D,Данные!$B:$B,$A28,Данные!$A:$A,">="&I$1,Данные!$A:$A,"<="&I$2)} -> 0 | ... M28: {=SUMIFS(Данные!$D:$D,Данные!$B:$B,$A28,Данные!$A:$A,">="&M$1,Данные!$A:$A,"<="&M$2)} -> 346144.14 | N28: {=SUM(B28:M28)} -> 1133889
A29: {=Статьи!A24} -> Ёлка 3 | B29: {=SUMIFS(Данные!$D:$D,Данные!$B:$B,$A29,Данные!$A:$A,">="&B$1,Данные!$A:$A,"<="&B$2)} -> 379836.22 | C29: {=SUMIFS(Данные!$D:$D,Данные!$B:$B,$A29,Данные!$A:$A,">="&C$1,Данные!$A:$A,"<="&C$2)} -> 0 | D29: {=SUMIFS(Данные!$D:$D,Данные!$B:$B,$A29,Данные!$A:$A,">="&D$1,Данные!$A:$A,"<="&D$2)} -> 0 | E29: {=SUMIFS(Данные!$D:$D,Данные!$B:$B,$A29,Данные!$A:$A,">="&E$1,Данные!$A:$A,"<="&E$2)} -> 0 | F29: {=SUMIFS(Данные!$D:$D,Данные!$B:$B,$A29,Данные!$A:$A,">="&F$1,Данные!$A:$A,"<="&F$2)} -> 1.8817151e+09 | G29: {=SUMIFS(Данные!$D:$D,Данные!$B:$B,$A29,Данные!$A:$A,">="&G$1,Данные!$A:$A,"<="&G$2)} -> 185018.89 | H29: {=SUMIFS(Данные!$D:$D,Данные!$B:$B,$A29,Данные!$A:$A,">="&H$1,Данные!$A:$A,"<="&H$2)} -> 0 | I29: {=SUMIFS(Данные!$D:$D,Данные!$B:$B,$A29,Данные!$A:$A,">="&I$1,Данные!$A:$A,"<="&I$2)} -> 514835.97 | ... M29: {=SUMIFS(Данные!$D:$D,Данные!$B:$B,$A29,Данные!$A:$A,">="&M$1,Данные!$A:$A,"<="&M$2)} -> 87531.96 | N29: {=SUM(B29:M29)} -> 1.8830753e+09
A30: {=Статьи!A25} -> Елка 3 | B30: {=SUMIFS(Данные!$D:$D,Данные!$B:$B,$A30,Данные!$A:$A,">="&B$1,Данные!$A:$A,"<="&B$2)} -> 0 | C30: {=SUMIFS(Данные!$D:$D,Данные!$B:$B,$A30,Данные!$A:$A,">="&C$1,Данные!$A:$A,"<="&C$2)} -> 0 | D30: {=SUMIFS(Данные!$D:$D,Данные!$B:$B,$A30,Данные!$A:$A,">="&D$1,Данные!$A:$A,"<="&D$2)} -> 0 | E30: {=SUMIFS(Данные!$D:$D,Данные!$B:$B,$A30,Данные!$A:$A,">="&E$1,Данные!$A:$A,"<="&E$2)} -> 138812.72 | F30: {=SUMIFS(Данные!$D:$D,Данные!$B:$B,$A30,Данные!$A:$A,">="&F$1,Данные!$A:$A,"<="&F$2)} -> 38193.87 | G30: {=SUMIFS(Данные!$D:$D,Данные!$B:$B,$A30,Данные!$A:$A,">="&G$1,Данные!$A:$A,"<="&G$2)} -> 0 | H30: {=SUMIFS(Данные!$D:$D,Данные!$B:$B,$A30,Данные!$A:$A,">="&H$1,Данные!$A:$A,"<="&H$2)} -> 0 | I30: {=SUMIFS(Данные!$D:$D,Данные!$B:$B,$A30,Данные!$A:$A,">="&I$1,Данные!$A:$A,"<="&I$2)} -> 1.2815172e+09 | ... M30: {=SUMIFS(Данные!$D:$D,Данные!$B:$B,$A30,Данные!$A:$A,">="&M$1,Данные!$A:$A,"<="&M$2)} -> 0 | N30: {=SUM(B30:M30)} -> 1.2820175e+09
A31: {=Статьи!A26} -> Аренда 3 | B31: {=SUMIFS(Данные!$D:$D,Данные!$B:$B,$A31,Данные!$A:$A,">="&B$1,Данные!$A:$A,"<="&B$2)} -> 0 | C31: {=SUMIFS(Данные!$D:$D,Данные!$B:$B,$A31,Данные!$A:$A,">="&C$1,Данные!$A:$A,"<="&C$2)} -> 0 | D31: {=SUMIFS(Данные!$D:$D,Данные!$B:$B,$A31,Данные!$A:$A,">="&D$1,Данные!$A:$A,"<="&D$2)} -> 0 | E31: {=SUMIFS(Данные!$D:$D,Данные!$B:$B,$A31,Данные!$A:$A,">="&E$1,Данные!$A:$A,"<="&E$2)} -> 373909.42 | F31: {=SUMIFS(Данные!$D:$D,Данные!$B:$B,$A31,Данные!$A:$A,">="&F$1,Данные!$A:$A,"<="&F$2)} -> -2930.33 | G31: {=SUMIFS(Данные!$D:$D,Данные!$B:$B,$A31,Данные!$A:$A,">="&G$1,Данные!$A:$A,"<="&G$2)} -> 376896.25 | H31: {=SUMIFS(Данные!$D:$D,Данные!$B:$B,$A31,Данные!$A:$A,">="&H$1,Данные!$A:$A,"<="&H$2)} -> 0 | I31: {=SUMIFS(Данные!$D:$D,Данные!$B:$B,$A31,Данные!$A:$A,">="&I$1,Данные!$A:$A,"<="&I$2)} -> 0 | ... M31: {=SUMIFS(Данные!$D:$D,Данные!$B:$B,$A31,Данные!$A:$A,">="&M$1,Данные!$A:$A,"<="&M$2)} -> 0 | N31: {=SUM(B31:M31)} -> 1891179.2
A32: Итого группа 5 | B32: {=SUM(B27:B31)} -> 436442.84 | C32: {=SUM(C27:C31)} -> 0 | D32: {=SUM(D27:D31)} -> 265561.61 | E32: {=SUM(E27:E31)} -> 948128.23 | F32: {=SUM(F27:F31)} -> 1.8821064e+09 | G32: {=SUM(G27:G31)} -> 877522.26 | H32: {=SUM(H27:H31)} -> 481161.35 | I32: {=SUM(I27:I31)} -> 1.2820321e+09 | ... N32: {=SUM(N27:N31)} -> 3.1697873e+09
A33: {=Статьи!A27} -> Связь 3 | B33: {=SUMIFS(Данные!$D:$D,Данные!$B:$B,$A33,Данные!$A:$A,">="&B$1,Данные!$A:$A,"<="&B$2)} -> 27521.77 | C33: {=SUMIFS(Данные!$D:$D,Данные!$B:$B,$A33,Данные!$A:$A,">="&C$1,Данные!$A:$A,"<="&C$2)} -> 0 | D33: {=SUMIFS(Данные!$D:$D,Данные!$B:$B,$A33,Данные!$A:$A,">="&D$1,Данные!$A:$A,"<="&D$2)} -> 0 | E33: {=SUMIFS(Данные!$D:$D,Данные!$B:$B,$A33,Данные!$A:$A,">="&E$1,Данные!$A:$A,"<="&E$2)} -> 190699 | F33: {=SUMIFS(Данные!$D:$D,Данные!$B:$B,$A33,Данные!$A:$A,">="&F$1,Данные!$A:$A,"<="&F$2)} -> 93549.25 | G33: {=SUMIFS(Данные!$D:$D,Данные!$B:$B,$A33,Данные!$A:$A,">="&G$1,Данные!$A:$A,"<="&G$2)} -> 369197.94 | H33: {=SUMIFS(Данные!$D:$D,Данные!$B:$B,$A33,Данные!$A:$A,">="&H$1,Данные!$A:$A,"<="&H$2)} -> 132793.61 | I33: {=SUMIFS(Данные!$D:$D,Данные!$B:$B,$A33,Данные!$A:$A,">="&I$1,Данные!$A:$A,"<="&I$2)} -> 393482.97 | ... M33: {=SUMIFS(Данные!$D:$D,Данные!$B:$B,$A33,Данные!$A:$A,">="&M$1,Данные!$A:$A,"<="&M$2)} -> 159471.5 | N33: {=SUM(B33:M33)} -> 1852085.3
A34: {=Статьи!A28} -> Налог 3 | B34: {=SUMIFS(Данные!$D:$D,Данные!$B:$B,$A34,Данные!$A:$A,">="&B$1,Данные!$A:$A,"<="&B$2)} -> 0 | C34: {=SUMIFS(Данные!$D:$D,Данные!$B:$B,$A34,Данные!$A:$A,">="&C$1,Данные!$A:$A,"<="&C$2)} -> -59194.5 | D34: {=SUMIFS(Данные!$D:$D,Данные!$B:$B,$A34,Данные!$A:$A,">="&D$1,Данные!$A:$A,"<="&D$2)} -> 0 | E34: {=SUMIFS(Данные!$D:$D,Данные!$B:$B,$A34,Данные!$A:$A,">="&E$1,Данные!$A:$A,"<="&E$2)} -> 0 | F34: {=SUMIFS(Данные!$D:$D,Данные!$B:$B,$A34,Данные!$A:$A,">="&F$1,Данные!$A:$A,"<="&F$2)} -> 280166.41 | G34: {=SUMIFS(Данные!$D:$D,Данные!$B:$B,$A34,Данные!$A:$A,">="&G$1,Данные!$A:$A,"<="&G$2)} -> 0 | H34: {=SUMIFS(Данные!$D:$D,Данные!$B:$B,$A34,Данные!$A:$A,">="&H$1,Данные!$A:$A,"<="&H$2)} -> 0 | I34: {=SUMIFS(Данные!$D:$D,Данные!$B:$B,$A34,Данные!$A:$A,">="&I$1,Данные!$A:$A,"<="&I$2)} -> 295033.37 | ... M34: {=SUMIFS(Данные!$D:$D,Данные!$B:$B,$A34,Данные!$A:$A,">="&M$1,Данные!$A:$A,"<="&M$2)} -> 241153.62 | N34: {=SUM(B34:M34)} -> 933602.78
A35: {=Статьи!A29} -> Доход 3 | B35: {=SUMIFS(Данные!$D:$D,Данные!$B:$B,$A35,Данные!$A:$A,">="&B$1,Данные!$A:$A,"<="&B$2)} -> 371061.55 | C35: {=SUMIFS(Данные!$D:$D,Данные!$B:$B,$A35,Данные!$A:$A,">="&C$1,Данные!$A:$A,"<="&C$2)} -> 50413.46 | D35: {=SUMIFS(Данные!$D:$D,Данные!$B:$B,$A35,Данные!$A:$A,">="&D$1,Данные!$A:$A,"<="&D$2)} -> 387270.57 | E35: {=SUMIFS(Данные!$D:$D,Данные!$B:$B,$A35,Данные!$A:$A,">="&E$1,Данные!$A:$A,"<="&E$2)} -> -19894.29 | F35: {=SUMIFS(Данные!$D:$D,Данные!$B:$B,$A35,Данные!$A:$A,">="&F$1,Данные!$A:$A,"<="&F$2)} -> 320529.04 | G35: {=SUMIFS(Данные!$D:$D,Данные!$B:$B,$A35,Данные!$A:$A,">="&G$1,Данные!$A:$A,"<="&G$2)} -> 0 | H35: {=SUMIFS(Данные!$D:$D,Данные!$B:$B,$A35,Данные!$A:$A,">="&H$1,Данные!$A:$A,"<="&H$2)} -> 584926.12 | I35: {=SUMIFS(Данные!$D:$D,Данные!$B:$B,$A35,Данные!$A:$A,">="&I$1,Данные!$A:$A,"<="&I$2)} -> 0 | ... M35: {=SUMIFS(Данные!$D:$D,Данные!$B:$B,$A35,Данные!$A:$A,">="&M$1,Данные!$A:$A,"<="&M$2)} -> -100543.09 | N35: {=SUM(B35:M35)} -> 1974235.4
A36: {=Статьи!A30} -> Сырьё 3 | B36: {=SUMIFS(Данные!$D:$D,Данные!$B:$B,$A36,Данные!$A:$A,">="&B$1,Данные!$A:$A,"<="&B$2)} -> 354518.59 | C36: {=SUMIFS(Данные!$D:$D,Данные!$B:$B,$A36,Данные!$A:$A,">="&C$1,Данные!$A:$A,"<="&C$2)} -> 204939.46 | D36: {=SUMIFS(Данные!$D:$D,Данные!$B:$B,$A36,Данные!$A:$A,">="&D$1,Данные!$A:$A,"<="&D$2)} -> 191368.37 | E36: {=SUMIFS(Данные!$D:$D,Данные!$B:$B,$A36,Данные!$A:$A,">="&E$1,Данные!$A:$A,"<="&E$2)} -> 0 | F36: {=SUMIFS(Данные!$D:$D,Данные!$B:$B,$A36,Данные!$A:$A,">="&F$1,Данные!$A:$A,"<="&F$2)} -> 287101.89 | G36: {=SUMIFS(Данные!$D:$D,Данные!$B:$B,$A36,Данные!$A:$A,">="&G$1,Данные!$A:$A,"<="&G$2)} -> 644785.7 | H36: {=SUMIFS(Данные!$D:$D,Данные!$B:$B,$A36,Данные!$A:$A,">="&H$1,Данные!$A:$A,"<="&H$2)} -> 0 | I36: {=SUMIFS(Данные!$D:$D,Данные!$B:$B,$A36,Данные!$A:$A,">="&I$1,Данные!$A:$A,"<="&I$2)} -> 0 | ... M36: {=SUMIFS(Данные!$D:$D,Данные!$B:$B,$A36,Данные!$A:$A,">="&M$1,Данные!$A:$A,"<="&M$2)} -> 0 | N36: {=SUM(B36:M36)} -> 1656921
A37: {=Статьи!A31} -> Сырье 3 | B37: {=SUMIFS(Данные!$D:$D,Данные!$B:$B,$A37,Данные!$A:$A,">="&B$1,Данные!$A:$A,"<="&B$2)} -> 0 | C37: {=SUMIFS(Данные!$D:$D,Данные!$B:$B,$A37,Данные!$A:$A,">="&C$1,Данные!$A:$A,"<="&C$2)} -> 0 | D37: {=SUMIFS(Данные!$D:$D,Данные!$B:$B,$A37,Данные!$A:$A,">="&D$1,Данные!$A:$A,"<="&D$2)} -> 0 | E37: {=SUMIFS(Данные!$D:$D,Данные!$B:$B,$A37,Данные!$A:$A,">="&E$1,Данные!$A:$A,"<="&E$2)} -> 0 | F37: {=SUMIFS(Данные!$D:$D,Данные!$B:$B,$A37,Данные!$A:$A,">="&F$1,Данные!$A:$A,"<="&F$2)} -> 0 | G37: {=SUMIFS(Данные!$D:$D,Данные!$B:$B,$A37,Данные!$A:$A,">="&G$1,Данные!$A:$A,"<="&G$2)} -> 541045.82 | H37: {=SUMIFS(Данные!$D:$D,Данные!$B:$B,$A37,Данные!$A:$A,">="&H$1,Данные!$A:$A,"<="&H$2)} -> 167126.5 | I37: {=SUMIFS(Данные!$D:$D,Данные!$B:$B,$A37,Данные!$A:$A,">="&I$1,Данные!$A:$A,"<="&I$2)} -> 0 | ... M37: {=SUMIFS(Данные!$D:$D,Данные!$B:$B,$A37,Данные!$A:$A,">="&M$1,Данные!$A:$A,"<="&M$2)} -> 0 | N37: {=SUM(B37:M37)} -> 682903.28
A38: Итого группа 6 | B38: {=SUM(B33:B37)} -> 753101.91 | C38: {=SUM(C33:C37)} -> 196158.42 | D38: {=SUM(D33:D37)} -> 578638.94 | E38: {=SUM(E33:E37)} -> 170804.71 | F38: {=SUM(F33:F37)} -> 981346.59 | G38: {=SUM(G33:G37)} -> 1555029.5 | H38: {=SUM(H33:H37)} -> 884846.23 | I38: {=SUM(I33:I37)} -> 688516.34 | ... N38: {=SUM(N33:N37)} -> 7099747.8
A39: {=Статьи!A32} -> Чай 4 | B39: {=SUMIFS(Данные!$D:$D,Данные!$B:$B,$A39,Данные!$A:$A,">="&B$1,Данные!$A:$A,"<="&B$2)} -> 0 | C39: {=SUMIFS(Данные!$D:$D,Данные!$B:$B,$A39,Данные!$A:$A,">="&C$1,Данные!$A:$A,"<="&C$2)} -> 0 | D39: {=SUMIFS(Данные!$D:$D,Данные!$B:$B,$A39,Данные!$A:$A,">="&D$1,Данные!$A:$A,"<="&D$2)} -> 0 | E39: {=SUMIFS(Данные!$D:$D,Данные!$B:$B,$A39,Данные!$A:$A,">="&E$1,Данные!$A:$A,"<="&E$2)} -> 0 | F39: {=SUMIFS(Данные!$D:$D,Данные!$B:$B,$A39,Данные!$A:$A,">="&F$1,Данные!$A:$A,"<="&F$2)} -> 0 | G39: {=SUMIFS(Данные!$D:$D,Данные!$B:$B,$A39,Данные!$A:$A,">="&G$1,Данные!$A:$A,"<="&G$2)} -> 0 | H39: {=SUMIFS(Данные!$D:$D,Данные!$B:$B,$A39,Данные!$A:$A,">="&H$1,Данные!$A:$A,"<="&H$2)} -> 206502.25 | I39: {=SUMIFS(Данные!$D:$D,Данные!$B:$B,$A39,Данные!$A:$A,">="&I$1,Данные!$A:$A,"<="&I$2)} -> 412631.83 | ... M39: {=SUMIFS(Данные!$D:$D,Данные!$B:$B,$A39,Данные!$A:$A,">="&M$1,Данные!$A:$A,"<="&M$2)} -> 286133.45 | N39: {=SUM(B39:M39)} -> 814966.76
A40: {=Статьи!A33} -> Чаи 4 | B40: {=SUMIFS(Данные!$D:$D,Данные!$B:$B,$A40,Данные!$A:$A,">="&B$1,Данные!$A:$A,"<="&B$2)} -> 0 | C40: {=SUMIFS(Данные!$D:$D,Данные!$B:$B,$A40,Данные!$A:$A,">="&C$1,Данные!$A:$A,"<="&C$2)} -> -82546.68 | D40: {=SUMIFS(Данные!$D:$D,Данные!$B:$B,$A40,Данные!$A:$A,">="&D$1,Данные!$A:$A,"<="&D$2)} -> 0 | E40: {=SUMIFS(Данные!$D:$D,Данные!$B:$B,$A40,Данные!$A:$A,">="&E$1,Данные!$A:$A,"<="&E$2)} -> -1902.9 | F40: {=SUMIFS(Данные!$D:$D,Данные!$B:$B,$A40,Данные!$A:$A,">="&F$1,Данные!$A:$A,"<="&F$2)} -> 0 | G40: {=SUMIFS(Данные!$D:$D,Данные!$B:$B,$A40,Данные!$A:$A,">="&G$1,Данные!$A:$A,"<="&G$2)} -> -7931.29 | H40: {=SUMIFS(Данные!$D:$D,Данные!$B:$B,$A40,Данные!$A:$A,">="&H$1,Данные!$A:$A,"<="&H$2)} -> 0 | I40: {=SUMIFS(Данные!$D:$D,Данные!$B:$B,$A40,Данные!$A:$A,">="&I$1,Данные!$A:$A,"<="&I$2)} -> 0 | ... M40: {=SUMIFS(Данные!$D:$D,Данные!$B:$B,$A40,Данные!$A:$A,">="&M$1,Данные!$A:$A,"<="&M$2)} -> 0 | N40: {=SUM(B40:M40)} -> 378721.45
...

Sheet ПоПроектам
A1: ПоПроектам | B1: П01 | C1: П02 | D1: П03 | E1: П04 | F1: П05 | G1: П06 | H1: П07 | I1: П08 | J1: П09 | K1: П10 | L1: П11 | M1: П12 | N1: П13 | O1: П14 | P1: П15
A2: {=Статьи!A2} -> Чай 1 | B2: {=SUMIFS(Данные!$D$2:$D$341,Данные!$B$2:$B$341,$A2,Данные!$F$2:$F$341,B$1,Данные!$A$2:$A$341,">="&Параметры!$B$1,Данные!$A$2:$A$341,"<="&Параметры!$B$2,Данные!$E$2:$E$341,Параметры!$B$4)} -> 0 | C2: {=SUMIFS(Данные!$D$2:$D$341,Данные!$B$2:$B$341,$A2,Данные!$F$2:$F$341,C$1,Данные!$A$2:$A$341,">="&Параметры!$B$1,Данные!$A$2:$A$341,"<="&Параметры!$B$2,Данные!$E$2:$E$341,Параметры!$B$4)} -> 275047.94 | D2: {=SUMIFS(Данные!$D$2:$D$341,Данные!$B$2:$B$341,$A2,Данные!$F$2:$F$341,D$1,Данные!$A$2:$A$341,">="&Параметры!$B$1,Данные!$A$2:$A$341,"<="&Параметры!$B$2,Данные!$E$2:$E$341,Параметры!$B$4)} -> 0 | E2: {=SUMIFS(Данные!$D$2:$D$341,Данные!$B$2:$B$341,$A2,Данные!$F$2:$F$341,E$1,Данные!$A$2:$A$341,">="&Параметры!$B$1,Данные!$A$2:$A$341,"<="&Параметры!$B$2,Данные!$E$2:$E$341,Параметры!$B$4)} -> 0 | F2: {=SUMIFS(Данные!$D$2:$D$341,Данные!$B$2:$B$341,$A2,Данные!$F$2:$F$341,F$1,Данные!$A$2:$A$341,">="&Параметры!$B$1,Данные!$A$2:$A$341,"<="&Параметры!$B$2,Данные!$E$2:$E$341,Параметры!$B$4)} -> 0 | G2: {=SUMIFS(Данные!$D$2:$D$341,Данные!$B$2:$B$341,$A2,Данные!$F$2:$F$341,G$1,Данные!$A$2:$A$341,">="&Параметры!$B$1,Данные!$A$2:$A$341,"<="&Параметры!$B$2,Данные!$E$2:$E$341,Параметры!$B$4)} -> 0 | H2: {=SUMIFS(Данные!$D$2:$D$341,Данные!$B$2:$B$341,$A2,Данные!$F$2:$F$341,H$1,Данные!$A$2:$A$341,">="&Параметры!$B$1,Данные!$A$2:$A$341,"<="&Параметры!$B$2,Данные!$E$2:$E$341,Параметры!$B$4)} -> 0 | I2: {=SUMIFS(Данные!$D$2:$D$341,Данные!$B$2:$B$341,$A2,Данные!$F$2:$F$341,I$1,Данные!$A$2:$A$341,">="&Параметры!$B$1,Данные!$A$2:$A$341,"<="&Параметры!$B$2,Данные!$E$2:$E$341,Параметры!$B$4)} -> 0 | ... P2: {=SUMIFS(Данные!$D$2:$D$341,Данные!$B$2:$B$341,$A2,Данные!$F$2:$F$341,P$1,Данные!$A$2:$A$341,">="&Параметры!$B$1,Данные!$A$2:$A$341,"<="&Параметры!$B$2,Данные!$E$2:$E$341,Параметры!$B$4)} -> 0 | Q2: {=SUM(B2:P2)} -> 788324.44
A3: {=Статьи!A3} -> Чаи 1 | B3: {=SUMIFS(Данные!$D$2:$D$341,Данные!$B$2:$B$341,$A3,Данные!$F$2:$F$341,B$1,Данные!$A$2:$A$341,">="&Параметры!$B$1,Данные!$A$2:$A$341,"<="&Параметры!$B$2,Данные!$E$2:$E$341,Параметры!$B$4)} -> 0 | C3: {=SUMIFS(Данные!$D$2:$D$341,Данные!$B$2:$B$341,$A3,Данные!$F$2:$F$341,C$1,Данные!$A$2:$A$341,">="&Параметры!$B$1,Данные!$A$2:$A$341,"<="&Параметры!$B$2,Данные!$E$2:$E$341,Параметры!$B$4)} -> -21827.39 | D3: {=SUMIFS(Данные!$D$2:$D$341,Данные!$B$2:$B$341,$A3,Данные!$F$2:$F$341,D$1,Данные!$A$2:$A$341,">="&Параметры!$B$1,Данные!$A$2:$A$341,"<="&Параметры!$B$2,Данные!$E$2:$E$341,Параметры!$B$4)} -> 0 | E3: {=SUMIFS(Данные!$D$2:$D$341,Данные!$B$2:$B$341,$A3,Данные!$F$2:$F$341,E$1,Данные!$A$2:$A$341,">="&Параметры!$B$1,Данные!$A$2:$A$341,"<="&Параметры!$B$2,Данные!$E$2:$E$341,Параметры!$B$4)} -> 0 | F3: {=SUMIFS(Данные!$D$2:$D$341,Данные!$B$2:$B$341,$A3,Данные!$F$2:$F$341,F$1,Данные!$A$2:$A$341,">="&Параметры!$B$1,Данные!$A$2:$A$341,"<="&Параметры!$B$2,Данные!$E$2:$E$341,Параметры!$B$4)} -> 0 | G3: {=SUMIFS(Данные!$D$2:$D$341,Данные!$B$2:$B$341,$A3,Данные!$F$2:$F$341,G$1,Данные!$A$2:$A$341,">="&Параметры!$B$1,Данные!$A$2:$A$341,"<="&Параметры!$B$2,Данные!$E$2:$E$341,Параметры!$B$4)} -> 635132.9 | H3: {=SUMIFS(Данные!$D$2:$D$341,Данные!$B$2:$B$341,$A3,Данные!$F$2:$F$341,H$1,Данные!$A$2:$A$341,">="&Параметры!$B$1,Данные!$A$2:$A$341,"<="&Параметры!$B$2,Данные!$E$2:$E$341,Параметры!$B$4)} -> 0 | I3: {=SUMIFS(Данные!$D$2:$D$341,Данные!$B$2:$B$341,$A3,Данные!$F$2:$F$341,I$1,Данные!$A$2:$A$341,">="&Параметры!$B$1,Данные!$A$2:$A$341,"<="&Параметры!$B$2,Данные!$E$2:$E$341,Параметры!$B$4)} -> -6678.65 | ... P3: {=SUMIFS(Данные!$D$2:$D$341,Данные!$B$2:$B$341,$A3,Данные!$F$2:$F$341,P$1,Данные!$A$2:$A$341,">="&Параметры!$B$1,Данные!$A$2:$A$341,"<="&Параметры!$B$2,Данные!$E$2:$E$341,Параметры!$B$4)} -> 0 | Q3: {=SUM(B3:P3)} -> 1345676.9
A4: {=Статьи!A4} -> Ёлка 1 | B4: {=SUMIFS(Данные!$D$2:$D$341,Данные!$B$2:$B$341,$A4,Данные!$F$2:$F$341,B$1,Данные!$A$2:$A$341,">="&Параметры!$B$1,Данные!$A$2:$A$341,"<="&Параметры!$B$2,Данные!$E$2:$E$341,Параметры!$B$4)} -> 0 | C4: {=SUMIFS(Данные!$D$2:$D$341,Данные!$B$2:$B$341,$A4,Данные!$F$2:$F$341,C$1,Данные!$A$2:$A$341,">="&Параметры!$B$1,Данные!$A$2:$A$341,"<="&Параметры!$B$2,Данные!$E$2:$E$341,Параметры!$B$4)} -> 0 | D4: {=SUMIFS(Данные!$D$2:$D$341,Данные!$B$2:$B$341,$A4,Данные!$F$2:$F$341,D$1,Данные!$A$2:$A$341,">="&Параметры!$B$1,Данные!$A$2:$A$341,"<="&Параметры!$B$2,Данные!$E$2:$E$341,Параметры!$B$4)} -> 0 | E4: {=SUMIFS(Данные!$D$2:$D$341,Данные!$B$2:$B$341,$A4,Данные!$F$2:$F$341,E$1,Данные!$A$2:$A$341,">="&Параметры!$B$1,Данные!$A$2:$A$341,"<="&Параметры!$B$2,Данные!$E$2:$E$341,Параметры!$B$4)} -> 0 | F4: {=SUMIFS(Данные!$D$2:$D$341,Данные!$B$2:$B$341,$A4,Данные!$F$2:$F$341,F$1,Данные!$A$2:$A$341,">="&Параметры!$B$1,Данные!$A$2:$A$341,"<="&Параметры!$B$2,Данные!$E$2:$E$341,Параметры!$B$4)} -> 0 | G4: {=SUMIFS(Данные!$D$2:$D$341,Данные!$B$2:$B$341,$A4,Данные!$F$2:$F$341,G$1,Данные!$A$2:$A$341,">="&Параметры!$B$1,Данные!$A$2:$A$341,"<="&Параметры!$B$2,Данные!$E$2:$E$341,Параметры!$B$4)} -> 222968.2 | H4: {=SUMIFS(Данные!$D$2:$D$341,Данные!$B$2:$B$341,$A4,Данные!$F$2:$F$341,H$1,Данные!$A$2:$A$341,">="&Параметры!$B$1,Данные!$A$2:$A$341,"<="&Параметры!$B$2,Данные!$E$2:$E$341,Параметры!$B$4)} -> 0 | I4: {=SUMIFS(Данные!$D$2:$D$341,Данные!$B$2:$B$341,$A4,Данные!$F$2:$F$341,I$1,Данные!$A$2:$A$341,">="&Параметры!$B$1,Данные!$A$2:$A$341,"<="&Параметры!$B$2,Данные!$E$2:$E$341,Параметры!$B$4)} -> 0 | ... P4: {=SUMIFS(Данные!$D$2:$D$341,Данные!$B$2:$B$341,$A4,Данные!$F$2:$F$341,P$1,Данные!$A$2:$A$341,">="&Параметры!$B$1,Данные!$A$2:$A$341,"<="&Параметры!$B$2,Данные!$E$2:$E$341,Параметры!$B$4)} -> 22033.51 | Q4: {=SUM(B4:P4)} -> 245001.71
A5: {=Статьи!A5} -> Елка 1 | B5: {=SUMIFS(Данные!$D$2:$D$341,Данные!$B$2:$B$341,$A5,Данные!$F$2:$F$341,B$1,Данные!$A$2:$A$341,">="&Параметры!$B$1,Данные!$A$2:$A$341,"<="&Параметры!$B$2,Данные!$E$2:$E$341,Параметры!$B$4)} -> 0 | C5: {=SUMIFS(Данные!$D$2:$D$341,Данные!$B$2:$B$341,$A5,Данные!$F$2:$F$341,C$1,Данные!$A$2:$A$341,">="&Параметры!$B$1,Данные!$A$2:$A$341,"<="&Параметры!$B$2,Данные!$E$2:$E$341,Параметры!$B$4)} -> 230678.07 | D5: {=SUMIFS(Данные!$D$2:$D$341,Данные!$B$2:$B$341,$A5,Данные!$F$2:$F$341,D$1,Данные!$A$2:$A$341,">="&Параметры!$B$1,Данные!$A$2:$A$341,"<="&Параметры!$B$2,Данные!$E$2:$E$341,Параметры!$B$4)} -> 0 | E5: {=SUMIFS(Данные!$D$2:$D$341,Данные!$B$2:$B$341,$A5,Данные!$F$2:$F$341,E$1,Данные!$A$2:$A$341,">="&Параметры!$B$1,Данные!$A$2:$A$341,"<="&Параметры!$B$2,Данные!$E$2:$E$341,Параметры!$B$4)} -> 147133.95 | F5: {=SUMIFS(Данные!$D$2:$D$341,Данные!$B$2:$B$341,$A5,Данные!$F$2:$F$341,F$1,Данные!$A$2:$A$341,">="&Параметры!$B$1,Данные!$A$2:$A$341,"<="&Параметры!$B$2,Данные!$E$2:$E$341,Параметры!$B$4)} -> -73227.26 | G5: {=SUMIFS(Данные!$D$2:$D$341,Данные!$B$2:$B$341,$A5,Данные!$F$2:$F$341,G$1,Данные!$A$2:$A$341,">="&Параметры!$B$1,Данные!$A$2:$A$341,"<="&Параметры!$B$2,Данные!$E$2:$E$341,Параметры!$B$4)} -> 285461.58 | H5: {=SUMIFS(Данные!$D$2:$D$341,Данные!$B$2:$B$341,$A5,Данные!$F$2:$F$341,H$1,Данные!$A$2:$A$341,">="&Параметры!$B$1,Данные!$A$2:$A$341,"<="&Параметры!$B$2,Данные!$E$2:$E$341,Параметры!$B$4)} -> 142440.89 | I5: {=SUMIFS(Данные!$D$2:$D$341,Данные!$B$2:$B$341,$A5,Данные!$F$2:$F$341,I$1,Данные!$A$2:$A$341,">="&Параметры!$B$1,Данные!$A$2:$A$341,"<="&Параметры!$B$2,Данные!$E$2:$E$341,Параметры!$B$4)} -> 0 | ... P5: {=SUMIFS(Данные!$D$2:$D$341,Данные!$B$2:$B$341,$A5,Данные!$F$2:$F$341,P$1,Данные!$A$2:$A$341,">="&Параметры!$B$1,Данные!$A$2:$A$341,"<="&Параметры!$B$2,Данные!$E$2:$E$341,Параметры!$B$4)} -> 0 | Q5: {=SUM(B5:P5)} -> 732487.23
A6: {=Статьи!A6} -> Аренда 1 | B6: {=SUMIFS(Данные!$D$2:$D$341,Данные!$B$2:$B$341,$A6,Данные!$F$2:$F$341,B$1,Данные!$A$2:$A$341,">="&Параметры!$B$1,Данные!$A$2:$A$341,"<="&Параметры!$B$2,Данные!$E$2:$E$341,Параметры!$B$4)} -> 345306.23 | C6: {=SUMIFS(Данные!$D$2:$D$341,Данные!$B$2:$B$341,$A6,Данные!$F$2:$F$341,C$1,Данные!$A$2:$A$341,">="&Параметры!$B$1,Данные!$A$2:$A$341,"<="&Параметры!$B$2,Данные!$E$2:$E$341,Параметры!$B$4)} -> 0 | D6: {=SUMIFS(Данные!$D$2:$D$341,Данные!$B$2:$B$341,$A6,Данные!$F$2:$F$341,D$1,Данные!$A$2:$A$341,">="&Параметры!$B$1,Данные!$A$2:$A$341,"<="&Параметры!$B$2,Данные!$E$2:$E$341,Параметры!$B$4)} -> 0 | E6: {=SUMIFS(Данные!$D$2:$D$341,Данные!$B$2:$B$341,$A6,Данные!$F$2:$F$341,E$1,Данные!$A$2:$A$341,">="&Параметры!$B$1,Данные!$A$2:$A$341,"<="&Параметры!$B$2,Данные!$E$2:$E$341,Параметры!$B$4)} -> 0 | F6: {=SUMIFS(Данные!$D$2:$D$341,Данные!$B$2:$B$341,$A6,Данные!$F$2:$F$341,F$1,Данные!$A$2:$A$341,">="&Параметры!$B$1,Данные!$A$2:$A$341,"<="&Параметры!$B$2,Данные!$E$2:$E$341,Параметры!$B$4)} -> 0 | G6: {=SUMIFS(Данные!$D$2:$D$341,Данные!$B$2:$B$341,$A6,Данные!$F$2:$F$341,G$1,Данные!$A$2:$A$341,">="&Параметры!$B$1,Данные!$A$2:$A$341,"<="&Параметры!$B$2,Данные!$E$2:$E$341,Параметры!$B$4)} -> 0 | H6: {=SUMIFS(Данные!$D$2:$D$341,Данные!$B$2:$B$341,$A6,Данные!$F$2:$F$341,H$1,Данные!$A$2:$A$341,">="&Параметры!$B$1,Данные!$A$2:$A$341,"<="&Параметры!$B$2,Данные!$E$2:$E$341,Параметры!$B$4)} -> 0 | I6: {=SUMIFS(Данные!$D$2:$D$341,Данные!$B$2:$B$341,$A6,Данные!$F$2:$F$341,I$1,Данные!$A$2:$A$341,">="&Параметры!$B$1,Данные!$A$2:$A$341,"<="&Параметры!$B$2,Данные!$E$2:$E$341,Параметры!$B$4)} -> 0 | ... P6: {=SUMIFS(Данные!$D$2:$D$341,Данные!$B$2:$B$341,$A6,Данные!$F$2:$F$341,P$1,Данные!$A$2:$A$341,">="&Параметры!$B$1,Данные!$A$2:$A$341,"<="&Параметры!$B$2,Данные!$E$2:$E$341,Параметры!$B$4)} -> 0 | Q6: {=SUM(B6:P6)} -> 552992.4
A7: Итого группа 1 | B7: {=SUM(B2:B6)} -> 345306.23 | C7: {=SUM(C2:C6)} -> 483898.62 | D7: {=SUM(D2:D6)} -> 0 | E7: {=SUM(E2:E6)} -> 147133.95 | F7: {=SUM(F2:F6)} -> -73227.26 | G7: {=SUM(G2:G6)} -> 1143562.7 | H7: {=SUM(H2:H6)} -> 142440.89 | I7: {=SUM(I2:I6)} -> -6678.65 | ... Q7: {=SUM(Q2:Q6)} -> 3664482.7
A8: {=Статьи!A7} -> Связь 1 | B8: {=SUMIFS(Данные!$D$2:$D$341,Данные!$B$2:$B$341,$A8,Данные!$F$2:$F$341,B$1,Данные!$A$2:$A$341,">="&Параметры!$B$1,Данные!$A$2:$A$341,"<="&Параметры!$B$2,Данные!$E$2:$E$341,Параметры!$B$4)} -> 0 | C8: {=SUMIFS(Данные!$D$2:$D$341,Данные!$B$2:$B$341,$A8,Данные!$F$2:$F$341,C$1,Данные!$A$2:$A$341,">="&Параметры!$B$1,Данные!$A$2:$A$341,"<="&Параметры!$B$2,Данные!$E$2:$E$341,Параметры!$B$4)} -> 0 | D8: {=SUMIFS(Данные!$D$2:$D$341,Данные!$B$2:$B$341,$A8,Данные!$F$2:$F$341,D$1,Данные!$A$2:$A$341,">="&Параметры!$B$1,Данные!$A$2:$A$341,"<="&Параметры!$B$2,Данные!$E$2:$E$341,Параметры!$B$4)} -> 78369.71 | E8: {=SUMIFS(Данные!$D$2:$D$341,Данные!$B$2:$B$341,$A8,Данные!$F$2:$F$341,E$1,Данные!$A$2:$A$341,">="&Параметры!$B$1,Данные!$A$2:$A$341,"<="&Параметры!$B$2,Данные!$E$2:$E$341,Параметры!$B$4)} -> 290338.51 | F8: {=SUMIFS(Данные!$D$2:$D$341,Данные!$B$2:$B$341,$A8,Данные!$F$2:$F$341,F$1,Данные!$A$2:$A$341,">="&Параметры!$B$1,Данные!$A$2:$A$341,"<="&Параметры!$B$2,Данные!$E$2:$E$341,Параметры!$B$4)} -> 0 | G8: {=SUMIFS(Данные!$D$2:$D$341,Данные!$B$2:$B$341,$A8,Данные!$F$2:$F$341,G$1,Данные!$A$2:$A$341,">="&Параметры!$B$1,Данные!$A$2:$A$341,"<="&Параметры!$B$2,Данные!$E$2:$E$341,Параметры!$B$4)} -> 0 | H8: {=SUMIFS(Данные!$D$2:$D$341,Данные!$B$2:$B$341,$A8,Данные!$F$2:$F$341,H$1,Данные!$A$2:$A$341,">="&Параметры!$B$1,Данные!$A$2:$A$341,"<="&Параметры!$B$2,Данные!$E$2:$E$341,Параметры!$B$4)} -> 0 | I8: {=SUMIFS(Данные!$D$2:$D$341,Данные!$B$2:$B$341,$A8,Данные!$F$2:$F$341,I$1,Данные!$A$2:$A$341,">="&Параметры!$B$1,Данные!$A$2:$A$341,"<="&Параметры!$B$2,Данные!$E$2:$E$341,Параметры!$B$4)} -> 0 | ... P8: {=SUMIFS(Данные!$D$2:$D$341,Данные!$B$2:$B$341,$A8,Данные!$F$2:$F$341,P$1,Данные!$A$2:$A$341,">="&Параметры!$B$1,Данные!$A$2:$A$341,"<="&Параметры!$B$2,Данные!$E$2:$E$341,Параметры!$B$4)} -> 0 | Q8: {=SUM(B8:P8)} -> 589986.43
A9: {=Статьи!A8} -> Налог 1 | B9: {=SUMIFS(Данные!$D$2:$D$341,Данные!$B$2:$B$341,$A9,Данные!$F$2:$F$341,B$1,Данные!$A$2:$A$341,">="&Параметры!$B$1,Данные!$A$2:$A$341,"<="&Параметры!$B$2,Данные!$E$2:$E$341,Параметры!$B$4)} -> 0 | C9: {=SUMIFS(Данные!$D$2:$D$341,Данные!$B$2:$B$341,$A9,Данные!$F$2:$F$341,C$1,Данные!$A$2:$A$341,">="&Параметры!$B$1,Данные!$A$2:$A$341,"<="&Параметры!$B$2,Данные!$E$2:$E$341,Параметры!$B$4)} -> 24606.32 | D9: {=SUMIFS(Данные!$D$2:$D$341,Данные!$B$2:$B$341,$A9,Данные!$F$2:$F$341,D$1,Данные!$A$2:$A$341,">="&Параметры!$B$1,Данные!$A$2:$A$341,"<="&Параметры!$B$2,Данные!$E$2:$E$341,Параметры!$B$4)} -> 0 | E9: {=SUMIFS(Данные!$D$2:$D$341,Данные!$B$2:$B$341,$A9,Данные!$F$2:$F$341,E$1,Данные!$A$2:$A$341,">="&Параметры!$B$1,Данные!$A$2:$A$341,"<="&Параметры!$B$2,Данные!$E$2:$E$341,Параметры!$B$4)} -> 94760.89 | F9: {=SUMIFS(Данные!$D$2:$D$341,Данные!$B$2:$B$341,$A9,Данные!$F$2:$F$341,F$1,Данные!$A$2:$A$341,">="&Параметры!$B$1,Данные!$A$2:$A$341,"<="&Параметры!$B$2,Данные!$E$2:$E$341,Параметры!$B$4)} -> 0 | G9: {=SUMIFS(Данные!$D$2:$D$341,Данные!$B$2:$B$341,$A9,Данные!$F$2:$F$341,G$1,Данные!$A$2:$A$341,">="&Параметры!$B$1,Данные!$A$2:$A$341,"<="&Параметры!$B$2,Данные!$E$2:$E$341,Параметры!$B$4)} -> 0 | H9: {=SUMIFS(Данные!$D$2:$D$341,Данные!$B$2:$B$341,$A9,Данные!$F$2:$F$341,H$1,Данные!$A$2:$A$341,">="&Параметры!$B$1,Данные!$A$2:$A$341,"<="&Параметры!$B$2,Данные!$E$2:$E$341,Параметры!$B$4)} -> 0 | I9: {=SUMIFS(Данные!$D$2:$D$341,Данные!$B$2:$B$341,$A9,Данные!$F$2:$F$341,I$1,Данные!$A$2:$A$341,">="&Параметры!$B$1,Данные!$A$2:$A$341,"<="&Параметры!$B$2,Данные!$E$2:$E$341,Параметры!$B$4)} -> 0 | ... P9: {=SUMIFS(Данные!$D$2:$D$341,Данные!$B$2:$B$341,$A9,Данные!$F$2:$F$341,P$1,Данные!$A$2:$A$341,">="&Параметры!$B$1,Данные!$A$2:$A$341,"<="&Параметры!$B$2,Данные!$E$2:$E$341,Параметры!$B$4)} -> 0 | Q9: {=SUM(B9:P9)} -> 458743.56
