Workbook

Sheet NI
A1: =1-1*2^-53 -> 1
A2: =1-1*2^-52 -> 1
A3: =1-1*2^-51 -> 1
A4: =1-1*2^-50 -> 1
A5: =1-1*2^-49 -> 1
A6: =1-1*2^-48 -> 1
A7: =1-1*2^-47 -> 1
A8: =1-1*2^-46 -> 1
A9: =1-1*2^-45 -> 1
A10: =1-1*2^-44 -> 1
A11: =1-1*2^-43 -> 1
A12: =1-1*2^-42 -> 1
A13: =1-1*2^-40 -> 1
A14: =1-1*2^-37 -> 1
A15: =1-1*2^-33 -> 1
A16: =1-1*2^-27 -> 0.99999999
A17: =1-1*2^-20 -> 0.99999905
A18: =2-2*2^-53 -> 2
A19: =2-2*2^-52 -> 2
A20: =2-2*2^-51 -> 2
A21: =2-2*2^-50 -> 2
A22: =2-2*2^-49 -> 2
A23: =2-2*2^-48 -> 2
A24: =2-2*2^-47 -> 2
A25: =2-2*2^-46 -> 2
A26: =2-2*2^-45 -> 2
A27: =2-2*2^-44 -> 2
A28: =2-2*2^-43 -> 2
A29: =2-2*2^-42 -> 2
A30: =2-2*2^-40 -> 2
A31: =2-2*2^-37 -> 2
A32: =2-2*2^-33 -> 2
A33: =2-2*2^-27 -> 2
A34: =2-2*2^-20 -> 1.9999981
A35: =3-3*2^-53 -> 3
A36: =3-3*2^-52 -> 3
A37: =3-3*2^-51 -> 3
A38: =3-3*2^-50 -> 3
A39: =3-3*2^-49 -> 3
A40: =3-3*2^-48 -> 3
...

Sheet D
B1: 4 | C1: 2 | D1: 1 | E1: 1 | F1: Аренда | G1: 1 | H1: 45657 | I1: -10000 | J1: -10000 | L1: 1 | M1: one | N1: 10 | P1: 1 | Q1: 2 | R1: 5 | S1: 6 | U1: Tree | V1: Height | W1: Age | X1: Yield | Y1: Profit | AA1: Tree | AB1: Height | AC1: Tree | AD1: Tree | AE1: Tree | AF1: Tree | AG1: Tree | AH1: 0 | AI1: 0.2 | AK1: 58 | AL1: 35 | AM1: 45.35 | AN1: 47.65 | AP1: 41235 | AQ1: 0.09 | AR1: 1 | AS1: 1 | AT1: 0 | AU1: 39448 | AV1: 4 | AW1: TRUE | AX1: TRUE | AY1: 3 | AZ1: 1 | BA1: 6 | BB1: 33100 | BC1: 11 | BD1: 17 | BE1: 89 | BF1: 1 | BG1: 1 | BH1: a
A2: 2 | B2: 8 | C2: 7 | D2: 2 | E2: 2 | F2: аренда | G2: 2 | H2: 45658 | I2: 3000 | J2: 2750 | L2: 2 | M2: two | N2: 20 | P2: 3 | Q2: 4 | R2: 7 | S2: 8 | U2: Apple | V2: 18 | W2: 20 | X2: 14 | Y2: 105 | AA2: Apple | AB2: >10 | AC2: Pear | AD2: a* | AE2: Cherry | AF2: Plum | AH2: 1 | AI2: 0.3 | AK2: 11 | AL2: 25 | AM2: 17.56 | AN2: 18.44 | AP2: 41247 | AQ2: 0.11 | AR2: -0.5 | AS2: 2 | AT2: 10 | AU2: 39508 | AV2: 5 | AW2: FALSE | AX2: TRUE | AY2: 5 | AZ2: 2 | BA2: 7 | BB2: 47300 | BC2: 12 | BD2: 18 | BE2: 88 | BF2: 2 | BG2: 2
A3: abc | B3: 15 | C3: 11 | D3: abc | E3: =1/0 -> #DIV/0! | F3: Арендй | G3: 4 | H3: 45659 | I3: 4200 | J3: 4250 | L3: 3 | M3: three | N3: 30 | U3: Pear | V3: 12 | W3: 12 | X3: 10 | Y3: 96 | AH3: 2 | AI3: 0.1 | AK3: 10 | AL3: 23 | AM3: 16.09 | AN3: 16.91 | AP3: 41295 | AQ3: 0.1 | AR3: 0.041666667 | AS3: 2 | AT3: 20 | AU3: 39751 | AV3: 8 | AW3: abc | AX3: 1 | AY3: 7 | AZ3: 3 | BB3: 69000 | BC3: 13 | BE3: 92 | BF3: 2 | BG3: 3 | BH3: Б
A4: TRUE | B4: 16 | C4: 19 | D4: TRUE | E4: 4 | F4: Арeнда* | G4: 8 | H4: 45689 | I4: 6800 | J4: 3250 | L4: 5 | M4: five | N4: 50 | P4: 1 | Q4: 2 | R4: 3 | U4: Cherry | V4: 13 | W4: 14 | X4: 9 | Y4: 105 | AH4: 3 | AI4: 0.4 | AP4: 39778 | AR4: -0.0013888889 | AS4: a | AU4: 39859 | AV4: 7 | AY4: 10 | AZ4: 4 | BB4: 102000 | BC4: 14 | BE4: 101 | BF4: 3 | BG4: 4
A5: FALSE | B5: 23 | C5: 21 | E5: 5 | F5: x*y | G5: 16 | H5: 45717 | I5: 1200 | J5: 2750 | L5: 8 | M5: eight | N5: 80 | P5: 4 | Q5: 5 | R5: 6 | U5: Apple | V5: 14 | W5: 15 | X5: 10 | Y5: 75 | AK5: 58 | AL5: 35 | AP5: 39786 | AS5: A | AU5: 39904 | AV5: 11 | AY5: 11 | AZ5: 5 | BB5: 150000 | BC5: 15 | BE5: 94 | BF5: 5 | BG5: 3
A6: 45688 | B6: 42 | C6: 40 | D6: 5 | E6: 6 | F6: Чай | G6: 32 | H6: 45473 | L6: 13 | M6: thirteen | N6: 130 | U6: Pear | V6: 9 | W6: 8 | X6: 8 | Y6: 76.8 | AK6: 11 | AP6: 39834 | AS6: 3 | AV6: 4 | BB6: 220000 | BC6: 16 | BE6: 97 | BF6: 2 | BG6: 2
A7: =1/0 -> #DIV/0! | B7: -3.5 | C7: -1 | D7: FALSE | E7: 7 | F7: Чаи | G7: 64 | H7: 46022 | I7: -10000 | J7: 100 | U7: Apple | V7: 8 | W7: 9 | X7: 6 | Y7: 45 | AK7: TRUE | AL7: 23 | AP7: 38719 | AS7: 1 | AU7: 39508 | AV7: 3 | BE7: 95 | BG7: 1
A8: =NA() -> #N/A | B8: 10.25 | C8: 9 | D8: 3.5 | E8: 8 | I8: 3000 | J8: 200 | L8: 1 | M8: 2 | N8: 3 | O8: 5 | P8: 8 | Q8: 13 | AP8: 38733 | AS8: b | AU8: 39448 | BG8: 2
A9: Привет Мир | I9: 4200 | J9: 300 | L9: one | M9: two | N9: three | O9: five | P9: eight | Q9: thirteen | AK9: 58 | AL9: 35 | AU9: 39751 | BG9: 3
A10: 1.5 | J10: 400 | L10: 10 | M10: 20 | N10: 30 | O10: 50 | P10: 80 | Q10: 130 | AK10: 11 | AL10: =1/0 -> #DIV/0! | AU10: 39859 | BG10: 5
A11: 1,5 | I11: 6800 | J11: 500 | AK11: 10 | AL11: 23 | AU11: 39904 | BG11: 6
A12: 0 | BG12: 1
A13: ="" | I13: -10000
A14: =CHAR(9)&"abc"&CHAR(10) -> abc | I14: 3000
A15: 45688.75 | I15: =NA() -> #N/A
I16: 6800
I17: 1200

Sheet C
A1: {=MOD(NI!A10,1)} -> 1 | B1: =IF(ISERROR(A1),ERROR.TYPE(A1),IF(ISNUMBER(A1),0,IF(ISLOGICAL(A1),IF(A1,-1,-2),IF(ISTEXT(A1),-3,-4)))) -> 0 | C1: =IF(ISNUMBER(A1),A1,0) -> 1 | D1: =IF(ISTEXT(A1),A1,"") | E1: mod#10
A2: {=MOD(NI!A11,1)} -> 1 | B2: =IF(ISERROR(A2),ERROR.TYPE(A2),IF(ISNUMBER(A2),0,IF(ISLOGICAL(A2),IF(A2,-1,-2),IF(ISTEXT(A2),-3,-4)))) -> 0 | C2: =IF(ISNUMBER(A2),A2,0) -> 1 | D2: =IF(ISTEXT(A2),A2,"") | E2: mod#11
A3: {=MOD(NI!A12,1)} -> 1 | B3: =IF(ISERROR(A3),ERROR.TYPE(A3),IF(ISNUMBER(A3),0,IF(ISLOGICAL(A3),IF(A3,-1,-2),IF(ISTEXT(A3),-3,-4)))) -> 0 | C3: =IF(ISNUMBER(A3),A3,0) -> 1 | D3: =IF(ISTEXT(A3),A3,"") | E3: mod#12
A4: {=MOD(NI!A13,1)} -> 1 | B4: =IF(ISERROR(A4),ERROR.TYPE(A4),IF(ISNUMBER(A4),0,IF(ISLOGICAL(A4),IF(A4,-1,-2),IF(ISTEXT(A4),-3,-4)))) -> 0 | C4: =IF(ISNUMBER(A4),A4,0) -> 1 | D4: =IF(ISTEXT(A4),A4,"") | E4: mod#13
A5: {=MOD(NI!A14,1)} -> 1 | B5: =IF(ISERROR(A5),ERROR.TYPE(A5),IF(ISNUMBER(A5),0,IF(ISLOGICAL(A5),IF(A5,-1,-2),IF(ISTEXT(A5),-3,-4)))) -> 0 | C5: =IF(ISNUMBER(A5),A5,0) -> 1 | D5: =IF(ISTEXT(A5),A5,"") | E5: mod#14
A6: {=MOD(NI!A15,1)} -> 1 | B6: =IF(ISERROR(A6),ERROR.TYPE(A6),IF(ISNUMBER(A6),0,IF(ISLOGICAL(A6),IF(A6,-1,-2),IF(ISTEXT(A6),-3,-4)))) -> 0 | C6: =IF(ISNUMBER(A6),A6,0) -> 1 | D6: =IF(ISTEXT(A6),A6,"") | E6: mod#15
A7: {=MOD(NI!A16,1)} -> 0.99999999 | B7: =IF(ISERROR(A7),ERROR.TYPE(A7),IF(ISNUMBER(A7),0,IF(ISLOGICAL(A7),IF(A7,-1,-2),IF(ISTEXT(A7),-3,-4)))) -> 0 | C7: =IF(ISNUMBER(A7),A7,0) -> 0.99999999 | D7: =IF(ISTEXT(A7),A7,"") | E7: mod#16
A8: {=MOD(NI!A17,1)} -> 0.99999905 | B8: =IF(ISERROR(A8),ERROR.TYPE(A8),IF(ISNUMBER(A8),0,IF(ISLOGICAL(A8),IF(A8,-1,-2),IF(ISTEXT(A8),-3,-4)))) -> 0 | C8: =IF(ISNUMBER(A8),A8,0) -> 0.99999905 | D8: =IF(ISTEXT(A8),A8,"") | E8: mod#17
A9: {=MOD(NI!A18,1)} -> 1 | B9: =IF(ISERROR(A9),ERROR.TYPE(A9),IF(ISNUMBER(A9),0,IF(ISLOGICAL(A9),IF(A9,-1,-2),IF(ISTEXT(A9),-3,-4)))) -> 0 | C9: =IF(ISNUMBER(A9),A9,0) -> 1 | D9: =IF(ISTEXT(A9),A9,"") | E9: mod#18
A10: {=MOD(NI!A19,1)} -> 1 | B10: =IF(ISERROR(A10),ERROR.TYPE(A10),IF(ISNUMBER(A10),0,IF(ISLOGICAL(A10),IF(A10,-1,-2),IF(ISTEXT(A10),-3,-4)))) -> 0 | C10: =IF(ISNUMBER(A10),A10,0) -> 1 | D10: =IF(ISTEXT(A10),A10,"") | E10: mod#19
A11: {=MOD(NI!A20,1)} -> 1 | B11: =IF(ISERROR(A11),ERROR.TYPE(A11),IF(ISNUMBER(A11),0,IF(ISLOGICAL(A11),IF(A11,-1,-2),IF(ISTEXT(A11),-3,-4)))) -> 0 | C11: =IF(ISNUMBER(A11),A11,0) -> 1 | D11: =IF(ISTEXT(A11),A11,"") | E11: mod#20
A12: {=MOD(NI!A21,1)} -> 1 | B12: =IF(ISERROR(A12),ERROR.TYPE(A12),IF(ISNUMBER(A12),0,IF(ISLOGICAL(A12),IF(A12,-1,-2),IF(ISTEXT(A12),-3,-4)))) -> 0 | C12: =IF(ISNUMBER(A12),A12,0) -> 1 | D12: =IF(ISTEXT(A12),A12,"") | E12: mod#21
... A110: {=MOD(NI!A119,1)} -> 0.95642853 | B110: =IF(ISERROR(A110),ERROR.TYPE(A110),IF(ISNUMBER(A110),0,IF(ISLOGICAL(A110),IF(A110,-1,-2),IF(ISTEXT(A110),-3,-4)))) -> 0 | C110: =IF(ISNUMBER(A110),A110,0) -> 0.95642853 | D110: =IF(ISTEXT(A110),A110,"") | E110: mod#119
A111: {=NI!A1=1} -> TRUE | B111: =IF(ISERROR(A111),ERROR.TYPE(A111),IF(ISNUMBER(A111),0,IF(ISLOGICAL(A111),IF(A111,-1,-2),IF(ISTEXT(A111),-3,-4)))) -> -1 | C111: =IF(ISNUMBER(A111),A111,0) -> 0 | D111: =IF(ISTEXT(A111),A111,"") | E111: eq#1
A112: {=NI!A2=1} -> TRUE | B112: =IF(ISERROR(A112),ERROR.TYPE(A112),IF(ISNUMBER(A112),0,IF(ISLOGICAL(A112),IF(A112,-1,-2),IF(ISTEXT(A112),-3,-4)))) -> -1 | C112: =IF(ISNUMBER(A112),A112,0) -> 0 | D112: =IF(ISTEXT(A112),A112,"") | E112: eq#2
A113: {=NI!A3=1} -> TRUE | B113: =IF(ISERROR(A113),ERROR.TYPE(A113),IF(ISNUMBER(A113),0,IF(ISLOGICAL(A113),IF(A113,-1,-2),IF(ISTEXT(A113),-3,-4)))) -> -1 | C113: =IF(ISNUMBER(A113),A113,0) -> 0 | D113: =IF(ISTEXT(A113),A113,"") | E113: eq#3
A114: {=NI!A4=1} -> FALSE | B114: =IF(ISERROR(A114),ERROR.TYPE(A114),IF(ISNUMBER(A114),0,IF(ISLOGICAL(A114),IF(A114,-1,-2),IF(ISTEXT(A114),-3,-4)))) -> -2 | C114: =IF(ISNUMBER(A114),A114,0) -> 0 | D114: =IF(ISTEXT(A114),A114,"") | E114: eq#4
A115: {=NI!A5=1} -> FALSE | B115: =IF(ISERROR(A115),ERROR.TYPE(A115),IF(ISNUMBER(A115),0,IF(ISLOGICAL(A115),IF(A115,-1,-2),IF(ISTEXT(A115),-3,-4)))) -> -2 | C115: =IF(ISNUMBER(A115),A115,0) -> 0 | D115: =IF(ISTEXT(A115),A115,"") | E115: eq#5
A116: {=NI!A6=1} -> FALSE | B116: =IF(ISERROR(A116),ERROR.TYPE(A116),IF(ISNUMBER(A116),0,IF(ISLOGICAL(A116),IF(A116,-1,-2),IF(ISTEXT(A116),-3,-4)))) -> -2 | C116: =IF(ISNUMBER(A116),A116,0) -> 0 | D116: =IF(ISTEXT(A116),A116,"") | E116: eq#6
A117: {=NI!A7=1} -> FALSE | B117: =IF(ISERROR(A117),ERROR.TYPE(A117),IF(ISNUMBER(A117),0,IF(ISLOGICAL(A117),IF(A117,-1,-2),IF(ISTEXT(A117),-3,-4)))) -> -2 | C117: =IF(ISNUMBER(A117),A117,0) -> 0 | D117: =IF(ISTEXT(A117),A117,"") | E117: eq#7
A118: {=NI!A8=1} -> FALSE | B118: =IF(ISERROR(A118),ERROR.TYPE(A118),IF(ISNUMBER(A118),0,IF(ISLOGICAL(A118),IF(A118,-1,-2),IF(ISTEXT(A118),-3,-4)))) -> -2 | C118: =IF(ISNUMBER(A118),A118,0) -> 0 | D118: =IF(ISTEXT(A118),A118,"") | E118: eq#8
A119: {=NI!A9=1} -> FALSE | B119: =IF(ISERROR(A119),ERROR.TYPE(A119),IF(ISNUMBER(A119),0,IF(ISLOGICAL(A119),IF(A119,-1,-2),IF(ISTEXT(A119),-3,-4)))) -> -2 | C119: =IF(ISNUMBER(A119),A119,0) -> 0 | D119: =IF(ISTEXT(A119),A119,"") | E119: eq#9
A120: {=NI!A10=1} -> FALSE | B120: =IF(ISERROR(A120),ERROR.TYPE(A120),IF(ISNUMBER(A120),0,IF(ISLOGICAL(A120),IF(A120,-1,-2),IF(ISTEXT(A120),-3,-4)))) -> -2 | C120: =IF(ISNUMBER(A120),A120,0) -> 0 | D120: =IF(ISTEXT(A120),A120,"") | E120: eq#10
A121: {=NI!A11=1} -> FALSE | B121: =IF(ISERROR(A121),ERROR.TYPE(A121),IF(ISNUMBER(A121),0,IF(ISLOGICAL(A121),IF(A121,-1,-2),IF(ISTEXT(A121),-3,-4)))) -> -2 | C121: =IF(ISNUMBER(A121),A121,0) -> 0 | D121: =IF(ISTEXT(A121),A121,"") | E121: eq#11
A122: {=NI!A12=1} -> FALSE | B122: =IF(ISERROR(A122),ERROR.TYPE(A122),IF(ISNUMBER(A122),0,IF(ISLOGICAL(A122),IF(A122,-1,-2),IF(ISTEXT(A122),-3,-4)))) -> -2 | C122: =IF(ISNUMBER(A122),A122,0) -> 0 | D122: =IF(ISTEXT(A122),A122,"") | E122: eq#12
... A127: {=NI!A17=1} -> FALSE | B127: =IF(ISERROR(A127),ERROR.TYPE(A127),IF(ISNUMBER(A127),0,IF(ISLOGICAL(A127),IF(A127,-1,-2),IF(ISTEXT(A127),-3,-4)))) -> -2 | C127: =IF(ISNUMBER(A127),A127,0) -> 0 | D127: =IF(ISTEXT(A127),A127,"") | E127: eq#17
A128: {=NI!A18=2} -> TRUE | B128: =IF(ISERROR(A128),ERROR.TYPE(A128),IF(ISNUMBER(A128),0,IF(ISLOGICAL(A128),IF(A128,-1,-2),IF(ISTEXT(A128),-3,-4)))) -> -1 | C128: =IF(ISNUMBER(A128),A128,0) -> 0 | D128: =IF(ISTEXT(A128),A128,"") | E128: eq#18
A129: {=NI!A19=2} -> TRUE | B129: =IF(ISERROR(A129),ERROR.TYPE(A129),IF(ISNUMBER(A129),0,IF(ISLOGICAL(A129),IF(A129,-1,-2),IF(ISTEXT(A129),-3,-4)))) -> -1 | C129: =IF(ISNUMBER(A129),A129,0) -> 0 | D129: =IF(ISTEXT(A129),A129,"") | E129: eq#19
A130: {=NI!A20=2} -> TRUE | B130: =IF(ISERROR(A130),ERROR.TYPE(A130),IF(ISNUMBER(A130),0,IF(ISLOGICAL(A130),IF(A130,-1,-2),IF(ISTEXT(A130),-3,-4)))) -> -1 | C130: =IF(ISNUMBER(A130),A130,0) -> 0 | D130: =IF(ISTEXT(A130),A130,"") | E130: eq#20
A131: {=NI!A21=2} -> TRUE | B131: =IF(ISERROR(A131),ERROR.TYPE(A131),IF(ISNUMBER(A131),0,IF(ISLOGICAL(A131),IF(A131,-1,-2),IF(ISTEXT(A131),-3,-4)))) -> -1 | C131: =IF(ISNUMBER(A131),A131,0) -> 0 | D131: =IF(ISTEXT(A131),A131,"") | E131: eq#21
A132: {=NI!A22=2} -> TRUE | B132: =IF(ISERROR(A132),ERROR.TYPE(A132),IF(ISNUMBER(A132),0,IF(ISLOGICAL(A132),IF(A132,-1,-2),IF(ISTEXT(A132),-3,-4)))) -> -1 | C132: =IF(ISNUMBER(A132),A132,0) -> 0 | D132: =IF(ISTEXT(A132),A132,"") | E132: eq#22
A133: {=NI!A23=2} -> FALSE | B133: =IF(ISERROR(A133),ERROR.TYPE(A133),IF(ISNUMBER(A133),0,IF(ISLOGICAL(A133),IF(A133,-1,-2),IF(ISTEXT(A133),-3,-4)))) -> -2 | C133: =IF(ISNUMBER(A133),A133,0) -> 0 | D133: =IF(ISTEXT(A133),A133,"") | E133: eq#23
A134: {=NI!A24=2} -> FALSE | B134: =IF(ISERROR(A134),ERROR.TYPE(A134),IF(ISNUMBER(A134),0,IF(ISLOGICAL(A134),IF(A134,-1,-2),IF(ISTEXT(A134),-3,-4)))) -> -2 | C134: =IF(ISNUMBER(A134),A134,0) -> 0 | D134: =IF(ISTEXT(A134),A134,"") | E134: eq#24
A135: {=NI!A25=2} -> FALSE | B135: =IF(ISERROR(A135),ERROR.TYPE(A135),IF(ISNUMBER(A135),0,IF(ISLOGICAL(A135),IF(A135,-1,-2),IF(ISTEXT(A135),-3,-4)))) -> -2 | C135: =IF(ISNUMBER(A135),A135,0) -> 0 | D135: =IF(ISTEXT(A135),A135,"") | E135: eq#25
A136: {=NI!A26=2} -> FALSE | B136: =IF(ISERROR(A136),ERROR.TYPE(A136),IF(ISNUMBER(A136),0,IF(ISLOGICAL(A136),IF(A136,-1,-2),IF(ISTEXT(A136),-3,-4)))) -> -2 | C136: =IF(ISNUMBER(A136),A136,0) -> 0 | D136: =IF(ISTEXT(A136),A136,"") | E136: eq#26
A137: {=NI!A27=2} -> FALSE | B137: =IF(ISERROR(A137),ERROR.TYPE(A137),IF(ISNUMBER(A137),0,IF(ISLOGICAL(A137),IF(A137,-1,-2),IF(ISTEXT(A137),-3,-4)))) -> -2 | C137: =IF(ISNUMBER(A137),A137,0) -> 0 | D137: =IF(ISTEXT(A137),A137,"") | E137: eq#27
A138: {=NI!A28=2} -> FALSE | B138: =IF(ISERROR(A138),ERROR.TYPE(A138),IF(ISNUMBER(A138),0,IF(ISLOGICAL(A138),IF(A138,-1,-2),IF(ISTEXT(A138),-3,-4)))) -> -2 | C138: =IF(ISNUMBER(A138),A138,0) -> 0 | D138: =IF(ISTEXT(A138),A138,"") | E138: eq#28
A139: {=NI!A29=2} -> FALSE | B139: =IF(ISERROR(A139),ERROR.TYPE(A139),IF(ISNUMBER(A139),0,IF(ISLOGICAL(A139),IF(A139,-1,-2),IF(ISTEXT(A139),-3,-4)))) -> -2 | C139: =IF(ISNUMBER(A139),A139,0) -> 0 | D139: =IF(ISTEXT(A139),A139,"") | E139: eq#29
... A144: {=NI!A34=2} -> FALSE | B144: =IF(ISERROR(A144),ERROR.TYPE(A144),IF(ISNUMBER(A144),0,IF(ISLOGICAL(A144),IF(A144,-1,-2),IF(ISTEXT(A144),-3,-4)))) -> -2 | C144: =IF(ISNUMBER(A144),A144,0) -> 0 | D144: =IF(ISTEXT(A144),A144,"") | E144: eq#34
A145: {=NI!A35=3} -> TRUE | B145: =IF(ISERROR(A145),ERROR.TYPE(A145),IF(ISNUMBER(A145),0,IF(ISLOGICAL(A145),IF(A145,-1,-2),IF(ISTEXT(A145),-3,-4)))) -> -1 | C145: =IF(ISNUMBER(A145),A145,0) -> 0 | D145: =IF(ISTEXT(A145),A145,"") | E145: eq#35
...
