Workbook

Sheet NI
A1: =1-1*2^-53 -> 1
A2: =1-1*2^-52 -> 1
A3: =1-1*2^-51 -> 1
A4: =1-1*2^-50 -> 1
A5: =1-1*2^-49 -> 1
A6: =1-1*2^-48 -> 1
A7: =1-1*2^-47 -> 1
A8: =1-1*2^-46 -> 1
A9: =1-1*2^-45 -> 1
A10: =1-1*2^-44 -> 1
A11: =1-1*2^-43 -> 1
A12: =1-1*2^-42 -> 1
A13: =1-1*2^-40 -> 1
A14: =1-1*2^-37 -> 1
A15: =1-1*2^-33 -> 1
A16: =1-1*2^-27 -> 0.99999999
A17: =1-1*2^-20 -> 0.99999905
A18: =2-2*2^-53 -> 2
A19: =2-2*2^-52 -> 2
A20: =2-2*2^-51 -> 2
A21: =2-2*2^-50 -> 2
A22: =2-2*2^-49 -> 2
A23: =2-2*2^-48 -> 2
A24: =2-2*2^-47 -> 2
A25: =2-2*2^-46 -> 2
A26: =2-2*2^-45 -> 2
A27: =2-2*2^-44 -> 2
A28: =2-2*2^-43 -> 2
A29: =2-2*2^-42 -> 2
A30: =2-2*2^-40 -> 2
A31: =2-2*2^-37 -> 2
A32: =2-2*2^-33 -> 2
A33: =2-2*2^-27 -> 2
A34: =2-2*2^-20 -> 1.9999981
A35: =3-3*2^-53 -> 3
A36: =3-3*2^-52 -> 3
A37: =3-3*2^-51 -> 3
A38: =3-3*2^-50 -> 3
A39: =3-3*2^-49 -> 3
A40: =3-3*2^-48 -> 3
...

Sheet D
B1: 4 | C1: 2 | D1: 1 | E1: 1 | F1: Аренда | G1: 1 | H1: 45657 | I1: -10000 | J1: -10000 | L1: 1 | M1: one | N1: 10 | P1: 1 | Q1: 2 | R1: 5 | S1: 6 | U1: Tree | V1: Height | W1: Age | X1: Yield | Y1: Profit | AA1: Tree | AB1: Height | AC1: Tree | AD1: Tree | AE1: Tree | AF1: Tree | AG1: Tree | AH1: 0 | AI1: 0.2 | AK1: 58 | AL1: 35 | AM1: 45.35 | AN1: 47.65 | AP1: 41235 | AQ1: 0.09 | AR1: 1 | AS1: 1 | AT1: 0 | AU1: 39448 | AV1: 4 | AW1: TRUE | AX1: TRUE | AY1: 3 | AZ1: 1 | BA1: 6 | BB1: 33100 | BC1: 11 | BD1: 17 | BE1: 89 | BF1: 1 | BG1: 1 | BH1: a
A2: 2 | B2: 8 | C2: 7 | D2: 2 | E2: 2 | F2: аренда | G2: 2 | H2: 45658 | I2: 3000 | J2: 2750 | L2: 2 | M2: two | N2: 20 | P2: 3 | Q2: 4 | R2: 7 | S2: 8 | U2: Apple | V2: 18 | W2: 20 | X2: 14 | Y2: 105 | AA2: Apple | AB2: >10 | AC2: Pear | AD2: a* | AE2: Cherry | AF2: Plum | AH2: 1 | AI2: 0.3 | AK2: 11 | AL2: 25 | AM2: 17.56 | AN2: 18.44 | AP2: 41247 | AQ2: 0.11 | AR2: -0.5 | AS2: 2 | AT2: 10 | AU2: 39508 | AV2: 5 | AW2: FALSE | AX2: TRUE | AY2: 5 | AZ2: 2 | BA2: 7 | BB2: 47300 | BC2: 12 | BD2: 18 | BE2: 88 | BF2: 2 | BG2: 2
A3: abc | B3: 15 | C3: 11 | D3: abc | E3: =1/0 -> #DIV/0! | F3: Арендй | G3: 4 | H3: 45659 | I3: 4200 | J3: 4250 | L3: 3 | M3: three | N3: 30 | U3: Pear | V3: 12 | W3: 12 | X3: 10 | Y3: 96 | AH3: 2 | AI3: 0.1 | AK3: 10 | AL3: 23 | AM3: 16.09 | AN3: 16.91 | AP3: 41295 | AQ3: 0.1 | AR3: 0.041666667 | AS3: 2 | AT3: 20 | AU3: 39751 | AV3: 8 | AW3: abc | AX3: 1 | AY3: 7 | AZ3: 3 | BB3: 69000 | BC3: 13 | BE3: 92 | BF3: 2 | BG3: 3 | BH3: Б
A4: TRUE | B4: 16 | C4: 19 | D4: TRUE | E4: 4 | F4: Арeнда* | G4: 8 | H4: 45689 | I4: 6800 | J4: 3250 | L4: 5 | M4: five | N4: 50 | P4: 1 | Q4: 2 | R4: 3 | U4: Cherry | V4: 13 | W4: 14 | X4: 9 | Y4: 105 | AH4: 3 | AI4: 0.4 | AP4: 39778 | AR4: -0.0013888889 | AS4: a | AU4: 39859 | AV4: 7 | AY4: 10 | AZ4: 4 | BB4: 102000 | BC4: 14 | BE4: 101 | BF4: 3 | BG4: 4
A5: FALSE | B5: 23 | C5: 21 | E5: 5 | F5: x*y | G5: 16 | H5: 45717 | I5: 1200 | J5: 2750 | L5: 8 | M5: eight | N5: 80 | P5: 4 | Q5: 5 | R5: 6 | U5: Apple | V5: 14 | W5: 15 | X5: 10 | Y5: 75 | AK5: 58 | AL5: 35 | AP5: 39786 | AS5: A | AU5: 39904 | AV5: 11 | AY5: 11 | AZ5: 5 | BB5: 150000 | BC5: 15 | BE5: 94 | BF5: 5 | BG5: 3
A6: 45688 | B6: 42 | C6: 40 | D6: 5 | E6: 6 | F6: Чай | G6: 32 | H6: 45473 | L6: 13 | M6: thirteen | N6: 130 | U6: Pear | V6: 9 | W6: 8 | X6: 8 | Y6: 76.8 | AK6: 11 | AP6: 39834 | AS6: 3 | AV6: 4 | BB6: 220000 | BC6: 16 | BE6: 97 | BF6: 2 | BG6: 2
A7: =1/0 -> #DIV/0! | B7: -3.5 | C7: -1 | D7: FALSE | E7: 7 | F7: Чаи | G7: 64 | H7: 46022 | I7: -10000 | J7: 100 | U7: Apple | V7: 8 | W7: 9 | X7: 6 | Y7: 45 | AK7: TRUE | AL7: 23 | AP7: 38719 | AS7: 1 | AU7: 39508 | AV7: 3 | BE7: 95 | BG7: 1
A8: =NA() -> #N/A | B8: 10.25 | C8: 9 | D8: 3.5 | E8: 8 | I8: 3000 | J8: 200 | L8: 1 | M8: 2 | N8: 3 | O8: 5 | P8: 8 | Q8: 13 | AP8: 38733 | AS8: b | AU8: 39448 | BG8: 2
A9: Привет Мир | I9: 4200 | J9: 300 | L9: one | M9: two | N9: three | O9: five | P9: eight | Q9: thirteen | AK9: 58 | AL9: 35 | AU9: 39751 | BG9: 3
A10: 1.5 | J10: 400 | L10: 10 | M10: 20 | N10: 30 | O10: 50 | P10: 80 | Q10: 130 | AK10: 11 | AL10: =1/0 -> #DIV/0! | AU10: 39859 | BG10: 5
A11: 1,5 | I11: 6800 | J11: 500 | AK11: 10 | AL11: 23 | AU11: 39904 | BG11: 6
A12: 0 | BG12: 1
A13: ="" | I13: -10000
A14: =CHAR(9)&"abc"&CHAR(10) -> abc | I14: 3000
A15: 45688.75 | I15: =NA() -> #N/A
I16: 6800
I17: 1200

Sheet C
A1: {=ISEVEN(NI!A395)} -> TRUE | B1: =IF(ISERROR(A1),ERROR.TYPE(A1),IF(ISNUMBER(A1),0,IF(ISLOGICAL(A1),IF(A1,-1,-2),IF(ISTEXT(A1),-3,-4)))) -> -1 | C1: =IF(ISNUMBER(A1),A1,0) -> 0 | D1: =IF(ISTEXT(A1),A1,"") | E1: parity:ISEVEN#21
A2: {=ISEVEN(NI!A396)} -> TRUE | B2: =IF(ISERROR(A2),ERROR.TYPE(A2),IF(ISNUMBER(A2),0,IF(ISLOGICAL(A2),IF(A2,-1,-2),IF(ISTEXT(A2),-3,-4)))) -> -1 | C2: =IF(ISNUMBER(A2),A2,0) -> 0 | D2: =IF(ISTEXT(A2),A2,"") | E2: parity:ISEVEN#22
A3: {=ISEVEN(NI!A397)} -> TRUE | B3: =IF(ISERROR(A3),ERROR.TYPE(A3),IF(ISNUMBER(A3),0,IF(ISLOGICAL(A3),IF(A3,-1,-2),IF(ISTEXT(A3),-3,-4)))) -> -1 | C3: =IF(ISNUMBER(A3),A3,0) -> 0 | D3: =IF(ISTEXT(A3),A3,"") | E3: parity:ISEVEN#23
A4: {=ISEVEN(NI!A398)} -> FALSE | B4: =IF(ISERROR(A4),ERROR.TYPE(A4),IF(ISNUMBER(A4),0,IF(ISLOGICAL(A4),IF(A4,-1,-2),IF(ISTEXT(A4),-3,-4)))) -> -2 | C4: =IF(ISNUMBER(A4),A4,0) -> 0 | D4: =IF(ISTEXT(A4),A4,"") | E4: parity:ISEVEN#24
A5: {=ISEVEN(NI!A399)} -> FALSE | B5: =IF(ISERROR(A5),ERROR.TYPE(A5),IF(ISNUMBER(A5),0,IF(ISLOGICAL(A5),IF(A5,-1,-2),IF(ISTEXT(A5),-3,-4)))) -> -2 | C5: =IF(ISNUMBER(A5),A5,0) -> 0 | D5: =IF(ISTEXT(A5),A5,"") | E5: parity:ISEVEN#25
A6: {=ISEVEN(NI!A400)} -> FALSE | B6: =IF(ISERROR(A6),ERROR.TYPE(A6),IF(ISNUMBER(A6),0,IF(ISLOGICAL(A6),IF(A6,-1,-2),IF(ISTEXT(A6),-3,-4)))) -> -2 | C6: =IF(ISNUMBER(A6),A6,0) -> 0 | D6: =IF(ISTEXT(A6),A6,"") | E6: parity:ISEVEN#26
A7: {=ISEVEN(NI!A401)} -> FALSE | B7: =IF(ISERROR(A7),ERROR.TYPE(A7),IF(ISNUMBER(A7),0,IF(ISLOGICAL(A7),IF(A7,-1,-2),IF(ISTEXT(A7),-3,-4)))) -> -2 | C7: =IF(ISNUMBER(A7),A7,0) -> 0 | D7: =IF(ISTEXT(A7),A7,"") | E7: parity:ISEVEN#27
A8: {=ISEVEN(NI!A402)} -> FALSE | B8: =IF(ISERROR(A8),ERROR.TYPE(A8),IF(ISNUMBER(A8),0,IF(ISLOGICAL(A8),IF(A8,-1,-2),IF(ISTEXT(A8),-3,-4)))) -> -2 | C8: =IF(ISNUMBER(A8),A8,0) -> 0 | D8: =IF(ISTEXT(A8),A8,"") | E8: parity:ISEVEN#28
A9: {=ISEVEN(NI!A403)} -> FALSE | B9: =IF(ISERROR(A9),ERROR.TYPE(A9),IF(ISNUMBER(A9),0,IF(ISLOGICAL(A9),IF(A9,-1,-2),IF(ISTEXT(A9),-3,-4)))) -> -2 | C9: =IF(ISNUMBER(A9),A9,0) -> 0 | D9: =IF(ISTEXT(A9),A9,"") | E9: parity:ISEVEN#29
A10: {=ISEVEN(NI!A404)} -> FALSE | B10: =IF(ISERROR(A10),ERROR.TYPE(A10),IF(ISNUMBER(A10),0,IF(ISLOGICAL(A10),IF(A10,-1,-2),IF(ISTEXT(A10),-3,-4)))) -> -2 | C10: =IF(ISNUMBER(A10),A10,0) -> 0 | D10: =IF(ISTEXT(A10),A10,"") | E10: parity:ISEVEN#30
A11: {=ISEVEN(NI!A405)} -> FALSE | B11: =IF(ISERROR(A11),ERROR.TYPE(A11),IF(ISNUMBER(A11),0,IF(ISLOGICAL(A11),IF(A11,-1,-2),IF(ISTEXT(A11),-3,-4)))) -> -2 | C11: =IF(ISNUMBER(A11),A11,0) -> 0 | D11: =IF(ISTEXT(A11),A11,"") | E11: parity:ISEVEN#31
A12: {=ISEVEN(NI!A406)} -> FALSE | B12: =IF(ISERROR(A12),ERROR.TYPE(A12),IF(ISNUMBER(A12),0,IF(ISLOGICAL(A12),IF(A12,-1,-2),IF(ISTEXT(A12),-3,-4)))) -> -2 | C12: =IF(ISNUMBER(A12),A12,0) -> 0 | D12: =IF(ISTEXT(A12),A12,"") | E12: parity:ISEVEN#32
... A17: {=ISEVEN(NI!A411)} -> FALSE | B17: =IF(ISERROR(A17),ERROR.TYPE(A17),IF(ISNUMBER(A17),0,IF(ISLOGICAL(A17),IF(A17,-1,-2),IF(ISTEXT(A17),-3,-4)))) -> -2 | C17: =IF(ISNUMBER(A17),A17,0) -> 0 | D17: =IF(ISTEXT(A17),A17,"") | E17: parity:ISEVEN#37
A18: {=ISODD(NI!A391)} -> FALSE | B18: =IF(ISERROR(A18),ERROR.TYPE(A18),IF(ISNUMBER(A18),0,IF(ISLOGICAL(A18),IF(A18,-1,-2),IF(ISTEXT(A18),-3,-4)))) -> -2 | C18: =IF(ISNUMBER(A18),A18,0) -> 0 | D18: =IF(ISTEXT(A18),A18,"") | E18: parity:ISODD#17
A19: {=ISODD(NI!A392)} -> FALSE | B19: =IF(ISERROR(A19),ERROR.TYPE(A19),IF(ISNUMBER(A19),0,IF(ISLOGICAL(A19),IF(A19,-1,-2),IF(ISTEXT(A19),-3,-4)))) -> -2 | C19: =IF(ISNUMBER(A19),A19,0) -> 0 | D19: =IF(ISTEXT(A19),A19,"") | E19: parity:ISODD#18
A20: {=ISODD(NI!A393)} -> FALSE | B20: =IF(ISERROR(A20),ERROR.TYPE(A20),IF(ISNUMBER(A20),0,IF(ISLOGICAL(A20),IF(A20,-1,-2),IF(ISTEXT(A20),-3,-4)))) -> -2 | C20: =IF(ISNUMBER(A20),A20,0) -> 0 | D20: =IF(ISTEXT(A20),A20,"") | E20: parity:ISODD#19
A21: {=ISODD(NI!A394)} -> FALSE | B21: =IF(ISERROR(A21),ERROR.TYPE(A21),IF(ISNUMBER(A21),0,IF(ISLOGICAL(A21),IF(A21,-1,-2),IF(ISTEXT(A21),-3,-4)))) -> -2 | C21: =IF(ISNUMBER(A21),A21,0) -> 0 | D21: =IF(ISTEXT(A21),A21,"") | E21: parity:ISODD#20
A22: {=ISODD(NI!A395)} -> FALSE | B22: =IF(ISERROR(A22),ERROR.TYPE(A22),IF(ISNUMBER(A22),0,IF(ISLOGICAL(A22),IF(A22,-1,-2),IF(ISTEXT(A22),-3,-4)))) -> -2 | C22: =IF(ISNUMBER(A22),A22,0) -> 0 | D22: =IF(ISTEXT(A22),A22,"") | E22: parity:ISODD#21
A23: {=ISODD(NI!A396)} -> FALSE | B23: =IF(ISERROR(A23),ERROR.TYPE(A23),IF(ISNUMBER(A23),0,IF(ISLOGICAL(A23),IF(A23,-1,-2),IF(ISTEXT(A23),-3,-4)))) -> -2 | C23: =IF(ISNUMBER(A23),A23,0) -> 0 | D23: =IF(ISTEXT(A23),A23,"") | E23: parity:ISODD#22
A24: {=ISODD(NI!A397)} -> FALSE | B24: =IF(ISERROR(A24),ERROR.TYPE(A24),IF(ISNUMBER(A24),0,IF(ISLOGICAL(A24),IF(A24,-1,-2),IF(ISTEXT(A24),-3,-4)))) -> -2 | C24: =IF(ISNUMBER(A24),A24,0) -> 0 | D24: =IF(ISTEXT(A24),A24,"") | E24: parity:ISODD#23
A25: {=ISODD(NI!A398)} -> TRUE | B25: =IF(ISERROR(A25),ERROR.TYPE(A25),IF(ISNUMBER(A25),0,IF(ISLOGICAL(A25),IF(A25,-1,-2),IF(ISTEXT(A25),-3,-4)))) -> -1 | C25: =IF(ISNUMBER(A25),A25,0) -> 0 | D25: =IF(ISTEXT(A25),A25,"") | E25: parity:ISODD#24
A26: {=ISODD(NI!A399)} -> TRUE | B26: =IF(ISERROR(A26),ERROR.TYPE(A26),IF(ISNUMBER(A26),0,IF(ISLOGICAL(A26),IF(A26,-1,-2),IF(ISTEXT(A26),-3,-4)))) -> -1 | C26: =IF(ISNUMBER(A26),A26,0) -> 0 | D26: =IF(ISTEXT(A26),A26,"") | E26: parity:ISODD#25
A27: {=ISODD(NI!A400)} -> TRUE | B27: =IF(ISERROR(A27),ERROR.TYPE(A27),IF(ISNUMBER(A27),0,IF(ISLOGICAL(A27),IF(A27,-1,-2),IF(ISTEXT(A27),-3,-4)))) -> -1 | C27: =IF(ISNUMBER(A27),A27,0) -> 0 | D27: =IF(ISTEXT(A27),A27,"") | E27: parity:ISODD#26
A28: {=ISODD(NI!A401)} -> TRUE | B28: =IF(ISERROR(A28),ERROR.TYPE(A28),IF(ISNUMBER(A28),0,IF(ISLOGICAL(A28),IF(A28,-1,-2),IF(ISTEXT(A28),-3,-4)))) -> -1 | C28: =IF(ISNUMBER(A28),A28,0) -> 0 | D28: =IF(ISTEXT(A28),A28,"") | E28: parity:ISODD#27
A29: {=ISODD(NI!A402)} -> TRUE | B29: =IF(ISERROR(A29),ERROR.TYPE(A29),IF(ISNUMBER(A29),0,IF(ISLOGICAL(A29),IF(A29,-1,-2),IF(ISTEXT(A29),-3,-4)))) -> -1 | C29: =IF(ISNUMBER(A29),A29,0) -> 0 | D29: =IF(ISTEXT(A29),A29,"") | E29: parity:ISODD#28
... A38: {=ISODD(NI!A411)} -> TRUE | B38: =IF(ISERROR(A38),ERROR.TYPE(A38),IF(ISNUMBER(A38),0,IF(ISLOGICAL(A38),IF(A38,-1,-2),IF(ISTEXT(A38),-3,-4)))) -> -1 | C38: =IF(ISNUMBER(A38),A38,0) -> 0 | D38: =IF(ISTEXT(A38),A38,"") | E38: parity:ISODD#37
A39: {=DATE(NI!A412,1,1)} -> 45658 | B39: =IF(ISERROR(A39),ERROR.TYPE(A39),IF(ISNUMBER(A39),0,IF(ISLOGICAL(A39),IF(A39,-1,-2),IF(ISTEXT(A39),-3,-4)))) -> 0 | C39: =IF(ISNUMBER(A39),A39,0) -> 45658 | D39: =IF(ISTEXT(A39),A39,"") | E39: sample:DATE#5
A40: {=DATE(NI!A413,1,1)} -> 45292 | B40: =IF(ISERROR(A40),ERROR.TYPE(A40),IF(ISNUMBER(A40),0,IF(ISLOGICAL(A40),IF(A40,-1,-2),IF(ISTEXT(A40),-3,-4)))) -> 0 | C40: =IF(ISNUMBER(A40),A40,0) -> 45292 | D40: =IF(ISTEXT(A40),A40,"") | E40: sample:DATE#6
A41: {=INDEX(D!B1:B8,1,1,NI!A305)} -> 4 | B41: =IF(ISERROR(A41),ERROR.TYPE(A41),IF(ISNUMBER(A41),0,IF(ISLOGICAL(A41),IF(A41,-1,-2),IF(ISTEXT(A41),-3,-4)))) -> 0 | C41: =IF(ISNUMBER(A41),A41,0) -> 4 | D41: =IF(ISTEXT(A41),A41,"") | E41: sample:INDEX#9
A42: {=INDEX(D!B1:B8,1,1,NI!A306)} -> 4 | B42: =IF(ISERROR(A42),ERROR.TYPE(A42),IF(ISNUMBER(A42),0,IF(ISLOGICAL(A42),IF(A42,-1,-2),IF(ISTEXT(A42),-3,-4)))) -> 0 | C42: =IF(ISNUMBER(A42),A42,0) -> 4 | D42: =IF(ISTEXT(A42),A42,"") | E42: sample:INDEX#10
A43: {=COLUMNS(_xlfn.TOROW(D!D4:D6,NI!A305))} -> 3 | B43: =IF(ISERROR(A43),ERROR.TYPE(A43),IF(ISNUMBER(A43),0,IF(ISLOGICAL(A43),IF(A43,-1,-2),IF(ISTEXT(A43),-3,-4)))) -> 0 | C43: =IF(ISNUMBER(A43),A43,0) -> 3 | D43: =IF(ISTEXT(A43),A43,"") | E43: sample:TOROW#1
A44: {=COLUMNS(_xlfn.TOROW(D!D4:D6,NI!A306))} -> 3 | B44: =IF(ISERROR(A44),ERROR.TYPE(A44),IF(ISNUMBER(A44),0,IF(ISLOGICAL(A44),IF(A44,-1,-2),IF(ISTEXT(A44),-3,-4)))) -> 0 | C44: =IF(ISNUMBER(A44),A44,0) -> 3 | D44: =IF(ISTEXT(A44),A44,"") | E44: sample:TOROW#2
A45: {=_xlfn.PERCENTRANK.EXC(D!B1:B8,10,NI!A307)} -> 0.4 | B45: =IF(ISERROR(A45),ERROR.TYPE(A45),IF(ISNUMBER(A45),0,IF(ISLOGICAL(A45),IF(A45,-1,-2),IF(ISTEXT(A45),-3,-4)))) -> 0 | C45: =IF(ISNUMBER(A45),A45,0) -> 0.4 | D45: =IF(ISTEXT(A45),A45,"") | E45: sample:PERCENTRANK.EXC#1
A46: {=_xlfn.PERCENTRANK.EXC(D!B1:B8,10,NI!A308)} -> 0.4 | B46: =IF(ISERROR(A46),ERROR.TYPE(A46),IF(ISNUMBER(A46),0,IF(ISLOGICAL(A46),IF(A46,-1,-2),IF(ISTEXT(A46),-3,-4)))) -> 0 | C46: =IF(ISNUMBER(A46),A46,0) -> 0.4 | D46: =IF(ISTEXT(A46),A46,"") | E46: sample:PERCENTRANK.EXC#2
A47: {=_xlfn.PERCENTRANK.EXC(D!B1:B8,10,NI!A309)} -> 0.43 | B47: =IF(ISERROR(A47),ERROR.TYPE(A47),IF(ISNUMBER(A47),0,IF(ISLOGICAL(A47),IF(A47,-1,-2),IF(ISTEXT(A47),-3,-4)))) -> 0 | C47: =IF(ISNUMBER(A47),A47,0) -> 0.43 | D47: =IF(ISTEXT(A47),A47,"") | E47: sample:PERCENTRANK.EXC#3
A48: {=_xlfn.PERCENTRANK.EXC(D!B1:B8,10,NI!A310)} -> 0.43 | B48: =IF(ISERROR(A48),ERROR.TYPE(A48),IF(ISNUMBER(A48),0,IF(ISLOGICAL(A48),IF(A48,-1,-2),IF(ISTEXT(A48),-3,-4)))) -> 0 | C48: =IF(ISNUMBER(A48),A48,0) -> 0.43 | D48: =IF(ISTEXT(A48),A48,"") | E48: sample:PERCENTRANK.EXC#4
A49: {=PERCENTRANK(D!B1:B8,10,NI!A307)} -> 0.4 | B49: =IF(ISERROR(A49),ERROR.TYPE(A49),IF(ISNUMBER(A49),0,IF(ISLOGICAL(A49),IF(A49,-1,-2),IF(ISTEXT(A49),-3,-4)))) -> 0 | C49: =IF(ISNUMBER(A49),A49,0) -> 0.4 | D49: =IF(ISTEXT(A49),A49,"") | E49: sample:PERCENTRANK#1
A50: {=PERCENTRANK(D!B1:B8,10,NI!A308)} -> 0.4 | B50: =IF(ISERROR(A50),ERROR.TYPE(A50),IF(ISNUMBER(A50),0,IF(ISLOGICAL(A50),IF(A50,-1,-2),IF(ISTEXT(A50),-3,-4)))) -> 0 | C50: =IF(ISNUMBER(A50),A50,0) -> 0.4 | D50: =IF(ISTEXT(A50),A50,"") | E50: sample:PERCENTRANK#2
A51: {=PERCENTRANK(D!B1:B8,10,NI!A309)} -> 0.41 | B51: =IF(ISERROR(A51),ERROR.TYPE(A51),IF(ISNUMBER(A51),0,IF(ISLOGICAL(A51),IF(A51,-1,-2),IF(ISTEXT(A51),-3,-4)))) -> 0 | C51: =IF(ISNUMBER(A51),A51,0) -> 0.41 | D51: =IF(ISTEXT(A51),A51,"") | E51: sample:PERCENTRANK#3
A52: {=PERCENTRANK(D!B1:B8,10,NI!A310)} -> 0.41 | B52: =IF(ISERROR(A52),ERROR.TYPE(A52),IF(ISNUMBER(A52),0,IF(ISLOGICAL(A52),IF(A52,-1,-2),IF(ISTEXT(A52),-3,-4)))) -> 0 | C52: =IF(ISNUMBER(A52),A52,0) -> 0.41 | D52: =IF(ISTEXT(A52),A52,"") | E52: sample:PERCENTRANK#4
...
