Workbook

Sheet T
A1: 1 | B1: 1 | C1: 1 | D1: 1 | E1: 1 | F1: 1 | G1: 1 | H1: 2 | I1: 1 | K1: =SUBTOTAL(9,L1:L3) -> 8 | L1: 3 | M1: 3 | N1: 1 | O1: 2 | P1: 4
A2: 2 | B2: 2 | C2: 2 | D2: 2 | E2: 2 | F2: 2 | G2: 2 | H2: =1/0 -> #DIV/0! | I2: x | K2: =SUBTOTAL(1,L1:L3) -> 2.6666667 | L2: 1 | M2: 1 | N2: 3 | O2: 4 | P2: 8
A3: =SUBTOTAL(9,A1:A2) -> 3 | B3: =_xlfn.AGGREGATE(9,4,B1:B2) -> 3 | C3: =SUBTOTAL(9,C1:C2)*10 -> 30 | D3: =IF(TRUE,SUBTOTAL(9,D1:D2),0) -> 3 | E3: =A3 -> 3 | F3: =SUBTOTAL(109,F1:F2) -> 3 | G3: =_xlfn.AGGREGATE(9,0,G1:G2)+0 -> 3 | H3: 3 | I3: TRUE | L3: 4 | M3: 4 | N3: =SUBTOTAL(9,N1:O2) -> 10 | O3: 5 | P3: 15
H4: =NA() -> #N/A | M4: 1 | P4: 16
H5: 7 | I5: 2 | M5: 5 | P5: 23
H6: =SUBTOTAL(9,H2) -> #DIV/0! | I6: 3 | M6: 9 | P6: 42
I7: FALSE | M7: 2 | P7: =SUBTOTAL(9,P1:P2) -> 12
M8: 6 | P8: =_xlfn.AGGREGATE(4,4,P1:P6) -> 42
M9: 5
M10: 3
M11: =_xlfn.AGGREGATE(14,4,M1:M10,1) -> 9

Sheet D
B1: 4 | C1: 2 | D1: 1 | E1: 1 | F1: Аренда | G1: 1 | H1: 45657 | I1: -10000 | J1: -10000 | L1: 1 | M1: one | N1: 10 | P1: 1 | Q1: 2 | R1: 5 | S1: 6 | U1: Tree | V1: Height | W1: Age | X1: Yield | Y1: Profit | AA1: Tree | AB1: Height | AC1: Tree | AD1: Tree | AE1: Tree | AF1: Tree | AG1: Tree | AH1: 0 | AI1: 0.2 | AK1: 58 | AL1: 35 | AM1: 45.35 | AN1: 47.65 | AP1: 41235 | AQ1: 0.09 | AR1: 1 | AS1: 1 | AT1: 0 | AU1: 39448 | AV1: 4 | AW1: TRUE | AX1: TRUE | AY1: 3 | AZ1: 1 | BA1: 6 | BB1: 33100 | BC1: 11 | BD1: 17 | BE1: 89 | BF1: 1 | BG1: 1 | BH1: a
A2: 2 | B2: 8 | C2: 7 | D2: 2 | E2: 2 | F2: аренда | G2: 2 | H2: 45658 | I2: 3000 | J2: 2750 | L2: 2 | M2: two | N2: 20 | P2: 3 | Q2: 4 | R2: 7 | S2: 8 | U2: Apple | V2: 18 | W2: 20 | X2: 14 | Y2: 105 | AA2: Apple | AB2: >10 | AC2: Pear | AD2: a* | AE2: Cherry | AF2: Plum | AH2: 1 | AI2: 0.3 | AK2: 11 | AL2: 25 | AM2: 17.56 | AN2: 18.44 | AP2: 41247 | AQ2: 0.11 | AR2: -0.5 | AS2: 2 | AT2: 10 | AU2: 39508 | AV2: 5 | AW2: FALSE | AX2: TRUE | AY2: 5 | AZ2: 2 | BA2: 7 | BB2: 47300 | BC2: 12 | BD2: 18 | BE2: 88 | BF2: 2 | BG2: 2
A3: abc | B3: 15 | C3: 11 | D3: abc | E3: =1/0 -> #DIV/0! | F3: Арендй | G3: 4 | H3: 45659 | I3: 4200 | J3: 4250 | L3: 3 | M3: three | N3: 30 | U3: Pear | V3: 12 | W3: 12 | X3: 10 | Y3: 96 | AH3: 2 | AI3: 0.1 | AK3: 10 | AL3: 23 | AM3: 16.09 | AN3: 16.91 | AP3: 41295 | AQ3: 0.1 | AR3: 0.041666667 | AS3: 2 | AT3: 20 | AU3: 39751 | AV3: 8 | AW3: abc | AX3: 1 | AY3: 7 | AZ3: 3 | BB3: 69000 | BC3: 13 | BE3: 92 | BF3: 2 | BG3: 3 | BH3: Б
A4: TRUE | B4: 16 | C4: 19 | D4: TRUE | E4: 4 | F4: Арeнда* | G4: 8 | H4: 45689 | I4: 6800 | J4: 3250 | L4: 5 | M4: five | N4: 50 | P4: 1 | Q4: 2 | R4: 3 | U4: Cherry | V4: 13 | W4: 14 | X4: 9 | Y4: 105 | AH4: 3 | AI4: 0.4 | AP4: 39778 | AR4: -0.0013888889 | AS4: a | AU4: 39859 | AV4: 7 | AY4: 10 | AZ4: 4 | BB4: 102000 | BC4: 14 | BE4: 101 | BF4: 3 | BG4: 4
A5: FALSE | B5: 23 | C5: 21 | E5: 5 | F5: x*y | G5: 16 | H5: 45717 | I5: 1200 | J5: 2750 | L5: 8 | M5: eight | N5: 80 | P5: 4 | Q5: 5 | R5: 6 | U5: Apple | V5: 14 | W5: 15 | X5: 10 | Y5: 75 | AK5: 58 | AL5: 35 | AP5: 39786 | AS5: A | AU5: 39904 | AV5: 11 | AY5: 11 | AZ5: 5 | BB5: 150000 | BC5: 15 | BE5: 94 | BF5: 5 | BG5: 3
A6: 45688 | B6: 42 | C6: 40 | D6: 5 | E6: 6 | F6: Чай | G6: 32 | H6: 45473 | L6: 13 | M6: thirteen | N6: 130 | U6: Pear | V6: 9 | W6: 8 | X6: 8 | Y6: 76.8 | AK6: 11 | AP6: 39834 | AS6: 3 | AV6: 4 | BB6: 220000 | BC6: 16 | BE6: 97 | BF6: 2 | BG6: 2
A7: =1/0 -> #DIV/0! | B7: -3.5 | C7: -1 | D7: FALSE | E7: 7 | F7: Чаи | G7: 64 | H7: 46022 | I7: -10000 | J7: 100 | U7: Apple | V7: 8 | W7: 9 | X7: 6 | Y7: 45 | AK7: TRUE | AL7: 23 | AP7: 38719 | AS7: 1 | AU7: 39508 | AV7: 3 | BE7: 95 | BG7: 1
A8: =NA() -> #N/A | B8: 10.25 | C8: 9 | D8: 3.5 | E8: 8 | I8: 3000 | J8: 200 | L8: 1 | M8: 2 | N8: 3 | O8: 5 | P8: 8 | Q8: 13 | AP8: 38733 | AS8: b | AU8: 39448 | BG8: 2
A9: Привет Мир | I9: 4200 | J9: 300 | L9: one | M9: two | N9: three | O9: five | P9: eight | Q9: thirteen | AK9: 58 | AL9: 35 | AU9: 39751 | BG9: 3
A10: 1.5 | J10: 400 | L10: 10 | M10: 20 | N10: 30 | O10: 50 | P10: 80 | Q10: 130 | AK10: 11 | AL10: =1/0 -> #DIV/0! | AU10: 39859 | BG10: 5
A11: 1,5 | I11: 6800 | J11: 500 | AK11: 10 | AL11: 23 | AU11: 39904 | BG11: 6
A12: 0 | BG12: 1
A13: ="" | I13: -10000
A14: =CHAR(9)&"abc"&CHAR(10) -> abc | I14: 3000
A15: 45688.75 | I15: =NA() -> #N/A
I16: 6800
I17: 1200

Sheet C
A1: {=_xlfn.AGGREGATE(14,6,T!M1:M11,3)} -> 6 | B1: =IF(ISERROR(A1),ERROR.TYPE(A1),IF(ISNUMBER(A1),0,IF(ISLOGICAL(A1),IF(A1,-1,-2),IF(ISTEXT(A1),-3,-4)))) -> 0 | C1: =IF(ISNUMBER(A1),A1,0) -> 6 | D1: =IF(ISTEXT(A1),A1,"") | E1: AGGREGATE#275
A2: {=_xlfn.AGGREGATE(15,0,T!M1:M11,3)} -> 2 | B2: =IF(ISERROR(A2),ERROR.TYPE(A2),IF(ISNUMBER(A2),0,IF(ISLOGICAL(A2),IF(A2,-1,-2),IF(ISTEXT(A2),-3,-4)))) -> 0 | C2: =IF(ISNUMBER(A2),A2,0) -> 2 | D2: =IF(ISTEXT(A2),A2,"") | E2: AGGREGATE#276
A3: {=_xlfn.AGGREGATE(15,2,T!M1:M11,3)} -> 2 | B3: =IF(ISERROR(A3),ERROR.TYPE(A3),IF(ISNUMBER(A3),0,IF(ISLOGICAL(A3),IF(A3,-1,-2),IF(ISTEXT(A3),-3,-4)))) -> 0 | C3: =IF(ISNUMBER(A3),A3,0) -> 2 | D3: =IF(ISTEXT(A3),A3,"") | E3: AGGREGATE#277
A4: {=_xlfn.AGGREGATE(15,4,T!M1:M11,3)} -> 2 | B4: =IF(ISERROR(A4),ERROR.TYPE(A4),IF(ISNUMBER(A4),0,IF(ISLOGICAL(A4),IF(A4,-1,-2),IF(ISTEXT(A4),-3,-4)))) -> 0 | C4: =IF(ISNUMBER(A4),A4,0) -> 2 | D4: =IF(ISTEXT(A4),A4,"") | E4: AGGREGATE#278
A5: {=_xlfn.AGGREGATE(15,6,T!M1:M11,3)} -> 2 | B5: =IF(ISERROR(A5),ERROR.TYPE(A5),IF(ISNUMBER(A5),0,IF(ISLOGICAL(A5),IF(A5,-1,-2),IF(ISTEXT(A5),-3,-4)))) -> 0 | C5: =IF(ISNUMBER(A5),A5,0) -> 2 | D5: =IF(ISTEXT(A5),A5,"") | E5: AGGREGATE#279
A6: {=_xlfn.AGGREGATE(16,0,T!M1:M11,0.3)} -> 2.7 | B6: =IF(ISERROR(A6),ERROR.TYPE(A6),IF(ISNUMBER(A6),0,IF(ISLOGICAL(A6),IF(A6,-1,-2),IF(ISTEXT(A6),-3,-4)))) -> 0 | C6: =IF(ISNUMBER(A6),A6,0) -> 2.7 | D6: =IF(ISTEXT(A6),A6,"") | E6: AGGREGATE#280
A7: {=_xlfn.AGGREGATE(16,2,T!M1:M11,0.3)} -> 2.7 | B7: =IF(ISERROR(A7),ERROR.TYPE(A7),IF(ISNUMBER(A7),0,IF(ISLOGICAL(A7),IF(A7,-1,-2),IF(ISTEXT(A7),-3,-4)))) -> 0 | C7: =IF(ISNUMBER(A7),A7,0) -> 2.7 | D7: =IF(ISTEXT(A7),A7,"") | E7: AGGREGATE#281
A8: {=_xlfn.AGGREGATE(16,4,T!M1:M11,0.3)} -> 3 | B8: =IF(ISERROR(A8),ERROR.TYPE(A8),IF(ISNUMBER(A8),0,IF(ISLOGICAL(A8),IF(A8,-1,-2),IF(ISTEXT(A8),-3,-4)))) -> 0 | C8: =IF(ISNUMBER(A8),A8,0) -> 3 | D8: =IF(ISTEXT(A8),A8,"") | E8: AGGREGATE#282
A9: {=_xlfn.AGGREGATE(16,6,T!M1:M11,0.3)} -> 3 | B9: =IF(ISERROR(A9),ERROR.TYPE(A9),IF(ISNUMBER(A9),0,IF(ISLOGICAL(A9),IF(A9,-1,-2),IF(ISTEXT(A9),-3,-4)))) -> 0 | C9: =IF(ISNUMBER(A9),A9,0) -> 3 | D9: =IF(ISTEXT(A9),A9,"") | E9: AGGREGATE#283
A10: {=_xlfn.AGGREGATE(17,0,T!M1:M11,1)} -> 2.25 | B10: =IF(ISERROR(A10),ERROR.TYPE(A10),IF(ISNUMBER(A10),0,IF(ISLOGICAL(A10),IF(A10,-1,-2),IF(ISTEXT(A10),-3,-4)))) -> 0 | C10: =IF(ISNUMBER(A10),A10,0) -> 2.25 | D10: =IF(ISTEXT(A10),A10,"") | E10: AGGREGATE#284
A11: {=_xlfn.AGGREGATE(17,2,T!M1:M11,1)} -> 2.25 | B11: =IF(ISERROR(A11),ERROR.TYPE(A11),IF(ISNUMBER(A11),0,IF(ISLOGICAL(A11),IF(A11,-1,-2),IF(ISTEXT(A11),-3,-4)))) -> 0 | C11: =IF(ISNUMBER(A11),A11,0) -> 2.25 | D11: =IF(ISTEXT(A11),A11,"") | E11: AGGREGATE#285
A12: {=_xlfn.AGGREGATE(17,4,T!M1:M11,1)} -> 2.5 | B12: =IF(ISERROR(A12),ERROR.TYPE(A12),IF(ISNUMBER(A12),0,IF(ISLOGICAL(A12),IF(A12,-1,-2),IF(ISTEXT(A12),-3,-4)))) -> 0 | C12: =IF(ISNUMBER(A12),A12,0) -> 2.5 | D12: =IF(ISTEXT(A12),A12,"") | E12: AGGREGATE#286
A13: {=_xlfn.AGGREGATE(17,6,T!M1:M11,1)} -> 2.5 | B13: =IF(ISERROR(A13),ERROR.TYPE(A13),IF(ISNUMBER(A13),0,IF(ISLOGICAL(A13),IF(A13,-1,-2),IF(ISTEXT(A13),-3,-4)))) -> 0 | C13: =IF(ISNUMBER(A13),A13,0) -> 2.5 | D13: =IF(ISTEXT(A13),A13,"") | E13: AGGREGATE#287
A14: {=_xlfn.AGGREGATE(18,0,T!M1:M11,0.3)} -> 2.3 | B14: =IF(ISERROR(A14),ERROR.TYPE(A14),IF(ISNUMBER(A14),0,IF(ISLOGICAL(A14),IF(A14,-1,-2),IF(ISTEXT(A14),-3,-4)))) -> 0 | C14: =IF(ISNUMBER(A14),A14,0) -> 2.3 | D14: =IF(ISTEXT(A14),A14,"") | E14: AGGREGATE#288
A15: {=_xlfn.AGGREGATE(18,2,T!M1:M11,0.3)} -> 2.3 | B15: =IF(ISERROR(A15),ERROR.TYPE(A15),IF(ISNUMBER(A15),0,IF(ISLOGICAL(A15),IF(A15,-1,-2),IF(ISTEXT(A15),-3,-4)))) -> 0 | C15: =IF(ISNUMBER(A15),A15,0) -> 2.3 | D15: =IF(ISTEXT(A15),A15,"") | E15: AGGREGATE#289
A16: {=_xlfn.AGGREGATE(18,4,T!M1:M11,0.3)} -> 2.6 | B16: =IF(ISERROR(A16),ERROR.TYPE(A16),IF(ISNUMBER(A16),0,IF(ISLOGICAL(A16),IF(A16,-1,-2),IF(ISTEXT(A16),-3,-4)))) -> 0 | C16: =IF(ISNUMBER(A16),A16,0) -> 2.6 | D16: =IF(ISTEXT(A16),A16,"") | E16: AGGREGATE#290
A17: {=_xlfn.AGGREGATE(18,6,T!M1:M11,0.3)} -> 2.6 | B17: =IF(ISERROR(A17),ERROR.TYPE(A17),IF(ISNUMBER(A17),0,IF(ISLOGICAL(A17),IF(A17,-1,-2),IF(ISTEXT(A17),-3,-4)))) -> 0 | C17: =IF(ISNUMBER(A17),A17,0) -> 2.6 | D17: =IF(ISTEXT(A17),A17,"") | E17: AGGREGATE#291
A18: {=_xlfn.AGGREGATE(19,0,T!M1:M11,1)} -> 1.75 | B18: =IF(ISERROR(A18),ERROR.TYPE(A18),IF(ISNUMBER(A18),0,IF(ISLOGICAL(A18),IF(A18,-1,-2),IF(ISTEXT(A18),-3,-4)))) -> 0 | C18: =IF(ISNUMBER(A18),A18,0) -> 1.75 | D18: =IF(ISTEXT(A18),A18,"") | E18: AGGREGATE#292
A19: {=_xlfn.AGGREGATE(19,2,T!M1:M11,1)} -> 1.75 | B19: =IF(ISERROR(A19),ERROR.TYPE(A19),IF(ISNUMBER(A19),0,IF(ISLOGICAL(A19),IF(A19,-1,-2),IF(ISTEXT(A19),-3,-4)))) -> 0 | C19: =IF(ISNUMBER(A19),A19,0) -> 1.75 | D19: =IF(ISTEXT(A19),A19,"") | E19: AGGREGATE#293
A20: {=_xlfn.AGGREGATE(19,4,T!M1:M11,1)} -> 2 | B20: =IF(ISERROR(A20),ERROR.TYPE(A20),IF(ISNUMBER(A20),0,IF(ISLOGICAL(A20),IF(A20,-1,-2),IF(ISTEXT(A20),-3,-4)))) -> 0 | C20: =IF(ISNUMBER(A20),A20,0) -> 2 | D20: =IF(ISTEXT(A20),A20,"") | E20: AGGREGATE#294
A21: {=_xlfn.AGGREGATE(19,6,T!M1:M11,1)} -> 2 | B21: =IF(ISERROR(A21),ERROR.TYPE(A21),IF(ISNUMBER(A21),0,IF(ISLOGICAL(A21),IF(A21,-1,-2),IF(ISTEXT(A21),-3,-4)))) -> 0 | C21: =IF(ISNUMBER(A21),A21,0) -> 2 | D21: =IF(ISTEXT(A21),A21,"") | E21: AGGREGATE#295
A22: {=_xlfn.AGGREGATE(14,0,T!H1:H6,3)} -> #DIV/0! | B22: =IF(ISERROR(A22),ERROR.TYPE(A22),IF(ISNUMBER(A22),0,IF(ISLOGICAL(A22),IF(A22,-1,-2),IF(ISTEXT(A22),-3,-4)))) -> 2 | C22: =IF(ISNUMBER(A22),A22,0) -> 0 | D22: =IF(ISTEXT(A22),A22,"") | E22: AGGREGATE#296
A23: {=_xlfn.AGGREGATE(14,2,T!H1:H6,3)} -> 2 | B23: =IF(ISERROR(A23),ERROR.TYPE(A23),IF(ISNUMBER(A23),0,IF(ISLOGICAL(A23),IF(A23,-1,-2),IF(ISTEXT(A23),-3,-4)))) -> 0 | C23: =IF(ISNUMBER(A23),A23,0) -> 2 | D23: =IF(ISTEXT(A23),A23,"") | E23: AGGREGATE#297
A24: {=_xlfn.AGGREGATE(14,4,T!H1:H6,3)} -> #DIV/0! | B24: =IF(ISERROR(A24),ERROR.TYPE(A24),IF(ISNUMBER(A24),0,IF(ISLOGICAL(A24),IF(A24,-1,-2),IF(ISTEXT(A24),-3,-4)))) -> 2 | C24: =IF(ISNUMBER(A24),A24,0) -> 0 | D24: =IF(ISTEXT(A24),A24,"") | E24: AGGREGATE#298
A25: {=_xlfn.AGGREGATE(14,6,T!H1:H6,3)} -> 2 | B25: =IF(ISERROR(A25),ERROR.TYPE(A25),IF(ISNUMBER(A25),0,IF(ISLOGICAL(A25),IF(A25,-1,-2),IF(ISTEXT(A25),-3,-4)))) -> 0 | C25: =IF(ISNUMBER(A25),A25,0) -> 2 | D25: =IF(ISTEXT(A25),A25,"") | E25: AGGREGATE#299
A26: {=_xlfn.AGGREGATE(15,0,T!H1:H6,3)} -> #DIV/0! | B26: =IF(ISERROR(A26),ERROR.TYPE(A26),IF(ISNUMBER(A26),0,IF(ISLOGICAL(A26),IF(A26,-1,-2),IF(ISTEXT(A26),-3,-4)))) -> 2 | C26: =IF(ISNUMBER(A26),A26,0) -> 0 | D26: =IF(ISTEXT(A26),A26,"") | E26: AGGREGATE#300
A27: {=_xlfn.AGGREGATE(15,2,T!H1:H6,3)} -> 7 | B27: =IF(ISERROR(A27),ERROR.TYPE(A27),IF(ISNUMBER(A27),0,IF(ISLOGICAL(A27),IF(A27,-1,-2),IF(ISTEXT(A27),-3,-4)))) -> 0 | C27: =IF(ISNUMBER(A27),A27,0) -> 7 | D27: =IF(ISTEXT(A27),A27,"") | E27: AGGREGATE#301
A28: {=_xlfn.AGGREGATE(15,4,T!H1:H6,3)} -> #DIV/0! | B28: =IF(ISERROR(A28),ERROR.TYPE(A28),IF(ISNUMBER(A28),0,IF(ISLOGICAL(A28),IF(A28,-1,-2),IF(ISTEXT(A28),-3,-4)))) -> 2 | C28: =IF(ISNUMBER(A28),A28,0) -> 0 | D28: =IF(ISTEXT(A28),A28,"") | E28: AGGREGATE#302
A29: {=_xlfn.AGGREGATE(15,6,T!H1:H6,3)} -> 7 | B29: =IF(ISERROR(A29),ERROR.TYPE(A29),IF(ISNUMBER(A29),0,IF(ISLOGICAL(A29),IF(A29,-1,-2),IF(ISTEXT(A29),-3,-4)))) -> 0 | C29: =IF(ISNUMBER(A29),A29,0) -> 7 | D29: =IF(ISTEXT(A29),A29,"") | E29: AGGREGATE#303
A30: {=_xlfn.AGGREGATE(16,0,T!H1:H6,0.3)} -> #DIV/0! | B30: =IF(ISERROR(A30),ERROR.TYPE(A30),IF(ISNUMBER(A30),0,IF(ISLOGICAL(A30),IF(A30,-1,-2),IF(ISTEXT(A30),-3,-4)))) -> 2 | C30: =IF(ISNUMBER(A30),A30,0) -> 0 | D30: =IF(ISTEXT(A30),A30,"") | E30: AGGREGATE#304
A31: {=_xlfn.AGGREGATE(16,2,T!H1:H6,0.3)} -> 2.6 | B31: =IF(ISERROR(A31),ERROR.TYPE(A31),IF(ISNUMBER(A31),0,IF(ISLOGICAL(A31),IF(A31,-1,-2),IF(ISTEXT(A31),-3,-4)))) -> 0 | C31: =IF(ISNUMBER(A31),A31,0) -> 2.6 | D31: =IF(ISTEXT(A31),A31,"") | E31: AGGREGATE#305
A32: {=_xlfn.AGGREGATE(16,4,T!H1:H6,0.3)} -> #DIV/0! | B32: =IF(ISERROR(A32),ERROR.TYPE(A32),IF(ISNUMBER(A32),0,IF(ISLOGICAL(A32),IF(A32,-1,-2),IF(ISTEXT(A32),-3,-4)))) -> 2 | C32: =IF(ISNUMBER(A32),A32,0) -> 0 | D32: =IF(ISTEXT(A32),A32,"") | E32: AGGREGATE#306
A33: {=_xlfn.AGGREGATE(16,6,T!H1:H6,0.3)} -> 2.6 | B33: =IF(ISERROR(A33),ERROR.TYPE(A33),IF(ISNUMBER(A33),0,IF(ISLOGICAL(A33),IF(A33,-1,-2),IF(ISTEXT(A33),-3,-4)))) -> 0 | C33: =IF(ISNUMBER(A33),A33,0) -> 2.6 | D33: =IF(ISTEXT(A33),A33,"") | E33: AGGREGATE#307
A34: {=_xlfn.AGGREGATE(17,0,T!H1:H6,1)} -> #DIV/0! | B34: =IF(ISERROR(A34),ERROR.TYPE(A34),IF(ISNUMBER(A34),0,IF(ISLOGICAL(A34),IF(A34,-1,-2),IF(ISTEXT(A34),-3,-4)))) -> 2 | C34: =IF(ISNUMBER(A34),A34,0) -> 0 | D34: =IF(ISTEXT(A34),A34,"") | E34: AGGREGATE#308
A35: {=_xlfn.AGGREGATE(17,2,T!H1:H6,1)} -> 2.5 | B35: =IF(ISERROR(A35),ERROR.TYPE(A35),IF(ISNUMBER(A35),0,IF(ISLOGICAL(A35),IF(A35,-1,-2),IF(ISTEXT(A35),-3,-4)))) -> 0 | C35: =IF(ISNUMBER(A35),A35,0) -> 2.5 | D35: =IF(ISTEXT(A35),A35,"") | E35: AGGREGATE#309
A36: {=_xlfn.AGGREGATE(17,4,T!H1:H6,1)} -> #DIV/0! | B36: =IF(ISERROR(A36),ERROR.TYPE(A36),IF(ISNUMBER(A36),0,IF(ISLOGICAL(A36),IF(A36,-1,-2),IF(ISTEXT(A36),-3,-4)))) -> 2 | C36: =IF(ISNUMBER(A36),A36,0) -> 0 | D36: =IF(ISTEXT(A36),A36,"") | E36: AGGREGATE#310
A37: {=_xlfn.AGGREGATE(17,6,T!H1:H6,1)} -> 2.5 | B37: =IF(ISERROR(A37),ERROR.TYPE(A37),IF(ISNUMBER(A37),0,IF(ISLOGICAL(A37),IF(A37,-1,-2),IF(ISTEXT(A37),-3,-4)))) -> 0 | C37: =IF(ISNUMBER(A37),A37,0) -> 2.5 | D37: =IF(ISTEXT(A37),A37,"") | E37: AGGREGATE#311
A38: {=_xlfn.AGGREGATE(18,0,T!H1:H6,0.3)} -> #DIV/0! | B38: =IF(ISERROR(A38),ERROR.TYPE(A38),IF(ISNUMBER(A38),0,IF(ISLOGICAL(A38),IF(A38,-1,-2),IF(ISTEXT(A38),-3,-4)))) -> 2 | C38: =IF(ISNUMBER(A38),A38,0) -> 0 | D38: =IF(ISTEXT(A38),A38,"") | E38: AGGREGATE#312
A39: {=_xlfn.AGGREGATE(18,2,T!H1:H6,0.3)} -> 2.2 | B39: =IF(ISERROR(A39),ERROR.TYPE(A39),IF(ISNUMBER(A39),0,IF(ISLOGICAL(A39),IF(A39,-1,-2),IF(ISTEXT(A39),-3,-4)))) -> 0 | C39: =IF(ISNUMBER(A39),A39,0) -> 2.2 | D39: =IF(ISTEXT(A39),A39,"") | E39: AGGREGATE#313
A40: {=_xlfn.AGGREGATE(18,4,T!H1:H6,0.3)} -> #DIV/0! | B40: =IF(ISERROR(A40),ERROR.TYPE(A40),IF(ISNUMBER(A40),0,IF(ISLOGICAL(A40),IF(A40,-1,-2),IF(ISTEXT(A40),-3,-4)))) -> 2 | C40: =IF(ISNUMBER(A40),A40,0) -> 0 | D40: =IF(ISTEXT(A40),A40,"") | E40: AGGREGATE#314
...
