Workbook

Sheet Rq
A1: ="a"&_xlfn.UNICHAR(133)&"b" -> a b
A2: ="a"&_xlfn.UNICHAR(8232)&"b" -> a b
A3: ="a"&_xlfn.UNICHAR(11)&"b" -> a_x000B_b
A4: ="a"&_xlfn.UNICHAR(12)&"b" -> a_x000C_b
A5: abc
A6: é
A7: a‿b
A8: ３
A9: ς
A10: aA
A11: ="ab"&CHAR(13)&CHAR(10) -> ab_x000D_
A12: a
A13: ٣
A14: aaaaaaaaaaaaaaaaab
A15: aaaaaaaaaaaaaaaaaab
A16: aaaaaaaaaaaaaaaaaaab
A17: aaaaaaaaaaaaaaaaaaaaaaab
A18: aaaaaaaaaaaaaaaaaaaaaaaaaaab
A19: aaaaaaaaaaaaaaaaaaaaaaaaaaaaaaab
A20: aaaaaaaaaaaaaaaabaaaaaaaaaaaaaaaabaaaaaaaaaaaaaaaabaaaaaaaaaaaaaaaabaaaaaaaaaaaaaaaabaaaaaaaaaaaaaaaabaaaaaaaaaaaaaaaabaaaaaaaaaaaaaaaabaaaaaaaaaaaaaaaabaaaaaaaaaaaaaaaabaaaaaaaaaaaaaaaabaaaaaaaaaaaaaaaabaaaaaaaaaaaaaaaabaaaaaaaaaaaaaaaabaaaaaaaaaaaaaaaabaaaaaaaaaaaaaaaabaaaaaaaaaaaaaaaabaaaaaaaaaaaaaaaabaaaaaaaaaaaaaaaabaaaaaaaaaaaaaaaabaaaaaaaaaaaaaaaabaaaaaaaaaaaaaaaabaaaaaaaaaaaaaaaabaaaaaaaaaaaaaaaabaaaaaaaaaaaaaaaabaaaaaaaaaaaaaaaabaaaaaaaaaaaaaaaabaaaaaaaaaaaaaaaabaaaaaaaaaaaaaaaabaaaaaaaaaaaaaaaabaaaaaaaaaaaaaaaabaaaaaaaaaaaaaaaabaaaaaaaaaaaaaaaabaaaaaaaaaaaaaaaabaaaaaaaaaaaaaaaabaaaaaaaaaaaaaaaabaaaaaaaaaaaaaaaabaaaaaaaaaaaaaaaabaaaaaaaaaaaaaaaabaaaaaaaaaaaaaaaab
A21: (a(b)c)
A22: ab
A23: ="a"&CHAR(13) -> a_x000D_
A24: a_b
A25: aaaaaaaaaaaaaaaaaaaaaaaab
A26: aaaaaaaaaaaaaaaaaaaaaaaaab
A27: aaaaaaaaaaaaaaaaaaaaaaaaaab
A28: xxxxxxxxxxzy
A29: xxxxxxxxxxxxzy
A30: xxxxxxxxxxxxxxzy
A31: xxxxxxxxxxxxxxxxzy

Sheet D
B1: 4 | C1: 2 | D1: 1 | E1: 1 | F1: Аренда | G1: 1 | H1: 45657 | I1: -10000 | J1: -10000 | L1: 1 | M1: one | N1: 10 | P1: 1 | Q1: 2 | R1: 5 | S1: 6 | U1: Tree | V1: Height | W1: Age | X1: Yield | Y1: Profit | AA1: Tree | AB1: Height | AC1: Tree | AD1: Tree | AE1: Tree | AF1: Tree | AG1: Tree | AH1: 0 | AI1: 0.2 | AK1: 58 | AL1: 35 | AM1: 45.35 | AN1: 47.65 | AP1: 41235 | AQ1: 0.09 | AR1: 1 | AS1: 1 | AT1: 0 | AU1: 39448 | AV1: 4 | AW1: TRUE | AX1: TRUE | AY1: 3 | AZ1: 1 | BA1: 6 | BB1: 33100 | BC1: 11 | BD1: 17 | BE1: 89 | BF1: 1 | BG1: 1 | BH1: a
A2: 2 | B2: 8 | C2: 7 | D2: 2 | E2: 2 | F2: аренда | G2: 2 | H2: 45658 | I2: 3000 | J2: 2750 | L2: 2 | M2: two | N2: 20 | P2: 3 | Q2: 4 | R2: 7 | S2: 8 | U2: Apple | V2: 18 | W2: 20 | X2: 14 | Y2: 105 | AA2: Apple | AB2: >10 | AC2: Pear | AD2: a* | AE2: Cherry | AF2: Plum | AH2: 1 | AI2: 0.3 | AK2: 11 | AL2: 25 | AM2: 17.56 | AN2: 18.44 | AP2: 41247 | AQ2: 0.11 | AR2: -0.5 | AS2: 2 | AT2: 10 | AU2: 39508 | AV2: 5 | AW2: FALSE | AX2: TRUE | AY2: 5 | AZ2: 2 | BA2: 7 | BB2: 47300 | BC2: 12 | BD2: 18 | BE2: 88 | BF2: 2 | BG2: 2
A3: abc | B3: 15 | C3: 11 | D3: abc | E3: =1/0 -> #DIV/0! | F3: Арендй | G3: 4 | H3: 45659 | I3: 4200 | J3: 4250 | L3: 3 | M3: three | N3: 30 | U3: Pear | V3: 12 | W3: 12 | X3: 10 | Y3: 96 | AH3: 2 | AI3: 0.1 | AK3: 10 | AL3: 23 | AM3: 16.09 | AN3: 16.91 | AP3: 41295 | AQ3: 0.1 | AR3: 0.041666667 | AS3: 2 | AT3: 20 | AU3: 39751 | AV3: 8 | AW3: abc | AX3: 1 | AY3: 7 | AZ3: 3 | BB3: 69000 | BC3: 13 | BE3: 92 | BF3: 2 | BG3: 3 | BH3: Б
A4: TRUE | B4: 16 | C4: 19 | D4: TRUE | E4: 4 | F4: Арeнда* | G4: 8 | H4: 45689 | I4: 6800 | J4: 3250 | L4: 5 | M4: five | N4: 50 | P4: 1 | Q4: 2 | R4: 3 | U4: Cherry | V4: 13 | W4: 14 | X4: 9 | Y4: 105 | AH4: 3 | AI4: 0.4 | AP4: 39778 | AR4: -0.0013888889 | AS4: a | AU4: 39859 | AV4: 7 | AY4: 10 | AZ4: 4 | BB4: 102000 | BC4: 14 | BE4: 101 | BF4: 3 | BG4: 4
A5: FALSE | B5: 23 | C5: 21 | E5: 5 | F5: x*y | G5: 16 | H5: 45717 | I5: 1200 | J5: 2750 | L5: 8 | M5: eight | N5: 80 | P5: 4 | Q5: 5 | R5: 6 | U5: Apple | V5: 14 | W5: 15 | X5: 10 | Y5: 75 | AK5: 58 | AL5: 35 | AP5: 39786 | AS5: A | AU5: 39904 | AV5: 11 | AY5: 11 | AZ5: 5 | BB5: 150000 | BC5: 15 | BE5: 94 | BF5: 5 | BG5: 3
A6: 45688 | B6: 42 | C6: 40 | D6: 5 | E6: 6 | F6: Чай | G6: 32 | H6: 45473 | L6: 13 | M6: thirteen | N6: 130 | U6: Pear | V6: 9 | W6: 8 | X6: 8 | Y6: 76.8 | AK6: 11 | AP6: 39834 | AS6: 3 | AV6: 4 | BB6: 220000 | BC6: 16 | BE6: 97 | BF6: 2 | BG6: 2
A7: =1/0 -> #DIV/0! | B7: -3.5 | C7: -1 | D7: FALSE | E7: 7 | F7: Чаи | G7: 64 | H7: 46022 | I7: -10000 | J7: 100 | U7: Apple | V7: 8 | W7: 9 | X7: 6 | Y7: 45 | AK7: TRUE | AL7: 23 | AP7: 38719 | AS7: 1 | AU7: 39508 | AV7: 3 | BE7: 95 | BG7: 1
A8: =NA() -> #N/A | B8: 10.25 | C8: 9 | D8: 3.5 | E8: 8 | I8: 3000 | J8: 200 | L8: 1 | M8: 2 | N8: 3 | O8: 5 | P8: 8 | Q8: 13 | AP8: 38733 | AS8: b | AU8: 39448 | BG8: 2
A9: Привет Мир | I9: 4200 | J9: 300 | L9: one | M9: two | N9: three | O9: five | P9: eight | Q9: thirteen | AK9: 58 | AL9: 35 | AU9: 39751 | BG9: 3
A10: 1.5 | J10: 400 | L10: 10 | M10: 20 | N10: 30 | O10: 50 | P10: 80 | Q10: 130 | AK10: 11 | AL10: =1/0 -> #DIV/0! | AU10: 39859 | BG10: 5
A11: 1,5 | I11: 6800 | J11: 500 | AK11: 10 | AL11: 23 | AU11: 39904 | BG11: 6
A12: 0 | BG12: 1
A13: ="" | I13: -10000
A14: =CHAR(9)&"abc"&CHAR(10) -> abc | I14: 3000
A15: 45688.75 | I15: =NA() -> #N/A
I16: 6800
I17: 1200

Sheet C
A1: {=_xlfn.XMATCH("a.b",Rq!A1,3)} -> 1 | B1: =IF(ISERROR(A1),ERROR.TYPE(A1),IF(ISNUMBER(A1),0,IF(ISLOGICAL(A1),IF(A1,-1,-2),IF(ISTEXT(A1),-3,-4)))) -> 0 | C1: =IF(ISNUMBER(A1),A1,0) -> 1 | D1: =IF(ISTEXT(A1),A1,"") | E1: line#1
A2: {=_xlfn.XMATCH("(?m)a$",Rq!A1,3)} -> #N/A | B2: =IF(ISERROR(A2),ERROR.TYPE(A2),IF(ISNUMBER(A2),0,IF(ISLOGICAL(A2),IF(A2,-1,-2),IF(ISTEXT(A2),-3,-4)))) -> 7 | C2: =IF(ISNUMBER(A2),A2,0) -> 0 | D2: =IF(ISTEXT(A2),A2,"") | E2: line#2
A3: {=_xlfn.XMATCH("a\Rb",Rq!A1,3)} -> 1 | B3: =IF(ISERROR(A3),ERROR.TYPE(A3),IF(ISNUMBER(A3),0,IF(ISLOGICAL(A3),IF(A3,-1,-2),IF(ISTEXT(A3),-3,-4)))) -> 0 | C3: =IF(ISNUMBER(A3),A3,0) -> 1 | D3: =IF(ISTEXT(A3),A3,"") | E3: line#3
A4: {=_xlfn.XMATCH("a.b",Rq!A2,3)} -> 1 | B4: =IF(ISERROR(A4),ERROR.TYPE(A4),IF(ISNUMBER(A4),0,IF(ISLOGICAL(A4),IF(A4,-1,-2),IF(ISTEXT(A4),-3,-4)))) -> 0 | C4: =IF(ISNUMBER(A4),A4,0) -> 1 | D4: =IF(ISTEXT(A4),A4,"") | E4: line#4
A5: {=_xlfn.XMATCH("(?m)a$",Rq!A2,3)} -> #N/A | B5: =IF(ISERROR(A5),ERROR.TYPE(A5),IF(ISNUMBER(A5),0,IF(ISLOGICAL(A5),IF(A5,-1,-2),IF(ISTEXT(A5),-3,-4)))) -> 7 | C5: =IF(ISNUMBER(A5),A5,0) -> 0 | D5: =IF(ISTEXT(A5),A5,"") | E5: line#5
A6: {=_xlfn.XMATCH("a.b",Rq!A3,3)} -> 1 | B6: =IF(ISERROR(A6),ERROR.TYPE(A6),IF(ISNUMBER(A6),0,IF(ISLOGICAL(A6),IF(A6,-1,-2),IF(ISTEXT(A6),-3,-4)))) -> 0 | C6: =IF(ISNUMBER(A6),A6,0) -> 1 | D6: =IF(ISTEXT(A6),A6,"") | E6: line#6
A7: {=_xlfn.XMATCH("a.b",Rq!A4,3)} -> 1 | B7: =IF(ISERROR(A7),ERROR.TYPE(A7),IF(ISNUMBER(A7),0,IF(ISLOGICAL(A7),IF(A7,-1,-2),IF(ISTEXT(A7),-3,-4)))) -> 0 | C7: =IF(ISNUMBER(A7),A7,0) -> 1 | D7: =IF(ISTEXT(A7),A7,"") | E7: line#7
A8: {=_xlfn.XMATCH("b$",Rq!A11,3)} -> 1 | B8: =IF(ISERROR(A8),ERROR.TYPE(A8),IF(ISNUMBER(A8),0,IF(ISLOGICAL(A8),IF(A8,-1,-2),IF(ISTEXT(A8),-3,-4)))) -> 0 | C8: =IF(ISNUMBER(A8),A8,0) -> 1 | D8: =IF(ISTEXT(A8),A8,"") | E8: line#8
A9: {=_xlfn.XMATCH("a$",Rq!A23,3)} -> 1 | B9: =IF(ISERROR(A9),ERROR.TYPE(A9),IF(ISNUMBER(A9),0,IF(ISLOGICAL(A9),IF(A9,-1,-2),IF(ISTEXT(A9),-3,-4)))) -> 0 | C9: =IF(ISNUMBER(A9),A9,0) -> 1 | D9: =IF(ISTEXT(A9),A9,"") | E9: line#9
A10: {=_xlfn.XMATCH("a\vb",Rq!A1,3)} -> 1 | B10: =IF(ISERROR(A10),ERROR.TYPE(A10),IF(ISNUMBER(A10),0,IF(ISLOGICAL(A10),IF(A10,-1,-2),IF(ISTEXT(A10),-3,-4)))) -> 0 | C10: =IF(ISNUMBER(A10),A10,0) -> 1 | D10: =IF(ISTEXT(A10),A10,"") | E10: line#10
A11: {=_xlfn.XMATCH("(*LF)a.b",Rq!A1,3)} -> 1 | B11: =IF(ISERROR(A11),ERROR.TYPE(A11),IF(ISNUMBER(A11),0,IF(ISLOGICAL(A11),IF(A11,-1,-2),IF(ISTEXT(A11),-3,-4)))) -> 0 | C11: =IF(ISNUMBER(A11),A11,0) -> 1 | D11: =IF(ISTEXT(A11),A11,"") | E11: line#11
A12: {=_xlfn.XMATCH("(*ANYCRLF)a.b",Rq!A1,3)} -> 1 | B12: =IF(ISERROR(A12),ERROR.TYPE(A12),IF(ISNUMBER(A12),0,IF(ISLOGICAL(A12),IF(A12,-1,-2),IF(ISTEXT(A12),-3,-4)))) -> 0 | C12: =IF(ISNUMBER(A12),A12,0) -> 1 | D12: =IF(ISTEXT(A12),A12,"") | E12: line#12
A13: {=_xlfn.XMATCH("(?<=a{1,3})b",Rq!A5,3)} -> 1 | B13: =IF(ISERROR(A13),ERROR.TYPE(A13),IF(ISNUMBER(A13),0,IF(ISLOGICAL(A13),IF(A13,-1,-2),IF(ISTEXT(A13),-3,-4)))) -> 0 | C13: =IF(ISNUMBER(A13),A13,0) -> 1 | D13: =IF(ISTEXT(A13),A13,"") | E13: look#1
A14: {=_xlfn.XMATCH("(?<=a|bc)c",Rq!A5,3)} -> #N/A | B14: =IF(ISERROR(A14),ERROR.TYPE(A14),IF(ISNUMBER(A14),0,IF(ISLOGICAL(A14),IF(A14,-1,-2),IF(ISTEXT(A14),-3,-4)))) -> 7 | C14: =IF(ISNUMBER(A14),A14,0) -> 0 | D14: =IF(ISTEXT(A14),A14,"") | E14: look#2
A15: {=_xlfn.XMATCH("(?<=(a)|b)c",Rq!A5,3)} -> 1 | B15: =IF(ISERROR(A15),ERROR.TYPE(A15),IF(ISNUMBER(A15),0,IF(ISLOGICAL(A15),IF(A15,-1,-2),IF(ISTEXT(A15),-3,-4)))) -> 0 | C15: =IF(ISNUMBER(A15),A15,0) -> 1 | D15: =IF(ISTEXT(A15),A15,"") | E15: look#3
A16: {=_xlfn.XMATCH("^e\w$",Rq!A6,3)} -> 1 | B16: =IF(ISERROR(A16),ERROR.TYPE(A16),IF(ISNUMBER(A16),0,IF(ISLOGICAL(A16),IF(A16,-1,-2),IF(ISTEXT(A16),-3,-4)))) -> 0 | C16: =IF(ISNUMBER(A16),A16,0) -> 1 | D16: =IF(ISTEXT(A16),A16,"") | E16: class#1
A17: {=_xlfn.XMATCH("^a\wb$",Rq!A7,3)} -> 1 | B17: =IF(ISERROR(A17),ERROR.TYPE(A17),IF(ISNUMBER(A17),0,IF(ISLOGICAL(A17),IF(A17,-1,-2),IF(ISTEXT(A17),-3,-4)))) -> 0 | C17: =IF(ISNUMBER(A17),A17,0) -> 1 | D17: =IF(ISTEXT(A17),A17,"") | E17: class#2
A18: {=_xlfn.XMATCH("\d",Rq!A8,3)} -> 1 | B18: =IF(ISERROR(A18),ERROR.TYPE(A18),IF(ISNUMBER(A18),0,IF(ISLOGICAL(A18),IF(A18,-1,-2),IF(ISTEXT(A18),-3,-4)))) -> 0 | C18: =IF(ISNUMBER(A18),A18,0) -> 1 | D18: =IF(ISTEXT(A18),A18,"") | E18: class#3
A19: {=_xlfn.XMATCH("a\sb",Rq!A2,3)} -> 1 | B19: =IF(ISERROR(A19),ERROR.TYPE(A19),IF(ISNUMBER(A19),0,IF(ISLOGICAL(A19),IF(A19,-1,-2),IF(ISTEXT(A19),-3,-4)))) -> 0 | C19: =IF(ISNUMBER(A19),A19,0) -> 1 | D19: =IF(ISTEXT(A19),A19,"") | E19: class#4
A20: {=_xlfn.XMATCH("^\w+$",Rq!A24,3)} -> 1 | B20: =IF(ISERROR(A20),ERROR.TYPE(A20),IF(ISNUMBER(A20),0,IF(ISLOGICAL(A20),IF(A20,-1,-2),IF(ISTEXT(A20),-3,-4)))) -> 0 | C20: =IF(ISNUMBER(A20),A20,0) -> 1 | D20: =IF(ISTEXT(A20),A20,"") | E20: class#5
A21: {=_xlfn.XMATCH("[[:punct:]]",Rq!A7,3)} -> 1 | B21: =IF(ISERROR(A21),ERROR.TYPE(A21),IF(ISNUMBER(A21),0,IF(ISLOGICAL(A21),IF(A21,-1,-2),IF(ISTEXT(A21),-3,-4)))) -> 0 | C21: =IF(ISNUMBER(A21),A21,0) -> 1 | D21: =IF(ISTEXT(A21),A21,"") | E21: class#6
A22: {=_xlfn.XMATCH("\p{Xan}",Rq!A8,3)} -> 1 | B22: =IF(ISERROR(A22),ERROR.TYPE(A22),IF(ISNUMBER(A22),0,IF(ISLOGICAL(A22),IF(A22,-1,-2),IF(ISTEXT(A22),-3,-4)))) -> 0 | C22: =IF(ISNUMBER(A22),A22,0) -> 1 | D22: =IF(ISTEXT(A22),A22,"") | E22: class#7
A23: {=_xlfn.XMATCH("\p{sc=Cyrl}",Rq!A5,3)} -> #N/A | B23: =IF(ISERROR(A23),ERROR.TYPE(A23),IF(ISNUMBER(A23),0,IF(ISLOGICAL(A23),IF(A23,-1,-2),IF(ISTEXT(A23),-3,-4)))) -> 7 | C23: =IF(ISNUMBER(A23),A23,0) -> 0 | D23: =IF(ISTEXT(A23),A23,"") | E23: class#8
A24: {=_xlfn.XMATCH("\p{L&}",Rq!A9,3)} -> 1 | B24: =IF(ISERROR(A24),ERROR.TYPE(A24),IF(ISNUMBER(A24),0,IF(ISLOGICAL(A24),IF(A24,-1,-2),IF(ISTEXT(A24),-3,-4)))) -> 0 | C24: =IF(ISNUMBER(A24),A24,0) -> 1 | D24: =IF(ISTEXT(A24),A24,"") | E24: class#9
A25: {=_xlfn.XMATCH("\p{Greek}",Rq!A9,3)} -> 1 | B25: =IF(ISERROR(A25),ERROR.TYPE(A25),IF(ISNUMBER(A25),0,IF(ISLOGICAL(A25),IF(A25,-1,-2),IF(ISTEXT(A25),-3,-4)))) -> 0 | C25: =IF(ISNUMBER(A25),A25,0) -> 1 | D25: =IF(ISTEXT(A25),A25,"") | E25: class#10
A26: {=_xlfn.XMATCH("\p{ greek }",Rq!A9,3)} -> 1 | B26: =IF(ISERROR(A26),ERROR.TYPE(A26),IF(ISNUMBER(A26),0,IF(ISLOGICAL(A26),IF(A26,-1,-2),IF(ISTEXT(A26),-3,-4)))) -> 0 | C26: =IF(ISNUMBER(A26),A26,0) -> 1 | D26: =IF(ISTEXT(A26),A26,"") | E26: class#11
A27: {=_xlfn.XMATCH("\pL",Rq!A9,3)} -> 1 | B27: =IF(ISERROR(A27),ERROR.TYPE(A27),IF(ISNUMBER(A27),0,IF(ISLOGICAL(A27),IF(A27,-1,-2),IF(ISTEXT(A27),-3,-4)))) -> 0 | C27: =IF(ISNUMBER(A27),A27,0) -> 1 | D27: =IF(ISTEXT(A27),A27,"") | E27: class#12
A28: {=_xlfn.XMATCH("\p{Bidi_Class:L}",Rq!A9,3)} -> 1 | B28: =IF(ISERROR(A28),ERROR.TYPE(A28),IF(ISNUMBER(A28),0,IF(ISLOGICAL(A28),IF(A28,-1,-2),IF(ISTEXT(A28),-3,-4)))) -> 0 | C28: =IF(ISNUMBER(A28),A28,0) -> 1 | D28: =IF(ISTEXT(A28),A28,"") | E28: class#13
A29: {=_xlfn.XMATCH("(?i)σ",Rq!A9,3)} -> 1 | B29: =IF(ISERROR(A29),ERROR.TYPE(A29),IF(ISNUMBER(A29),0,IF(ISLOGICAL(A29),IF(A29,-1,-2),IF(ISTEXT(A29),-3,-4)))) -> 0 | C29: =IF(ISNUMBER(A29),A29,0) -> 1 | D29: =IF(ISTEXT(A29),A29,"") | E29: case#1
A30: {=_xlfn.XMATCH("(?i)(a)\1",Rq!A10,3)} -> 1 | B30: =IF(ISERROR(A30),ERROR.TYPE(A30),IF(ISNUMBER(A30),0,IF(ISLOGICAL(A30),IF(A30,-1,-2),IF(ISTEXT(A30),-3,-4)))) -> 0 | C30: =IF(ISNUMBER(A30),A30,0) -> 1 | D30: =IF(ISTEXT(A30),A30,"") | E30: case#2
A31: {=_xlfn.XMATCH("(?i)[^a]",Rq!A10,3)} -> #N/A | B31: =IF(ISERROR(A31),ERROR.TYPE(A31),IF(ISNUMBER(A31),0,IF(ISLOGICAL(A31),IF(A31,-1,-2),IF(ISTEXT(A31),-3,-4)))) -> 7 | C31: =IF(ISNUMBER(A31),A31,0) -> 0 | D31: =IF(ISTEXT(A31),A31,"") | E31: case#3
A32: {=_xlfn.XMATCH("(?i)\p{Lu}",Rq!A12,3)} -> 1 | B32: =IF(ISERROR(A32),ERROR.TYPE(A32),IF(ISNUMBER(A32),0,IF(ISLOGICAL(A32),IF(A32,-1,-2),IF(ISTEXT(A32),-3,-4)))) -> 0 | C32: =IF(ISNUMBER(A32),A32,0) -> 1 | D32: =IF(ISTEXT(A32),A32,"") | E32: case#4
A33: {=_xlfn.XMATCH("(?i)[A-Z]",Rq!A12,3)} -> 1 | B33: =IF(ISERROR(A33),ERROR.TYPE(A33),IF(ISNUMBER(A33),0,IF(ISLOGICAL(A33),IF(A33,-1,-2),IF(ISTEXT(A33),-3,-4)))) -> 0 | C33: =IF(ISNUMBER(A33),A33,0) -> 1 | D33: =IF(ISTEXT(A33),A33,"") | E33: case#5
A34: {=_xlfn.XMATCH("(?i)(?^)A",Rq!A12,3)} -> #N/A | B34: =IF(ISERROR(A34),ERROR.TYPE(A34),IF(ISNUMBER(A34),0,IF(ISLOGICAL(A34),IF(A34,-1,-2),IF(ISTEXT(A34),-3,-4)))) -> 7 | C34: =IF(ISNUMBER(A34),A34,0) -> 0 | D34: =IF(ISTEXT(A34),A34,"") | E34: option#1
A35: {=_xlfn.XMATCH("(?aD)\d",Rq!A13,3)} -> #N/A | B35: =IF(ISERROR(A35),ERROR.TYPE(A35),IF(ISNUMBER(A35),0,IF(ISLOGICAL(A35),IF(A35,-1,-2),IF(ISTEXT(A35),-3,-4)))) -> 7 | C35: =IF(ISNUMBER(A35),A35,0) -> 0 | D35: =IF(ISTEXT(A35),A35,"") | E35: option#2
A36: {=_xlfn.XMATCH("(*LIMIT_MATCH=100)(a+)+$",Rq!A14,3)} -> #VALUE! | B36: =IF(ISERROR(A36),ERROR.TYPE(A36),IF(ISNUMBER(A36),0,IF(ISLOGICAL(A36),IF(A36,-1,-2),IF(ISTEXT(A36),-3,-4)))) -> 3 | C36: =IF(ISNUMBER(A36),A36,0) -> 0 | D36: =IF(ISTEXT(A36),A36,"") | E36: option#3
A37: {=_xlfn.XMATCH("(*NO_AUTO_POSSESS)a+b",Rq!A5,3)} -> 1 | B37: =IF(ISERROR(A37),ERROR.TYPE(A37),IF(ISNUMBER(A37),0,IF(ISLOGICAL(A37),IF(A37,-1,-2),IF(ISTEXT(A37),-3,-4)))) -> 0 | C37: =IF(ISNUMBER(A37),A37,0) -> 1 | D37: =IF(ISTEXT(A37),A37,"") | E37: option#4
A38: {=_xlfn.XMATCH("(*UTF)(*UCP)abc",Rq!A5,3)} -> 1 | B38: =IF(ISERROR(A38),ERROR.TYPE(A38),IF(ISNUMBER(A38),0,IF(ISLOGICAL(A38),IF(A38,-1,-2),IF(ISTEXT(A38),-3,-4)))) -> 0 | C38: =IF(ISNUMBER(A38),A38,0) -> 1 | D38: =IF(ISTEXT(A38),A38,"") | E38: option#5
A39: {=_xlfn.XMATCH("(?-x)a",Rq!A5,3)} -> 1 | B39: =IF(ISERROR(A39),ERROR.TYPE(A39),IF(ISNUMBER(A39),0,IF(ISLOGICAL(A39),IF(A39,-1,-2),IF(ISTEXT(A39),-3,-4)))) -> 0 | C39: =IF(ISNUMBER(A39),A39,0) -> 1 | D39: =IF(ISTEXT(A39),A39,"") | E39: option#6
A40: {=_xlfn.XMATCH("^(\((?:[^()]|(?-1))*\))$",Rq!A21,3)} -> 1 | B40: =IF(ISERROR(A40),ERROR.TYPE(A40),IF(ISNUMBER(A40),0,IF(ISLOGICAL(A40),IF(A40,-1,-2),IF(ISTEXT(A40),-3,-4)))) -> 0 | C40: =IF(ISNUMBER(A40),A40,0) -> 1 | D40: =IF(ISTEXT(A40),A40,"") | E40: recurse#1
...
